Workbook

Sheet 8502271974_TradeBook
A1: Date | B1: Stock | C1: Action | D1: Qty | E1: Price | F1: Trade Value | G1: Order Ref. | H1: Settlement | I1: Segment | J1: DP Id - Client DP Id | K1: Exchange | L1: STT | M1: Transaction and SEBI Turnover charges | N1: Stamp Duty | O1: Brokerage + Service Tax | P1: Brokerage incl. taxes
A2: 43823 | B2: BHAAIR | C2: Buy | D2: 1000 | E2: 455.4 | F2: 455400 | G2: 20191224N300015202 | H2: 2019241 | I2: Rolling | J2: IN302679-38296183 | K2: NSE | L2: 0 | M2: 0 | N2: 0 | O2: 0 | P2: 0
A3: 43823 | B3: BHAAIR | C3: Sell | D3: 2500 | E3: 454.68 | F3: 1136711.8 | G3: 20191224N300018981 | H3: 2019241 | I3: Rolling | J3: IN302679-38296183 | K3: NSE | L3: 0 | M3: 0 | N3: 0 | O3: 0 | P3: 0
A4: 43823 | B4: BHAAIR | C4: Sell | D4: 1000 | E4: 456 | F4: 456000 | G4: 20191224N300019401 | H4: 2019241 | I4: Rolling | J4: IN302679-38296183 | K4: NSE | L4: 0 | M4: 0 | N4: 0 | O4: 0 | P4: 0
A5: 43823 | B5: ZEEENT | C5: Sell | D5: 1500 | E5: 299 | F5: 448500 | G5: 20191224N300021904 | H5: 2019241 | I5: Rolling | J5: IN302679-38296183 | K5: NSE | L5: 0 | M5: 0 | N5: 0 | O5: 0 | P5: 0
A6: 43823 | B6: ZEEENT | C6: Buy | D6: 1500 | E6: 298.1 | F6: 447150 | G6: 20191224N300024805 | H6: 2019241 | I6: Rolling | J6: IN302679-38296183 | K6: NSE | L6: 0 | M6: 0 | N6: 0 | O6: 0 | P6: 0
A7: 43823 | B7: BHAAIR | C7: Sell | D7: 2500 | E7: 458.25 | F7: 1145625 | G7: 20191224N300026387 | H7: 2019241 | I7: Rolling | J7: IN302679-38296183 | K7: NSE | L7: 0 | M7: 0 | N7: 0 | O7: 0 | P7: 0
A8: 43823 | B8: BHAAIR | C8: Buy | D8: 5000 | E8: 457.53 | F8: 2287654.3 | G8: 20191224N300028987 | H8: 2019241 | I8: Rolling | J8: IN302679-38296183 | K8: NSE | L8: 0 | M8: 0 | N8: 0 | O8: 0 | P8: 0
A9: 43823 | B9: VAKRAN | C9: Buy | D9: 50 | E9: 41 | F9: 2050 | G9: 20191224N900014798 | H9: 2019241 | I9: Rolling | J9: IN302679-38296183 | K9: NSE | L9: 0 | M9: 0 | N9: 0 | O9: 0 | P9: 0
A10: 43822 | B10: VEDLIM | C10: Sell | D10: 1000 | E10: 147.5 | F10: 147500 | G10: 20191223N300016041 | H10: 2019240 | I10: Rolling | J10: IN302679-38296183 | K10: NSE | L10: 36.83 | M10: 3.25 | N10: 0 | O10: 87.61 | P10: 127.685
A11: 43822 | B11: YESBAN | C11: Sell | D11: 5000 | E11: 51.85 | F11: 259250 | G11: 20191223N300017561 | H11: 2019240 | I11: Rolling | J11: IN302679-38296183 | K11: NSE | L11: 256 | M11: 5.7 | N11: 0 | O11: 153.98 | P11: 415.6836
A12: 43822 | B12: YESBAN | C12: Buy | D12: 5000 | E12: 51.5 | F12: 257500 | G12: 20191223N300018688 | H12: 2019240 | I12: Rolling | J12: IN302679-38296183 | K12: NSE | L12: 0 | M12: 5.67 | N12: 0 | O12: 152.94 | P12: 158.605
A13: 43822 | B13: VEDLIM | C13: Buy | D13: 1000 | E13: 146.98 | F13: 146979.35 | G13: 20191223N300018770 | H13: 2019240 | I13: Rolling | J13: IN302679-38296183 | K13: NSE | L13: 0 | M13: 3.23 | N13: 0 | O13: 87.3 | P13: 90.5338
... A1629: 40995 | B1629: MUTFIN | C1629: Buy | D1629: 6 | E1629: 139.45 | F1629: 836.7 | G1629: 20120327N900002419 | H1629: 2012059 | I1629: Rolling | J1629: IN302679-38296183 | K1629: NSE | L1629: 1 | M1629: 0.03 | N1629: 0.08 | O1629: 23.07 | P1629: 24.183

Sheet Buy
L1: BuyVal | O1: Sell Val | Q1: ValDiff | R1: P/L | S1: P | T1: L
L2: =SUM(L10:L1000) -> 1.3903295e+08 | O2: =SUM(O10:O1000) -> 1.3795368e+08 | Q2: =SUM(Q10:Q1000) -> -1079260.7 | R2: =SUM(R10:R1000) -> -658534.65 | S2: =SUM(S10:S1000) -> 123508.77 | T2: =SUM(T10:T1000) -> -782043.42
R3: -5341.2691 | S3: 0 | T3: -5341.2691
R4: =R2+R3 -> -663875.91 | S4: =S2+S3 -> 123508.77 | T4: =T2+T3 -> -787384.69
A5: Action | B5: Buy
B7: Values
A8: Row Labels | B8: Sum of Qty | C8: Sum of Price | D8: Sum of Trade Value | E8: Sum of Brokerage incl. taxes | H8: Values | M8: SELL Lookup | P8: Analysis
A9: ARVLIM | B9: 100 | C9: 357 | D9: 35700 | E9: 271.1581 | G9: Row Labels | H9: Sum of Qty | I9: Sum of Price | J9: Sum of Trade Value | K9: Sum of Brokerage incl. taxes | L9: BuyVal | M9: Stk | N9: SQTY | O9: Sell Val | P9: QtyDiff | Q9: ValDiff | R9: P/L | S9: P | T9: L | U9: Status
A10: ASHLEY | B10: 20950 | C10: 832.5 | D10: 2032062.5 | E10: 1382.5109 | G10: ARVLIM | H10: 100 | I10: 357 | J10: 35700 | K10: 271.1581 | L10: =J10+K10 -> 35971.158 | M10: =VLOOKUP(G10,Sell!G:L,1,0) -> ARVLIM | N10: =IFERROR(VLOOKUP(G10,Sell!G:L,2,0),0) -> 100 | O10: =IFERROR(VLOOKUP(G10,Sell!G:L,6,0),0) -> 37021.849 | P10: =H10-N10 -> 0 | Q10: =O10-L10 -> 1050.691 | R10: =IF(P10=0,Q10,0) -> 1050.691 | S10: =IF(R10>0,R10,0) -> 1050.691 | T10: =IF(R10>0,0,R10) -> 0 | U10: =IF(AND(LEN(G10)>0,R10=0),"Open","")
A11: CENBAN | B11: 5349 | C11: 408.5 | D11: 134103.5 | E11: 334.6101 | G11: ASHLEY | H11: 20950 | I11: 832.5 | J11: 2032062.5 | K11: 1382.5109 | L11: =J11+K11 -> 2033445 | M11: =VLOOKUP(G11,Sell!G:L,1,0) -> ASHLEY | N11: =IFERROR(VLOOKUP(G11,Sell!G:L,2,0),0) -> 20950 | O11: =IFERROR(VLOOKUP(G11,Sell!G:L,6,0),0) -> 2010848 | P11: =H11-N11 -> 0 | Q11: =O11-L11 -> -22596.986 | R11: =IF(P11=0,Q11,0) -> -22596.986 | S11: =IF(R11>0,R11,0) -> 0 | T11: =IF(R11>0,0,R11) -> -22596.986 | U11: =IF(AND(LEN(G11)>0,R11=0),"Open","")
A12: GATLIM | B12: 13139 | C12: 2621.8 | D12: 1756297.1 | E12: 4898.7724 | G12: CENBAN | H12: 5349 | I12: 408.5 | J12: 134103.5 | K12: 334.6101 | L12: =J12+K12 -> 134438.11 | M12: =VLOOKUP(G12,Sell!G:L,1,0) -> CENBAN | N12: =IFERROR(VLOOKUP(G12,Sell!G:L,2,0),0) -> 5349 | O12: =IFERROR(VLOOKUP(G12,Sell!G:L,6,0),0) -> 145640.5 | P12: =H12-N12 -> 0 | Q12: =O12-L12 -> 11202.39 | R12: =IF(P12=0,Q12,0) -> 11202.39 | S12: =IF(R12>0,R12,0) -> 11202.39 | T12: =IF(R12>0,0,R12) -> 0 | U12: =IF(AND(LEN(G12)>0,R12=0),"Open","")
A13: GMRINF | B13: 25325 | C13: 200.39 | D13: 452689.75 | E13: 2312.3229 | G13: GATLIM | H13: 13139 | I13: 2621.8 | J13: 1756297.1 | K13: 4898.7724 | L13: =J13+K13 -> 1761195.8 | M13: =VLOOKUP(G13,Sell!G:L,1,0) -> GATLIM | N13: =IFERROR(VLOOKUP(G13,Sell!G:L,2,0),0) -> 13139 | O13: =IFERROR(VLOOKUP(G13,Sell!G:L,6,0),0) -> 1699130.4 | P13: =H13-N13 -> 0 | Q13: =O13-L13 -> -62065.465 | R13: =IF(P13=0,Q13,0) -> -62065.465 | S13: =IF(R13>0,R13,0) -> 0 | T13: =IF(R13>0,0,R13) -> -62065.465 | U13: =IF(AND(LEN(G13)>0,R13=0),"Open","")
A14: HINCOP | B14: 500 | C14: 77 | D14: 38500 | E14: 282.0019 | G14: GMRINF | H14: 25325 | I14: 200.39 | J14: 452689.75 | K14: 2312.3229 | L14: =J14+K14 -> 455002.07 | M14: =VLOOKUP(G14,Sell!G:L,1,0) -> GMRINF | N14: =IFERROR(VLOOKUP(G14,Sell!G:L,2,0),0) -> 25325 | O14: =IFERROR(VLOOKUP(G14,Sell!G:L,6,0),0) -> 419457.3 | P14: =H14-N14 -> 0 | Q14: =O14-L14 -> -35544.769 | R14: =IF(P14=0,Q14,0) -> -35544.769 | S14: =IF(R14>0,R14,0) -> 0 | T14: =IF(R14>0,0,R14) -> -35544.769 | U14: =IF(AND(LEN(G14)>0,R14=0),"Open","")
A15: INFTEC | B15: 310 | C15: 4031.16 | D15: 274814.15 | E15: 1014.6312 | G15: HINCOP | H15: 500 | I15: 77 | J15: 38500 | K15: 282.0019 | L15: =J15+K15 -> 38782.002 | M15: =VLOOKUP(G15,Sell!G:L,1,0) -> HINCOP | N15: =IFERROR(VLOOKUP(G15,Sell!G:L,2,0),0) -> 500 | O15: =IFERROR(VLOOKUP(G15,Sell!G:L,6,0),0) -> 40200.412 | P15: =H15-N15 -> 0 | Q15: =O15-L15 -> 1418.4101 | R15: =IF(P15=0,Q15,0) -> 1418.4101 | S15: =IF(R15>0,R15,0) -> 1418.4101 | T15: =IF(R15>0,0,R15) -> 0 | U15: =IF(AND(LEN(G15)>0,R15=0),"Open","")
A16: JAIASS | B16: 500 | C16: 66 | D16: 33000 | E16: 238.618 | G16: INFTEC | H16: 310 | I16: 4031.16 | J16: 274814.15 | K16: 1014.6312 | L16: =J16+K16 -> 275828.78 | M16: =VLOOKUP(G16,Sell!G:L,1,0) -> INFTEC | N16: =IFERROR(VLOOKUP(G16,Sell!G:L,2,0),0) -> 300 | O16: =IFERROR(VLOOKUP(G16,Sell!G:L,6,0),0) -> 269196.34 | P16: =H16-N16 -> 10 | Q16: =O16-L16 -> -6632.4404 | R16: =IF(P16=0,Q16,0) -> 0 | S16: =IF(R16>0,R16,0) -> 0 | T16: =IF(R16>0,0,R16) -> 0 | U16: =IF(AND(LEN(G16)>0,R16=0),"Open","") -> Open
A17: JAIPOW | B17: 3000 | C17: 34.7 | D17: 46200 | E17: 335.6274 | G17: JAIASS | H17: 500 | I17: 66 | J17: 33000 | K17: 238.618 | L17: =J17+K17 -> 33238.618 | M17: =VLOOKUP(G17,Sell!G:L,1,0) -> JAIASS | N17: =IFERROR(VLOOKUP(G17,Sell!G:L,2,0),0) -> 500 | O17: =IFERROR(VLOOKUP(G17,Sell!G:L,6,0),0) -> 41444.437 | P17: =H17-N17 -> 0 | Q17: =O17-L17 -> 8205.8193 | R17: =IF(P17=0,Q17,0) -> 8205.8193 | S17: =IF(R17>0,R17,0) -> 8205.8193 | T17: =IF(R17>0,0,R17) -> 0 | U17: =IF(AND(LEN(G17)>0,R17=0),"Open","")
A18: JBCHEM | B18: 1381 | C18: 2024.17 | D18: 440892.9 | E18: 956.7433 | G18: JAIPOW | H18: 3000 | I18: 34.7 | J18: 46200 | K18: 335.6274 | L18: =J18+K18 -> 46535.627 | M18: =VLOOKUP(G18,Sell!G:L,1,0) -> JAIPOW | N18: =IFERROR(VLOOKUP(G18,Sell!G:L,2,0),0) -> 3000 | O18: =IFERROR(VLOOKUP(G18,Sell!G:L,6,0),0) -> 33499.015 | P18: =H18-N18 -> 0 | Q18: =O18-L18 -> -13036.612 | R18: =IF(P18=0,Q18,0) -> -13036.612 | S18: =IF(R18>0,R18,0) -> 0 | T18: =IF(R18>0,0,R18) -> -13036.612 | U18: =IF(AND(LEN(G18)>0,R18=0),"Open","")
A19: KOHFOO | B19: 1000 | C19: 78.65 | D19: 78650 | E19: 596.336 | G19: JBCHEM | H19: 1381 | I19: 2024.17 | J19: 440892.9 | K19: 956.7433 | L19: =J19+K19 -> 441849.64 | M19: =VLOOKUP(G19,Sell!G:L,1,0) -> JBCHEM | N19: =IFERROR(VLOOKUP(G19,Sell!G:L,2,0),0) -> 1381 | O19: =IFERROR(VLOOKUP(G19,Sell!G:L,6,0),0) -> 423470.77 | P19: =H19-N19 -> 0 | Q19: =O19-L19 -> -18378.877 | R19: =IF(P19=0,Q19,0) -> -18378.877 | S19: =IF(R19>0,R19,0) -> 0 | T19: =IF(R19>0,0,R19) -> -18378.877 | U19: =IF(AND(LEN(G19)>0,R19=0),"Open","")
A20: LANINF | B20: 3000 | C20: 14.5 | D20: 22250 | E20: 128.666 | G20: KOHFOO | H20: 1000 | I20: 78.65 | J20: 78650 | K20: 596.336 | L20: =J20+K20 -> 79246.336 | M20: =VLOOKUP(G20,Sell!G:L,1,0) -> KOHFOO | N20: =IFERROR(VLOOKUP(G20,Sell!G:L,2,0),0) -> 1000 | O20: =IFERROR(VLOOKUP(G20,Sell!G:L,6,0),0) -> 70805.881 | P20: =H20-N20 -> 0 | Q20: =O20-L20 -> -8440.4547 | R20: =IF(P20=0,Q20,0) -> -8440.4547 | S20: =IF(R20>0,R20,0) -> 0 | T20: =IF(R20>0,0,R20) -> -8440.4547 | U20: =IF(AND(LEN(G20)>0,R20=0),"Open","")
A21: LTOVER | B21: 49500 | C21: 1300.34 | D21: 1719373.4 | E21: 3580.3923 | G21: LANINF | H21: 3000 | I21: 14.5 | J21: 22250 | K21: 128.666 | L21: =J21+K21 -> 22378.666 | M21: =VLOOKUP(G21,Sell!G:L,1,0) -> LANINF | N21: =IFERROR(VLOOKUP(G21,Sell!G:L,2,0),0) -> 3000 | O21: =IFERROR(VLOOKUP(G21,Sell!G:L,6,0),0) -> 21011.857 | P21: =H21-N21 -> 0 | Q21: =O21-L21 -> -1366.8092 | R21: =IF(P21=0,Q21,0) -> -1366.8092 | S21: =IF(R21>0,R21,0) -> 0 | T21: =IF(R21>0,0,R21) -> -1366.8092 | U21: =IF(AND(LEN(G21)>0,R21=0),"Open","")
... A23: MINLIM | B23: 1910 | C23: 11089.36 | D23: 1766671.3 | E23: 2051.7022 | G23: MANAFI | H23: 100 | I23: 92 | J23: 9200 | K23: 68.4936 | L23: =J23+K23 -> 9268.4936 | M23: =VLOOKUP(G23,Sell!G:L,1,0) -> MANAFI | N23: =IFERROR(VLOOKUP(G23,Sell!G:L,2,0),0) -> 100 | O23: =IFERROR(VLOOKUP(G23,Sell!G:L,6,0),0) -> 9670.4983 | P23: =H23-N23 -> 0 | Q23: =O23-L23 -> 402.0047 | R23: =IF(P23=0,Q23,0) -> 402.0047 | S23: =IF(R23>0,R23,0) -> 402.0047 | T23: =IF(R23>0,0,R23) -> 0 | U23: =IF(AND(LEN(G23)>0,R23=0),"Open","")
A24: MUTFIN | B24: 4823 | C24: 4118.8 | D24: 1947209.4 | E24: 5034.4991 | G24: MINLIM | H24: 1910 | I24: 11089.36 | J24: 1766671.3 | K24: 2051.7022 | L24: =J24+K24 -> 1768723 | M24: =VLOOKUP(G24,Sell!G:L,1,0) -> MINLIM | N24: =IFERROR(VLOOKUP(G24,Sell!G:L,2,0),0) -> 1920 | O24: =IFERROR(VLOOKUP(G24,Sell!G:L,6,0),0) -> 1725729.5 | P24: 0 | Q24: =O24-L24 -> -42993.528 | R24: =IF(P24=0,Q24,0) -> -42993.528 | S24: =IF(R24>0,R24,0) -> 0 | T24: =IF(R24>0,0,R24) -> -42993.528 | U24: =IF(AND(LEN(G24)>0,R24=0),"Open","")
A25: NHPC | B25: 700 | C25: 20 | D25: 14000 | E25: 102.424 | G25: MUTFIN | H25: 4823 | I25: 4118.8 | J25: 1947209.4 | K25: 5034.4991 | L25: =J25+K25 -> 1952243.9 | M25: =VLOOKUP(G25,Sell!G:L,1,0) -> MUTFIN | N25: =IFERROR(VLOOKUP(G25,Sell!G:L,2,0),0) -> 4823 | O25: =IFERROR(VLOOKUP(G25,Sell!G:L,6,0),0) -> 1923326.4 | P25: =H25-N25 -> 0 | Q25: =O25-L25 -> -28917.591 | R25: =IF(P25=0,Q25,0) -> -28917.591 | S25: =IF(R25>0,R25,0) -> 0 | T25: =IF(R25>0,0,R25) -> -28917.591 | U25: =IF(AND(LEN(G25)>0,R25=0),"Open","")
A26: PUNBAN | B26: 5500 | C26: 635.75 | D26: 482800 | E26: 781.7997 | G26: NHPC | H26: 700 | I26: 20 | J26: 14000 | K26: 102.424 | L26: =J26+K26 -> 14102.424 | M26: =VLOOKUP(G26,Sell!G:L,1,0) -> NHPC | N26: =IFERROR(VLOOKUP(G26,Sell!G:L,2,0),0) -> 700 | O26: =IFERROR(VLOOKUP(G26,Sell!G:L,6,0),0) -> 14176.956 | P26: =H26-N26 -> 0 | Q26: =O26-L26 -> 74.5319 | R26: =IF(P26=0,Q26,0) -> 74.5319 | S26: =IF(R26>0,R26,0) -> 74.5319 | T26: =IF(R26>0,0,R26) -> 0 | U26: =IF(AND(LEN(G26)>0,R26=0),"Open","")
A27: RELDEF | B27: 11500 | C27: 658.35 | D27: 674385.3 | E27: 4912.8277 | G27: PUNBAN | H27: 5500 | I27: 635.75 | J27: 482800 | K27: 781.7997 | L27: =J27+K27 -> 483581.8 | M27: =VLOOKUP(G27,Sell!G:L,1,0) -> PUNBAN | N27: =IFERROR(VLOOKUP(G27,Sell!G:L,2,0),0) -> 5500 | O27: =IFERROR(VLOOKUP(G27,Sell!G:L,6,0),0) -> 474990.86 | P27: =H27-N27 -> 0 | Q27: =O27-L27 -> -8590.9382 | R27: =IF(P27=0,Q27,0) -> -8590.9382 | S27: =IF(R27>0,R27,0) -> 0 | T27: =IF(R27>0,0,R27) -> -8590.9382 | U27: =IF(AND(LEN(G27)>0,R27=0),"Open","")
A28: RELPOW | B28: 575 | C28: 212 | D28: 60500 | E28: 441.1785 | G28: RELDEF | H28: 11500 | I28: 658.35 | J28: 674385.3 | K28: 4912.8277 | L28: =J28+K28 -> 679298.13 | M28: =VLOOKUP(G28,Sell!G:L,1,0) -> RELDEF | N28: =IFERROR(VLOOKUP(G28,Sell!G:L,2,0),0) -> 11500 | O28: =IFERROR(VLOOKUP(G28,Sell!G:L,6,0),0) -> 725840.37 | P28: =H28-N28 -> 0 | Q28: =O28-L28 -> 46542.244 | R28: =IF(P28=0,Q28,0) -> 46542.244 | S28: =IF(R28>0,R28,0) -> 46542.244 | T28: =IF(R28>0,0,R28) -> 0 | U28: =IF(AND(LEN(G28)>0,R28=0),"Open","")
A29: SUNADV | B29: 410 | C29: 1081 | D29: 131300 | E29: 729.6643 | G29: RELPOW | H29: 575 | I29: 212 | J29: 60500 | K29: 441.1785 | L29: =J29+K29 -> 60941.179 | M29: =VLOOKUP(G29,Sell!G:L,1,0) -> RELPOW | N29: =IFERROR(VLOOKUP(G29,Sell!G:L,2,0),0) -> 575 | O29: =IFERROR(VLOOKUP(G29,Sell!G:L,6,0),0) -> 37733.204 | P29: =H29-N29 -> 0 | Q29: =O29-L29 -> -23207.975 | R29: =IF(P29=0,Q29,0) -> -23207.975 | S29: =IF(R29>0,R29,0) -> 0 | T29: =IF(R29>0,0,R29) -> -23207.975 | U29: =IF(AND(LEN(G29)>0,R29=0),"Open","")
A30: SUNPHA | B30: 2990 | C30: 5885.19 | D30: 1305993.3 | E30: 1010.5932 | G30: SUNADV | H30: 410 | I30: 1081 | J30: 131300 | K30: 729.6643 | L30: =J30+K30 -> 132029.66 | M30: =VLOOKUP(G30,Sell!G:L,1,0) -> SUNADV | N30: =IFERROR(VLOOKUP(G30,Sell!G:L,2,0),0) -> 410 | O30: =IFERROR(VLOOKUP(G30,Sell!G:L,6,0),0) -> 123341.67 | P30: =H30-N30 -> 0 | Q30: =O30-L30 -> -8687.9977 | R30: =IF(P30=0,Q30,0) -> -8687.9977 | S30: =IF(R30>0,R30,0) -> 0 | T30: =IF(R30>0,0,R30) -> -8687.9977 | U30: =IF(AND(LEN(G30)>0,R30=0),"Open","")
A31: TATPOW | B31: 1000 | C31: 69 | D31: 69000 | E31: 512.8071 | G31: SUNPHA | H31: 2990 | I31: 5885.19 | J31: 1305993.3 | K31: 1010.5932 | L31: =J31+K31 -> 1307003.9 | M31: =VLOOKUP(G31,Sell!G:L,1,0) -> SUNPHA | N31: =IFERROR(VLOOKUP(G31,Sell!G:L,2,0),0) -> 2990 | O31: =IFERROR(VLOOKUP(G31,Sell!G:L,6,0),0) -> 1306411.1 | P31: =H31-N31 -> 0 | Q31: =O31-L31 -> -592.7825 | R31: =IF(P31=0,Q31,0) -> -592.7825 | S31: =IF(R31>0,R31,0) -> 0 | T31: =IF(R31>0,0,R31) -> -592.7825 | U31: =IF(AND(LEN(G31)>0,R31=0),"Open","")
A32: TVSMOT | B32: 200 | C32: 767.93 | D32: 76793.35 | E32: 578.464 | G32: TATPOW | H32: 1000 | I32: 69 | J32: 69000 | K32: 512.8071 | L32: =J32+K32 -> 69512.807 | M32: =VLOOKUP(G32,Sell!G:L,1,0) -> TATPOW | N32: =IFERROR(VLOOKUP(G32,Sell!G:L,2,0),0) -> 1000 | O32: =IFERROR(VLOOKUP(G32,Sell!G:L,6,0),0) -> 69663.034 | P32: =H32-N32 -> 0 | Q32: =O32-L32 -> 150.2264 | R32: =IF(P32=0,Q32,0) -> 150.2264 | S32: =IF(R32>0,R32,0) -> 150.2264 | T32: =IF(R32>0,0,R32) -> 0 | U32: =IF(AND(LEN(G32)>0,R32=0),"Open","")
A33: ZENINF | B33: 475 | C33: 11.15 | D33: 5296.25 | E33: 45.0191 | G33: TVSMOT | H33: 200 | I33: 767.93 | J33: 76793.35 | K33: 578.464 | L33: =J33+K33 -> 77371.814 | M33: =VLOOKUP(G33,Sell!G:L,1,0) -> TVSMOT | N33: =IFERROR(VLOOKUP(G33,Sell!G:L,2,0),0) -> 200 | O33: =IFERROR(VLOOKUP(G33,Sell!G:L,6,0),0) -> 79332.533 | P33: =H33-N33 -> 0 | Q33: =O33-L33 -> 1960.7186 | R33: =IF(P33=0,Q33,0) -> 1960.7186 | S33: =IF(R33>0,R33,0) -> 1960.7186 | T33: =IF(R33>0,0,R33) -> 0 | U33: =IF(AND(LEN(G33)>0,R33=0),"Open","")
A34: SUZENE | B34: 27500 | C34: 95.15 | D34: 439375 | E34: 2194.7199 | G34: ZENINF | H34: 475 | I34: 11.15 | J34: 5296.25 | K34: 45.0191 | L34: =J34+K34 -> 5341.2691 | M34: =VLOOKUP(G34,Sell!G:L,1,0) -> #N/A | N34: =IFERROR(VLOOKUP(G34,Sell!G:L,2,0),0) -> 0 | O34: =IFERROR(VLOOKUP(G34,Sell!G:L,6,0),0) -> 0 | P34: =H34-N34 -> 475 | Q34: =O34-L34 -> -5341.2691 | R34: =IF(P34=0,Q34,0) -> 0 | S34: =IF(R34>0,R34,0) -> 0 | T34: =IF(R34>0,0,R34) -> 0 | U34: =IF(AND(LEN(G34)>0,R34=0),"Open","") -> Open
A35: FINCHE | B35: 10250 | C35: 908.37 | D35: 709439.05 | E35: 3494.3405 | G35: SUZENE | H35: 27500 | I35: 95.15 | J35: 439375 | K35: 2194.7199 | L35: =J35+K35 -> 441569.72 | M35: =VLOOKUP(G35,Sell!G:L,1,0) -> SUZENE | N35: =IFERROR(VLOOKUP(G35,Sell!G:L,2,0),0) -> 27500 | O35: =IFERROR(VLOOKUP(G35,Sell!G:L,6,0),0) -> 436255.19 | P35: =H35-N35 -> 0 | Q35: =O35-L35 -> -5314.5313 | R35: =IF(P35=0,Q35,0) -> -5314.5313 | S35: =IF(R35>0,R35,0) -> 0 | T35: =IF(R35>0,0,R35) -> -5314.5313 | U35: =IF(AND(LEN(G35)>0,R35=0),"Open","")
A36: BANMAH | B36: 5000 | C36: 24 | D36: 120000 | E36: 82.6 | G36: FINCHE | H36: 10250 | I36: 908.37 | J36: 709439.05 | K36: 3494.3405 | L36: =J36+K36 -> 712933.39 | M36: =VLOOKUP(G36,Sell!G:L,1,0) -> FINCHE | N36: =IFERROR(VLOOKUP(G36,Sell!G:L,2,0),0) -> 9850 | O36: =IFERROR(VLOOKUP(G36,Sell!G:L,6,0),0) -> 689043.33 | P36: =H36-N36 -> 400 | Q36: =O36-L36 -> -23890.056 | R36: =IF(P36=0,Q36,0) -> 0 | S36: =IF(R36>0,R36,0) -> 0 | T36: =IF(R36>0,0,R36) -> 0 | U36: =IF(AND(LEN(G36)>0,R36=0),"Open","") -> Open
... A124: Grand Total | B124: 886771 | C124: 222985.58 | D124: 1.3887771e+08 | E124: 155233.27 | G124: TCS | H124: 10 | I124: 2208.95 | J124: 22089.5 | K124: 30.076 | L124: =J124+K124 -> 22119.576 | M124: =VLOOKUP(G124,Sell!G:L,1,0) -> TCS | N124: =IFERROR(VLOOKUP(G124,Sell!G:L,2,0),0) -> 10 | O124: =IFERROR(VLOOKUP(G124,Sell!G:L,6,0),0) -> 22235.87 | P124: =H124-N124 -> 0 | Q124: =O124-L124 -> 116.294 | R124: =IF(P124=0,Q124,0) -> 116.294 | S124: =IF(R124>0,R124,0) -> 116.294 | T124: =IF(R124>0,0,R124) -> 0 | U124: =IF(AND(LEN(G124)>0,R124=0),"Open","")
L125: =J125+K125 -> 0 | M125: =VLOOKUP(G125,Sell!G:L,1,0) -> #N/A | N125: =IFERROR(VLOOKUP(G125,Sell!G:L,2,0),0) -> 0 | O125: =IFERROR(VLOOKUP(G125,Sell!G:L,6,0),0) -> 0 | P125: =H125-N125 -> 0 | Q125: =O125-L125 -> 0 | R125: =IF(P125=0,Q125,0) -> 0 | S125: =IF(R125>0,R125,0) -> 0 | T125: =IF(R125>0,0,R125) -> 0 | U125: =IF(AND(LEN(G125)>0,R125=0),"Open","")
L126: =J126+K126 -> 0 | M126: =VLOOKUP(G126,Sell!G:L,1,0) -> #N/A | N126: =IFERROR(VLOOKUP(G126,Sell!G:L,2,0),0) -> 0 | O126: =IFERROR(VLOOKUP(G126,Sell!G:L,6,0),0) -> 0 | P126: =H126-N126 -> 0 | Q126: =O126-L126 -> 0 | R126: =IF(P126=0,Q126,0) -> 0 | S126: =IF(R126>0,R126,0) -> 0 | T126: =IF(R126>0,0,R126) -> 0 | U126: =IF(AND(LEN(G126)>0,R126=0),"Open","")
L127: =J127+K127 -> 0 | M127: =VLOOKUP(G127,Sell!G:L,1,0) -> #N/A | N127: =IFERROR(VLOOKUP(G127,Sell!G:L,2,0),0) -> 0 | O127: =IFERROR(VLOOKUP(G127,Sell!G:L,6,0),0) -> 0 | P127: =H127-N127 -> 0 | Q127: =O127-L127 -> 0 | R127: =IF(P127=0,Q127,0) -> 0 | S127: =IF(R127>0,R127,0) -> 0 | T127: =IF(R127>0,0,R127) -> 0 | U127: =IF(AND(LEN(G127)>0,R127=0),"Open","")
L128: =J128+K128 -> 0 | M128: =VLOOKUP(G128,Sell!G:L,1,0) -> #N/A | N128: =IFERROR(VLOOKUP(G128,Sell!G:L,2,0),0) -> 0 | O128: =IFERROR(VLOOKUP(G128,Sell!G:L,6,0),0) -> 0 | P128: =H128-N128 -> 0 | Q128: =O128-L128 -> 0 | R128: =IF(P128=0,Q128,0) -> 0 | S128: =IF(R128>0,R128,0) -> 0 | T128: =IF(R128>0,0,R128) -> 0 | U128: =IF(AND(LEN(G128)>0,R128=0),"Open","")
L129: =J129+K129 -> 0 | M129: =VLOOKUP(G129,Sell!G:L,1,0) -> #N/A | N129: =IFERROR(VLOOKUP(G129,Sell!G:L,2,0),0) -> 0 | O129: =IFERROR(VLOOKUP(G129,Sell!G:L,6,0),0) -> 0 | P129: =H129-N129 -> 0 | Q129: =O129-L129 -> 0 | R129: =IF(P129=0,Q129,0) -> 0 | S129: =IF(R129>0,R129,0) -> 0 | T129: =IF(R129>0,0,R129) -> 0 | U129: =IF(AND(LEN(G129)>0,R129=0),"Open","")
...

Sheet Sell
A1: Action | B1: Sell
B3: Values | H3: Values
A4: Row Labels | B4: Sum of Qty | C4: Sum of Price | D4: Sum of Trade Value | E4: Sum of Brokerage incl. taxes | G4: Row Labels | H4: Sum of Qty | I4: Sum of Price | J4: Sum of Trade Value | K4: Sum of Brokerage incl. taxes | L4: SellValue
A5: ARVLIM | B5: 100 | C5: 373 | D5: 37300 | E5: 278.1509 | G5: ARVLIM | H5: 100 | I5: 373 | J5: 37300 | K5: 278.1509 | L5: =J5-K5 -> 37021.849
A6: ASHLEY | B6: 20950 | C6: 1346.24 | D6: 2012879.8 | E6: 2031.7755 | G6: ASHLEY | H6: 20950 | I6: 1346.24 | J6: 2012879.8 | K6: 2031.7755 | L6: =J6-K6 -> 2010848
A7: CENBAN | B7: 5349 | C7: 182.81 | D7: 145972.75 | E7: 332.2501 | G7: CENBAN | H7: 5349 | I7: 182.81 | J7: 145972.75 | K7: 332.2501 | L7: =J7-K7 -> 145640.5
A8: GATLIM | B8: 13139 | C8: 2026.98 | D8: 1703019.6 | E8: 3889.2426 | G8: GATLIM | H8: 13139 | I8: 2026.98 | J8: 1703019.6 | K8: 3889.2426 | L8: =J8-K8 -> 1699130.4
A9: GMRINF | B9: 25325 | C9: 145.36 | D9: 421590 | E9: 2132.6962 | G9: GMRINF | H9: 25325 | I9: 145.36 | J9: 421590 | K9: 2132.6962 | L9: =J9-K9 -> 419457.3
A10: HINCOP | B10: 500 | C10: 81 | D10: 40500 | E10: 299.588 | G10: HINCOP | H10: 500 | I10: 81 | J10: 40500 | K10: 299.588 | L10: =J10-K10 -> 40200.412
A11: INFTEC | B11: 300 | C11: 2702 | D11: 270200 | E11: 1003.6592 | G11: INFTEC | H11: 300 | I11: 2702 | J11: 270200 | K11: 1003.6592 | L11: =J11-K11 -> 269196.34
A12: JAIASS | B12: 500 | C12: 83.5 | D12: 41750 | E12: 305.5627 | G12: JAIASS | H12: 500 | I12: 83.5 | J12: 41750 | K12: 305.5627 | L12: =J12-K12 -> 41444.437
A13: JAIPOW | B13: 3000 | C13: 23.4 | D13: 33750 | E13: 250.9846 | G13: JAIPOW | H13: 3000 | I13: 23.4 | J13: 33750 | K13: 250.9846 | L13: =J13-K13 -> 33499.015
A14: JBCHEM | B14: 1381 | C14: 1615.44 | D14: 424303.55 | E14: 832.7839 | G14: JBCHEM | H14: 1381 | I14: 1615.44 | J14: 424303.55 | K14: 832.7839 | L14: =J14-K14 -> 423470.77
A15: KOHFOO | B15: 1000 | C15: 71.35 | D15: 71345.05 | E15: 539.1687 | G15: KOHFOO | H15: 1000 | I15: 71.35 | J15: 71345.05 | K15: 539.1687 | L15: =J15-K15 -> 70805.881
A16: LANINF | B16: 3000 | C16: 14.6 | D16: 21200 | E16: 188.1432 | G16: LANINF | H16: 3000 | I16: 14.6 | J16: 21200 | K16: 188.1432 | L16: =J16-K16 -> 21011.857
... A118: TCS | B118: 10 | C118: 2227.15 | D118: 22271.5 | E118: 35.63 | G118: TCS | H118: 10 | I118: 2227.15 | J118: 22271.5 | K118: 35.63 | L118: =J118-K118 -> 22235.87
A119: Grand Total | B119: 876461 | C119: 206907.01 | D119: 1.3813332e+08 | E119: 179631.06 | L119: =J119-K119 -> 0
L120: =J120-K120 -> 0
L121: =J121-K121 -> 0
L122: =J122-K122 -> 0
L123: =J123-K123 -> 0
L124: =J124-K124 -> 0
L125: =J125-K125 -> 0
L126: =J126-K126 -> 0
L127: =J127-K127 -> 0
L128: =J128-K128 -> 0
L129: =J129-K129 -> 0
L130: =J130-K130 -> 0
L131: =J131-K131 -> 0
... L1000: =J1000-K1000 -> 0

Sheet P and L
A1: Status
A3: Row Labels | B3: Sum of P/L | E3: s | F3: v
A4: ARRGRE | B4: 433.8164 | E4: ICIBAN | F4: -88687.906
A5: ARVLIM | B5: 1050.691 | E5: SINPLA | F5: -77773.549
A6: ASHLEY | B6: -22596.986 | E6: GATLIM | F6: -62065.465
A7: BANBAR | B7: -2385.3294 | E7: MINLIM | F7: -42993.528
A8: BANMAH | B8: -1936.9032 | E8: GMRINF | F8: -35544.769
A9: BHAELE | B9: -16431.7 | E9: HINPET | F9: -33094.949
A10: BHEL | B10: 3821.0238 | E10: JSWSTE | F10: -32708.747
A11: BHUST | B11: -13399.066 | E11: CANHOM | F11: -29205.768
A12: BURCEM | B12: -28608.626 | E12: MUTFIN | F12: -28917.591
A13: CANHOM | B13: -29205.768 | E13: BURCEM | F13: -28608.626
A14: CENBAN | B14: 11202.39 | E14: FEDBAN | F14: -28038.522
A15: CROGRE | B15: 1.6078 | E15: RELPOW | F15: -23207.975
... A107: IDECEL | B107: 3619.6624 | E107: RELDEF | F107: 46542.244
A108: TCS | B108: 116.294
A109: Grand Total | B109: -658534.65

Sheet Sheet1
A1: Date | B1: Stock | C1: Action | D1: Qty | E1: Price | F1: Trade Value | G1: Order Ref. | H1: Settlement | I1: Segment | J1: DP Id - Client DP Id | K1: Exchange | L1: STT | M1: Transaction and SEBI Turnover charges | N1: Stamp Duty | O1: Brokerage + Service Tax | P1: Brokerage incl. taxes | Q1: BuyValue | R1: SellValue | S1: =SUM(Q:Q) -> 1.3276761e+08 | T1: =SUM(R:R) -> 1.3168303e+08 | U1: =T1-S1 -> -1084580.4
A2: 43817 | B2: JSWSTE | C2: Sell | D2: 2500 | E2: 257.5 | F2: 643750 | G2: 20191218N300015716 | H2: 2019237 | I2: Rolling | J2: IN302679-38296183 | K2: NSE | L2: 0 | M2: 0 | N2: 0 | O2: 0 | P2: 0 | Q2: =IF(C2="Buy",F2+P2,0) -> 0 | R2: =IF(C2="Sell",F2-P2,0) -> 643750
A3: 43817 | B3: JSWSTE | C3: Buy | D3: 1036 | E3: 260.93 | F3: 270322.4 | G3: 20191218N300017034 | H3: 2019237 | I3: Rolling | J3: IN302679-38296183 | K3: NSE | L3: 0 | M3: 0 | N3: 0 | O3: 0 | P3: 0 | Q3: =IF(C3="Buy",F3+P3,0) -> 270322.4 | R3: =IF(C3="Sell",F3-P3,0) -> 0
A4: 43817 | B4: JSWSTE | C4: Sell | D4: 1000 | E4: 263 | F4: 263000 | G4: 20191218N300018267 | H4: 2019237 | I4: Rolling | J4: IN302679-38296183 | K4: NSE | L4: 0 | M4: 0 | N4: 0 | O4: 0 | P4: 0 | Q4: =IF(C4="Buy",F4+P4,0) -> 0 | R4: =IF(C4="Sell",F4-P4,0) -> 263000
A5: 43817 | B5: JSWSTE | C5: Sell | D5: 1000 | E5: 262.5 | F5: 262500 | G5: 20191218N300020799 | H5: 2019237 | I5: Rolling | J5: IN302679-38296183 | K5: NSE | L5: 0 | M5: 0 | N5: 0 | O5: 0 | P5: 0 | Q5: =IF(C5="Buy",F5+P5,0) -> 0 | R5: =IF(C5="Sell",F5-P5,0) -> 262500
A6: 43817 | B6: JSWSTE | C6: Buy | D6: 1445 | E6: 265.45 | F6: 383575.25 | G6: 20191218N300027081 | H6: 2019237 | I6: Rolling | J6: IN302679-38296183 | K6: NSE | L6: 0 | M6: 0 | N6: 0 | O6: 0 | P6: 0 | Q6: =IF(C6="Buy",F6+P6,0) -> 383575.25 | R6: =IF(C6="Sell",F6-P6,0) -> 0
A7: 43817 | B7: JSWSTE | C7: Buy | D7: 2019 | E7: 263.95 | F7: 532915.05 | G7: 20191218N300032550 | H7: 2019237 | I7: Rolling | J7: IN302679-38296183 | K7: NSE | L7: 0 | M7: 0 | N7: 0 | O7: 0 | P7: 0 | Q7: =IF(C7="Buy",F7+P7,0) -> 532915.05 | R7: =IF(C7="Sell",F7-P7,0) -> 0
A8: 43816 | B8: JSWSTE | C8: Buy | D8: 2500 | E8: 261 | F8: 652500 | G8: 20191217N300021604 | H8: 2019236 | I8: Rolling | J8: IN302679-38296183 | K8: NSE | L8: 0 | M8: 14.36 | N8: 0 | O8: 387.56 | P8: 401.915 | Q8: =IF(C8="Buy",F8+P8,0) -> 652901.92 | R8: =IF(C8="Sell",F8-P8,0) -> 0
A9: 43816 | B9: JSWSTE | C9: Sell | D9: 2500 | E9: 258.9 | F9: 647250 | G9: 20191217N300028896 | H9: 2019236 | I9: Rolling | J9: IN302679-38296183 | K9: NSE | L9: 162 | M9: 14.24 | N9: 39 | O9: 384.46 | P9: 599.6994 | Q9: =IF(C9="Buy",F9+P9,0) -> 0 | R9: =IF(C9="Sell",F9-P9,0) -> 646650.3
A10: 43815 | B10: INDHO | C10: Sell | D10: 2500 | E10: 317.8 | F10: 794511.75 | G10: 20191216N300015908 | H10: 2019235 | I10: Rolling | J10: IN302679-38296183 | K10: NSE | L10: 196 | M10: 17.48 | N10: 47.1 | O10: 471.92 | P10: 732.4995 | Q10: =IF(C10="Buy",F10+P10,0) -> 0 | R10: =IF(C10="Sell",F10-P10,0) -> 793779.25
A11: 43815 | B11: INDHO | C11: Buy | D11: 2500 | E11: 309 | F11: 772500 | G11: 20191216N300016628 | H11: 2019235 | I11: Rolling | J11: IN302679-38296183 | K11: NSE | L11: 0 | M11: 17 | N11: 0 | O11: 458.84 | P11: 475.8357 | Q11: =IF(C11="Buy",F11+P11,0) -> 772975.84 | R11: =IF(C11="Sell",F11-P11,0) -> 0
A12: 43812 | B12: JAGPRA | C12: Buy | D12: 2500 | E12: 56.29 | F12: 140714.8 | G12: 20191213N300015089 | H12: 2019234 | I12: Rolling | J12: IN302679-38296183 | K12: NSE | L12: 0 | M12: 3.1 | N12: 0 | O12: 83.57 | P12: 86.6658 | Q12: =IF(C12="Buy",F12+P12,0) -> 140801.47 | R12: =IF(C12="Sell",F12-P12,0) -> 0
A13: 43812 | B13: INDHO | C13: Buy | D13: 500 | E13: 297 | F13: 148500 | G13: 20191213N300016088 | H13: 2019234 | I13: Rolling | J13: IN302679-38296183 | K13: NSE | L13: 0 | M13: 3.27 | N13: 0 | O13: 88.21 | P13: 91.477 | Q13: =IF(C13="Buy",F13+P13,0) -> 148591.48 | R13: =IF(C13="Sell",F13-P13,0) -> 0
... A1597: 40995 | B1597: MUTFIN | C1597: Buy | D1597: 6 | E1597: 139.45 | F1597: 836.7 | G1597: 20120327N900002419 | H1597: 2012059 | I1597: Rolling | J1597: IN302679-38296183 | K1597: NSE | L1597: 1 | M1597: 0.03 | N1597: 0.08 | O1597: 23.07 | P1597: 24.183 | Q1597: =IF(C1597="Buy",F1597+P1597,0) -> 860.883 | R1597: =IF(C1597="Sell",F1597-P1597,0) -> 0

Sheet StockHistory
B3: Column Labels
B4: Buy | D4: Sell | F4: Total Sum of Trade Value | G4: Total Sum of Brokerage incl. taxes
A5: Row Labels | B5: Sum of Trade Value | C5: Sum of Brokerage incl. taxes | D5: Sum of Trade Value | E5: Sum of Brokerage incl. taxes
A6: STABAN | B6: 710000 | C6: 464.4735 | D6: 962550 | E6: 853.3361 | F6: 1672550 | G6: 1317.8096
A7: 43125 | B7: 327000 | C7: 205.4675 | D7: 320000 | E7: 281.95 | F7: 647000 | G7: 487.4175 | H7: =B7+C7 -> 327205.47 | I7: =D7-E7 -> 319718.05 | J7: =I7-H7 -> -7487.4175
A8: 43741 | B8: 383000 | C8: 259.006 | D8: 383450 | E8: 332.1959 | F8: 766450 | G8: 591.2019 | H8: =B8+C8 -> 383259.01 | I8: =D8-E8 -> 383117.8 | J8: =I8-H8 -> -141.2019
A9: 43742 | D9: 259100 | E9: 239.1902 | F9: 259100 | G9: 239.1902 | H9: =B9+C9 -> 0 | I9: =D9-E9 -> 258860.81 | J9: =I9-H9 -> 258860.81
A10: JSWSTE | B10: 1839312.7 | C10: 401.915 | D10: 1816500 | E10: 599.6994 | F10: 3655812.7 | G10: 1001.6144 | H10: =B10+C10 -> 1839714.6 | I10: =D10-E10 -> 1815900.3 | J10: =I10-H10 -> -23814.314
A11: 43817 | B11: 1186812.7 | C11: 0 | D11: 1169250 | E11: 0 | F11: 2356062.7 | G11: 0 | H11: =B11+C11 -> 1186812.7 | I11: =D11-E11 -> 1169250 | J11: =I11-H11 -> -17562.7
A12: 43816 | B12: 652500 | C12: 401.915 | D12: 647250 | E12: 599.6994 | F12: 1299750 | G12: 1001.6144 | H12: =B12+C12 -> 652901.92 | I12: =D12-E12 -> 646650.3 | J12: =I12-H12 -> -6251.6144
A13: INDHO | B13: 5293477.5 | C13: 3569.2776 | D13: 5315242.4 | E13: 4657.4062 | F13: 10608720 | G13: 8226.6838 | H13: =B13+C13 -> 5297046.8 | I13: =D13-E13 -> 5310585 | J13: =I13-H13 -> 13538.216
A14: 43801 | B14: 57801.45 | C14: 69.2015 | D14: 58270 | E14: 50.772 | F14: 116071.45 | G14: 119.9735 | H14: =B14+C14 -> 57870.651 | I14: =D14-E14 -> 58219.228 | J14: =I14-H14 -> 348.5765
A15: 43815 | B15: 772500 | C15: 475.8357 | D15: 794511.75 | E15: 732.4995 | F15: 1567011.8 | G15: 1208.3352 | H15: =B15+C15 -> 772975.84 | I15: =D15-E15 -> 793779.25 | J15: =I15-H15 -> 20803.415
A16: 43812 | B16: 2439528.9 | C16: 1665.8699 | D16: 2426783 | E16: 2103.2098 | F16: 4866311.9 | G16: 3769.0797 | H16: =B16+C16 -> 2441194.8 | I16: =D16-E16 -> 2424679.8 | J16: =I16-H16 -> -16514.98
A17: 43798 | B17: 72800 | C17: 54.7416 | D17: 72850 | E17: 63.0827 | F17: 145650 | G17: 117.8243 | H17: =B17+C17 -> 72854.742 | I17: =D17-E17 -> 72786.917 | J17: =I17-H17 -> -67.8243
A18: 43797 | B18: 149000 | C18: 91.778 | D18: 152560.35 | E18: 141.2864 | F18: 301560.35 | G18: 233.0644 | H18: =B18+C18 -> 149091.78 | I18: =D18-E18 -> 152419.06 | J18: =I18-H18 -> 3327.2856
A19: 43795 | B19: 269425 | C19: 165.9475 | D19: 265767.3 | E19: 230.5968 | F19: 535192.3 | G19: 396.5443 | H19: =B19+C19 -> 269590.95 | I19: =D19-E19 -> 265536.7 | J19: =I19-H19 -> -4054.2443
A20: 43794 | B20: 1532422.2 | C20: 1045.9034 | D20: 1544500 | E20: 1335.959 | F20: 3076922.2 | G20: 2381.8624 | H20: =B20+C20 -> 1533468.1 | I20: =D20-E20 -> 1543164 | J20: =I20-H20 -> 9695.9876
A21: JAGPRA | B21: 460035.45 | C21: 1526.6306 | D21: 344977.25 | E21: 261.4496 | F21: 805012.7 | G21: 1788.0802 | H21: =B21+C21 -> 461562.08 | I21: =D21-E21 -> 344715.8 | J21: =I21-H21 -> -116846.28
A22: 43802 | B22: 60142.35 | C22: 464.8331 | F22: 60142.35 | G22: 464.8331 | H22: =B22+C22 -> 60607.183 | I22: =D22-E22 -> 0 | J22: =I22-H22 -> -60607.183
A23: 43808 | B23: 118431.95 | C23: 888.4354 | D23: 61500 | E23: 16.223 | F23: 179931.95 | G23: 904.6584 | H23: =B23+C23 -> 119320.39 | I23: =D23-E23 -> 61483.777 | J23: =I23-H23 -> -57836.608
A24: 43812 | B24: 281461.15 | C24: 173.3621 | D24: 283477.25 | E24: 245.2266 | F24: 564938.4 | G24: 418.5887 | H24: =B24+C24 -> 281634.51 | I24: =D24-E24 -> 283232.02 | J24: =I24-H24 -> 1597.5113
A25: RELCOM | B25: 6000 | C25: 301.452 | F25: 6000 | G25: 301.452 | H25: =B25+C25 -> 6301.452 | I25: =D25-E25 -> 0 | J25: =I25-H25 -> -6301.452
A26: 43805 | B26: 6000 | C26: 301.452 | F26: 6000 | G26: 301.452 | H26: =B26+C26 -> 6301.452 | I26: =D26-E26 -> 0 | J26: =I26-H26 -> -6301.452
A27: BHAAIR | B27: 1689393.2 | C27: 1040.6167 | D27: 1691095 | E27: 1566.3541 | F27: 3380488.3 | G27: 2606.9708 | H27: =B27+C27 -> 1690433.9 | I27: =D27-E27 -> 1689528.7 | J27: =I27-H27 -> -905.1708
A28: 43804 | B28: 1689393.2 | C28: 1040.6167 | D28: 1691095 | E28: 1566.3541 | F28: 3380488.3 | G28: 2606.9708 | H28: =B28+C28 -> 1690433.9 | I28: =D28-E28 -> 1689528.7 | J28: =I28-H28 -> -905.1708
A29: RBLBAN | B29: 93161.2 | C29: 57.3794 | D29: 94527.5 | E29: 81.6797 | F29: 187688.7 | G29: 139.0591 | H29: =B29+C29 -> 93218.579 | I29: =D29-E29 -> 94445.82 | J29: =I29-H29 -> 1227.2409
A30: 43802 | B30: 93161.2 | C30: 57.3794 | D30: 94527.5 | E30: 81.6797 | F30: 187688.7 | G30: 139.0591 | H30: =B30+C30 -> 93218.579 | I30: =D30-E30 -> 94445.82 | J30: =I30-H30 -> 1227.2409
A31: FEDBAN | B31: 89000 | C31: 54.818 | D31: 91100 | E31: 78.9042 | F31: 180100 | G31: 133.7222
A32: 43798 | B32: 89000 | C32: 54.818 | D32: 91100 | E32: 78.9042 | F32: 180100 | G32: 133.7222
A33: BIOCON | B33: 191292.5 | C33: 129.5285 | D33: 193830 | E33: 167.3942 | F33: 385122.5 | G33: 296.9227
A34: 43796 | B34: 191292.5 | C34: 129.5285 | D34: 193830 | E34: 167.3942 | F34: 385122.5 | G34: 296.9227
A35: LTOVER | B35: 2210 | C35: 59.6586 | F35: 2210 | G35: 59.6586
A36: 43795 | B36: 2210 | C36: 59.6586 | F36: 2210 | G36: 59.6586
A37: SUNPHA | B37: 159700 | C37: 101.0536 | D37: 160650 | E37: 141.6944 | F37: 320350 | G37: 242.748
A38: 43794 | B38: 159700 | C38: 101.0536 | D38: 160650 | E38: 141.6944 | F38: 320350 | G38: 242.748
A39: Grand Total | B39: 10533583 | C39: 7706.8035 | D39: 10670472 | E39: 8407.9179 | F39: 21204055 | G39: 16114.721
