Workbook

Sheet 8502271974_TradeBook
A1: Date | B1: Stock | C1: Action | D1: Qty | E1: Price | F1: Trade Value | G1: Order Ref. | H1: Settlement | I1: Segment | J1: DP Id - Client DP Id | K1: Exchange | L1: STT | M1: Transaction and SEBI Turnover charges | N1: Stamp Duty | O1: Brokerage + Service Tax | P1: Brokerage incl. taxes
A2: 43748 | B2: INDHO | C2: Sell | D2: 250 | E2: 240 | F2: 60000 | G2: 20191010N200000849 | H2: 2019190 | I2: Rolling | J2: IN302679-38296183 | K2: NSE | L2: 0 | M2: 0 | N2: 0 | O2: 0 | P2: 0
A3: 43748 | B3: ZEEENT | C3: Sell | D3: 100 | E3: 247 | F3: 24700 | G3: 20191010N300013763 | H3: 2019190 | I3: Rolling | J3: IN302679-38296183 | K3: NSE | L3: 0 | M3: 0 | N3: 0 | O3: 0 | P3: 0
A4: 43748 | B4: INDHO | C4: Buy | D4: 250 | E4: 212.47 | F4: 53116.95 | G4: 20191010N300016520 | H4: 2019190 | I4: Rolling | J4: IN302679-38296183 | K4: NSE | L4: 0 | M4: 0 | N4: 0 | O4: 0 | P4: 0
A5: 43748 | B5: ZEEENT | C5: Buy | D5: 500 | E5: 245.3 | F5: 122650 | G5: 20191010N300017812 | H5: 2019190 | I5: Rolling | J5: IN302679-38296183 | K5: NSE | L5: 0 | M5: 0 | N5: 0 | O5: 0 | P5: 0
A6: 43748 | B6: ZEEENT | C6: Sell | D6: 400 | E6: 245.2 | F6: 98080 | G6: 20191010N300017897 | H6: 2019190 | I6: Rolling | J6: IN302679-38296183 | K6: NSE | L6: 0 | M6: 0 | N6: 0 | O6: 0 | P6: 0
A7: 43748 | B7: INDHO | C7: Buy | D7: 500 | E7: 201.38 | F7: 100691.95 | G7: 20191010N300021912 | H7: 2019190 | I7: Rolling | J7: IN302679-38296183 | K7: NSE | L7: 0 | M7: 0 | N7: 0 | O7: 0 | P7: 0
A8: 43748 | B8: INDHO | C8: Buy | D8: 250 | E8: 195 | F8: 48750 | G8: 20191010N300022202 | H8: 2019190 | I8: Rolling | J8: IN302679-38296183 | K8: NSE | L8: 0 | M8: 0 | N8: 0 | O8: 0 | P8: 0
A9: 43748 | B9: INDHO | C9: Sell | D9: 366 | E9: 193.13 | F9: 70685.85 | G9: 20191010N300025561 | H9: 2019190 | I9: Rolling | J9: IN302679-38296183 | K9: NSE | L9: 0 | M9: 0 | N9: 0 | O9: 0 | P9: 0
A10: 43748 | B10: INDHO | C10: Sell | D10: 384 | E10: 197.5 | F10: 75840 | G10: 20191010N300028251 | H10: 2019190 | I10: Rolling | J10: IN302679-38296183 | K10: NSE | L10: 0 | M10: 0 | N10: 0 | O10: 0 | P10: 0
A11: 43747 | B11: STABAN | C11: Buy | D11: 1000 | E11: 249.69 | F11: 249686.15 | G11: 20191009N200000658 | H11: 2019189 | I11: Rolling | J11: IN302679-38296183 | K11: NSE | L11: 0 | M11: 5.49 | N11: 0 | O11: 148.3 | P11: 153.793
A12: 43747 | B12: STABAN | C12: Buy | D12: 500 | E12: 246.2 | F12: 123100 | G12: 20191009N200024437 | H12: 2019189 | I12: Rolling | J12: IN302679-38296183 | K12: NSE | L12: 0 | M12: 2.71 | N12: 0 | O12: 73.12 | P12: 75.8282
A13: 43747 | B13: STABAN | C13: Sell | D13: 1500 | E13: 251 | F13: 376500 | G13: 20191009N200044713 | H13: 2019189 | I13: Rolling | J13: IN302679-38296183 | K13: NSE | L13: 93.66 | M13: 8.28 | N13: 0 | O13: 223.63 | P13: 325.573
... A1373: 40995 | B1373: MUTFIN | C1373: Buy | D1373: 6 | E1373: 139.45 | F1373: 836.7 | G1373: 20120327N900002419 | H1373: 2012059 | I1373: Rolling | J1373: IN302679-38296183 | K1373: NSE | L1373: 1 | M1373: 0.03 | N1373: 0.08 | O1373: 23.07 | P1373: 24.183

Sheet Buy
L1: BuyVal | O1: Sell Val | Q1: ValDiff | R1: P/L | S1: P | T1: L
L2: =SUM(L10:L1000) -> 1.0853083e+08 | O2: =SUM(O10:O1000) -> 1.0759367e+08 | Q2: =SUM(Q10:Q1000) -> -937160.79 | R2: =SUM(R10:R1000) -> -685647.23 | S2: =SUM(S10:S1000) -> 90506.622 | T2: =SUM(T10:T1000) -> -776153.85
R3: -5341.2691 | S3: 0 | T3: -5341.2691
R4: =R2+R3 -> -690988.5 | S4: =S2+S3 -> 90506.622 | T4: =T2+T3 -> -781495.12
A5: Action | B5: Buy
B7: Values
A8: Row Labels | B8: Sum of Qty | C8: Sum of Price | D8: Sum of Trade Value | E8: Sum of Brokerage incl. taxes | H8: Values | M8: SELL Lookup | P8: Analysis
A9: ARVLIM | B9: 100 | C9: 357 | D9: 35700 | E9: 271.1581 | G9: Row Labels | H9: Sum of Qty | I9: Sum of Price | J9: Sum of Trade Value | K9: Sum of Brokerage incl. taxes | L9: BuyVal | M9: Stk | N9: SQTY | O9: Sell Val | P9: QtyDiff | Q9: ValDiff | R9: P/L | S9: P | T9: L | U9: Status
A10: ASHLEY | B10: 8450 | C10: 670.25 | D10: 1020912.5 | E10: 759.6855 | G10: ARVLIM | H10: 100 | I10: 357 | J10: 35700 | K10: 271.1581 | L10: =J10+K10 -> 35971.158 | M10: =VLOOKUP(G10,Sell!G:L,1,0) -> ARVLIM | N10: =IFERROR(VLOOKUP(G10,Sell!G:L,2,0),0) -> 100 | O10: =IFERROR(VLOOKUP(G10,Sell!G:L,6,0),0) -> 37021.849 | P10: =H10-N10 -> 0 | Q10: =O10-L10 -> 1050.691 | R10: =IF(P10=0,Q10,0) -> 1050.691 | S10: =IF(R10>0,R10,0) -> 1050.691 | T10: =IF(R10>0,0,R10) -> 0 | U10: =IF(AND(LEN(G10)>0,R10=0),"Open","")
A11: CENBAN | B11: 349 | C11: 386.5 | D11: 24103.5 | E11: 250.6601 | G11: ASHLEY | H11: 8450 | I11: 670.25 | J11: 1020912.5 | K11: 759.6855 | L11: =J11+K11 -> 1021672.2 | M11: =VLOOKUP(G11,Sell!G:L,1,0) -> ASHLEY | N11: =IFERROR(VLOOKUP(G11,Sell!G:L,2,0),0) -> 8450 | O11: =IFERROR(VLOOKUP(G11,Sell!G:L,6,0),0) -> 1006804.7 | P11: =H11-N11 -> 0 | Q11: =O11-L11 -> -14867.491 | R11: =IF(P11=0,Q11,0) -> -14867.491 | S11: =IF(R11>0,R11,0) -> 0 | T11: =IF(R11>0,0,R11) -> -14867.491 | U11: =IF(AND(LEN(G11)>0,R11=0),"Open","")
A12: GATLIM | B12: 13139 | C12: 2621.8 | D12: 1756297.1 | E12: 4898.7724 | G12: CENBAN | H12: 349 | I12: 386.5 | J12: 24103.5 | K12: 250.6601 | L12: =J12+K12 -> 24354.16 | M12: =VLOOKUP(G12,Sell!G:L,1,0) -> CENBAN | N12: =IFERROR(VLOOKUP(G12,Sell!G:L,2,0),0) -> 349 | O12: =IFERROR(VLOOKUP(G12,Sell!G:L,6,0),0) -> 27668.997 | P12: =H12-N12 -> 0 | Q12: =O12-L12 -> 3314.8373 | R12: =IF(P12=0,Q12,0) -> 3314.8373 | S12: =IF(R12>0,R12,0) -> 3314.8373 | T12: =IF(R12>0,0,R12) -> 0 | U12: =IF(AND(LEN(G12)>0,R12=0),"Open","")
A13: GMRINF | B13: 25325 | C13: 200.39 | D13: 452689.75 | E13: 2312.3229 | G13: GATLIM | H13: 13139 | I13: 2621.8 | J13: 1756297.1 | K13: 4898.7724 | L13: =J13+K13 -> 1761195.8 | M13: =VLOOKUP(G13,Sell!G:L,1,0) -> GATLIM | N13: =IFERROR(VLOOKUP(G13,Sell!G:L,2,0),0) -> 13139 | O13: =IFERROR(VLOOKUP(G13,Sell!G:L,6,0),0) -> 1699130.4 | P13: =H13-N13 -> 0 | Q13: =O13-L13 -> -62065.465 | R13: =IF(P13=0,Q13,0) -> -62065.465 | S13: =IF(R13>0,R13,0) -> 0 | T13: =IF(R13>0,0,R13) -> -62065.465 | U13: =IF(AND(LEN(G13)>0,R13=0),"Open","")
A14: HINCOP | B14: 500 | C14: 77 | D14: 38500 | E14: 282.0019 | G14: GMRINF | H14: 25325 | I14: 200.39 | J14: 452689.75 | K14: 2312.3229 | L14: =J14+K14 -> 455002.07 | M14: =VLOOKUP(G14,Sell!G:L,1,0) -> GMRINF | N14: =IFERROR(VLOOKUP(G14,Sell!G:L,2,0),0) -> 25325 | O14: =IFERROR(VLOOKUP(G14,Sell!G:L,6,0),0) -> 419457.3 | P14: =H14-N14 -> 0 | Q14: =O14-L14 -> -35544.769 | R14: =IF(P14=0,Q14,0) -> -35544.769 | S14: =IF(R14>0,R14,0) -> 0 | T14: =IF(R14>0,0,R14) -> -35544.769 | U14: =IF(AND(LEN(G14)>0,R14=0),"Open","")
A15: INFTEC | B15: 300 | C15: 2680.61 | D15: 268061.4 | E15: 925.1126 | G15: HINCOP | H15: 500 | I15: 77 | J15: 38500 | K15: 282.0019 | L15: =J15+K15 -> 38782.002 | M15: =VLOOKUP(G15,Sell!G:L,1,0) -> HINCOP | N15: =IFERROR(VLOOKUP(G15,Sell!G:L,2,0),0) -> 500 | O15: =IFERROR(VLOOKUP(G15,Sell!G:L,6,0),0) -> 40200.412 | P15: =H15-N15 -> 0 | Q15: =O15-L15 -> 1418.4101 | R15: =IF(P15=0,Q15,0) -> 1418.4101 | S15: =IF(R15>0,R15,0) -> 1418.4101 | T15: =IF(R15>0,0,R15) -> 0 | U15: =IF(AND(LEN(G15)>0,R15=0),"Open","")
A16: JAIASS | B16: 500 | C16: 66 | D16: 33000 | E16: 238.618 | G16: INFTEC | H16: 300 | I16: 2680.61 | J16: 268061.4 | K16: 925.1126 | L16: =J16+K16 -> 268986.51 | M16: =VLOOKUP(G16,Sell!G:L,1,0) -> INFTEC | N16: =IFERROR(VLOOKUP(G16,Sell!G:L,2,0),0) -> 300 | O16: =IFERROR(VLOOKUP(G16,Sell!G:L,6,0),0) -> 269196.34 | P16: =H16-N16 -> 0 | Q16: =O16-L16 -> 209.8282 | R16: =IF(P16=0,Q16,0) -> 209.8282 | S16: =IF(R16>0,R16,0) -> 209.8282 | T16: =IF(R16>0,0,R16) -> 0 | U16: =IF(AND(LEN(G16)>0,R16=0),"Open","")
A17: JAIPOW | B17: 3000 | C17: 34.7 | D17: 46200 | E17: 335.6274 | G17: JAIASS | H17: 500 | I17: 66 | J17: 33000 | K17: 238.618 | L17: =J17+K17 -> 33238.618 | M17: =VLOOKUP(G17,Sell!G:L,1,0) -> JAIASS | N17: =IFERROR(VLOOKUP(G17,Sell!G:L,2,0),0) -> 500 | O17: =IFERROR(VLOOKUP(G17,Sell!G:L,6,0),0) -> 41444.437 | P17: =H17-N17 -> 0 | Q17: =O17-L17 -> 8205.8193 | R17: =IF(P17=0,Q17,0) -> 8205.8193 | S17: =IF(R17>0,R17,0) -> 8205.8193 | T17: =IF(R17>0,0,R17) -> 0 | U17: =IF(AND(LEN(G17)>0,R17=0),"Open","")
A18: JBCHEM | B18: 1381 | C18: 2024.17 | D18: 440892.9 | E18: 956.7433 | G18: JAIPOW | H18: 3000 | I18: 34.7 | J18: 46200 | K18: 335.6274 | L18: =J18+K18 -> 46535.627 | M18: =VLOOKUP(G18,Sell!G:L,1,0) -> JAIPOW | N18: =IFERROR(VLOOKUP(G18,Sell!G:L,2,0),0) -> 3000 | O18: =IFERROR(VLOOKUP(G18,Sell!G:L,6,0),0) -> 33499.015 | P18: =H18-N18 -> 0 | Q18: =O18-L18 -> -13036.612 | R18: =IF(P18=0,Q18,0) -> -13036.612 | S18: =IF(R18>0,R18,0) -> 0 | T18: =IF(R18>0,0,R18) -> -13036.612 | U18: =IF(AND(LEN(G18)>0,R18=0),"Open","")
A19: KOHFOO | B19: 1000 | C19: 78.65 | D19: 78650 | E19: 596.336 | G19: JBCHEM | H19: 1381 | I19: 2024.17 | J19: 440892.9 | K19: 956.7433 | L19: =J19+K19 -> 441849.64 | M19: =VLOOKUP(G19,Sell!G:L,1,0) -> JBCHEM | N19: =IFERROR(VLOOKUP(G19,Sell!G:L,2,0),0) -> 1381 | O19: =IFERROR(VLOOKUP(G19,Sell!G:L,6,0),0) -> 423470.77 | P19: =H19-N19 -> 0 | Q19: =O19-L19 -> -18378.877 | R19: =IF(P19=0,Q19,0) -> -18378.877 | S19: =IF(R19>0,R19,0) -> 0 | T19: =IF(R19>0,0,R19) -> -18378.877 | U19: =IF(AND(LEN(G19)>0,R19=0),"Open","")
A20: LANINF | B20: 3000 | C20: 14.5 | D20: 22250 | E20: 128.666 | G20: KOHFOO | H20: 1000 | I20: 78.65 | J20: 78650 | K20: 596.336 | L20: =J20+K20 -> 79246.336 | M20: =VLOOKUP(G20,Sell!G:L,1,0) -> KOHFOO | N20: =IFERROR(VLOOKUP(G20,Sell!G:L,2,0),0) -> 1000 | O20: =IFERROR(VLOOKUP(G20,Sell!G:L,6,0),0) -> 70805.881 | P20: =H20-N20 -> 0 | Q20: =O20-L20 -> -8440.4547 | R20: =IF(P20=0,Q20,0) -> -8440.4547 | S20: =IF(R20>0,R20,0) -> 0 | T20: =IF(R20>0,0,R20) -> -8440.4547 | U20: =IF(AND(LEN(G20)>0,R20=0),"Open","")
A21: LTOVER | B21: 24150 | C21: 1159.49 | D21: 1085738.4 | E21: 2897.3127 | G21: LANINF | H21: 3000 | I21: 14.5 | J21: 22250 | K21: 128.666 | L21: =J21+K21 -> 22378.666 | M21: =VLOOKUP(G21,Sell!G:L,1,0) -> LANINF | N21: =IFERROR(VLOOKUP(G21,Sell!G:L,2,0),0) -> 3000 | O21: =IFERROR(VLOOKUP(G21,Sell!G:L,6,0),0) -> 21011.857 | P21: =H21-N21 -> 0 | Q21: =O21-L21 -> -1366.8092 | R21: =IF(P21=0,Q21,0) -> -1366.8092 | S21: =IF(R21>0,R21,0) -> 0 | T21: =IF(R21>0,0,R21) -> -1366.8092 | U21: =IF(AND(LEN(G21)>0,R21=0),"Open","")
... A23: MINLIM | B23: 1910 | C23: 11089.36 | D23: 1766671.3 | E23: 2051.7022 | G23: MANAFI | H23: 100 | I23: 92 | J23: 9200 | K23: 68.4936 | L23: =J23+K23 -> 9268.4936 | M23: =VLOOKUP(G23,Sell!G:L,1,0) -> MANAFI | N23: =IFERROR(VLOOKUP(G23,Sell!G:L,2,0),0) -> 100 | O23: =IFERROR(VLOOKUP(G23,Sell!G:L,6,0),0) -> 9670.4983 | P23: =H23-N23 -> 0 | Q23: =O23-L23 -> 402.0047 | R23: =IF(P23=0,Q23,0) -> 402.0047 | S23: =IF(R23>0,R23,0) -> 402.0047 | T23: =IF(R23>0,0,R23) -> 0 | U23: =IF(AND(LEN(G23)>0,R23=0),"Open","")
A24: MUTFIN | B24: 4823 | C24: 4118.8 | D24: 1947209.4 | E24: 5034.4991 | G24: MINLIM | H24: 1910 | I24: 11089.36 | J24: 1766671.3 | K24: 2051.7022 | L24: =J24+K24 -> 1768723 | M24: =VLOOKUP(G24,Sell!G:L,1,0) -> MINLIM | N24: =IFERROR(VLOOKUP(G24,Sell!G:L,2,0),0) -> 1920 | O24: =IFERROR(VLOOKUP(G24,Sell!G:L,6,0),0) -> 1725729.5 | P24: 0 | Q24: =O24-L24 -> -42993.528 | R24: =IF(P24=0,Q24,0) -> -42993.528 | S24: =IF(R24>0,R24,0) -> 0 | T24: =IF(R24>0,0,R24) -> -42993.528 | U24: =IF(AND(LEN(G24)>0,R24=0),"Open","")
A25: NHPC | B25: 700 | C25: 20 | D25: 14000 | E25: 102.424 | G25: MUTFIN | H25: 4823 | I25: 4118.8 | J25: 1947209.4 | K25: 5034.4991 | L25: =J25+K25 -> 1952243.9 | M25: =VLOOKUP(G25,Sell!G:L,1,0) -> MUTFIN | N25: =IFERROR(VLOOKUP(G25,Sell!G:L,2,0),0) -> 4823 | O25: =IFERROR(VLOOKUP(G25,Sell!G:L,6,0),0) -> 1923326.4 | P25: =H25-N25 -> 0 | Q25: =O25-L25 -> -28917.591 | R25: =IF(P25=0,Q25,0) -> -28917.591 | S25: =IF(R25>0,R25,0) -> 0 | T25: =IF(R25>0,0,R25) -> -28917.591 | U25: =IF(AND(LEN(G25)>0,R25=0),"Open","")
A26: PUNBAN | B26: 5500 | C26: 635.75 | D26: 482800 | E26: 781.7997 | G26: NHPC | H26: 700 | I26: 20 | J26: 14000 | K26: 102.424 | L26: =J26+K26 -> 14102.424 | M26: =VLOOKUP(G26,Sell!G:L,1,0) -> NHPC | N26: =IFERROR(VLOOKUP(G26,Sell!G:L,2,0),0) -> 700 | O26: =IFERROR(VLOOKUP(G26,Sell!G:L,6,0),0) -> 14176.956 | P26: =H26-N26 -> 0 | Q26: =O26-L26 -> 74.5319 | R26: =IF(P26=0,Q26,0) -> 74.5319 | S26: =IF(R26>0,R26,0) -> 74.5319 | T26: =IF(R26>0,0,R26) -> 0 | U26: =IF(AND(LEN(G26)>0,R26=0),"Open","")
A27: RELDEF | B27: 11500 | C27: 658.35 | D27: 674385.3 | E27: 4912.8277 | G27: PUNBAN | H27: 5500 | I27: 635.75 | J27: 482800 | K27: 781.7997 | L27: =J27+K27 -> 483581.8 | M27: =VLOOKUP(G27,Sell!G:L,1,0) -> PUNBAN | N27: =IFERROR(VLOOKUP(G27,Sell!G:L,2,0),0) -> 5500 | O27: =IFERROR(VLOOKUP(G27,Sell!G:L,6,0),0) -> 474990.86 | P27: =H27-N27 -> 0 | Q27: =O27-L27 -> -8590.9382 | R27: =IF(P27=0,Q27,0) -> -8590.9382 | S27: =IF(R27>0,R27,0) -> 0 | T27: =IF(R27>0,0,R27) -> -8590.9382 | U27: =IF(AND(LEN(G27)>0,R27=0),"Open","")
A28: RELPOW | B28: 575 | C28: 212 | D28: 60500 | E28: 441.1785 | G28: RELDEF | H28: 11500 | I28: 658.35 | J28: 674385.3 | K28: 4912.8277 | L28: =J28+K28 -> 679298.13 | M28: =VLOOKUP(G28,Sell!G:L,1,0) -> RELDEF | N28: =IFERROR(VLOOKUP(G28,Sell!G:L,2,0),0) -> 11500 | O28: =IFERROR(VLOOKUP(G28,Sell!G:L,6,0),0) -> 725840.37 | P28: =H28-N28 -> 0 | Q28: =O28-L28 -> 46542.244 | R28: =IF(P28=0,Q28,0) -> 46542.244 | S28: =IF(R28>0,R28,0) -> 46542.244 | T28: =IF(R28>0,0,R28) -> 0 | U28: =IF(AND(LEN(G28)>0,R28=0),"Open","")
A29: SUNADV | B29: 410 | C29: 1081 | D29: 131300 | E29: 729.6643 | G29: RELPOW | H29: 575 | I29: 212 | J29: 60500 | K29: 441.1785 | L29: =J29+K29 -> 60941.179 | M29: =VLOOKUP(G29,Sell!G:L,1,0) -> RELPOW | N29: =IFERROR(VLOOKUP(G29,Sell!G:L,2,0),0) -> 575 | O29: =IFERROR(VLOOKUP(G29,Sell!G:L,6,0),0) -> 37733.204 | P29: =H29-N29 -> 0 | Q29: =O29-L29 -> -23207.975 | R29: =IF(P29=0,Q29,0) -> -23207.975 | S29: =IF(R29>0,R29,0) -> 0 | T29: =IF(R29>0,0,R29) -> -23207.975 | U29: =IF(AND(LEN(G29)>0,R29=0),"Open","")
A30: SUNPHA | B30: 1640 | C30: 2708.2 | D30: 692344 | E30: 621.7325 | G30: SUNADV | H30: 410 | I30: 1081 | J30: 131300 | K30: 729.6643 | L30: =J30+K30 -> 132029.66 | M30: =VLOOKUP(G30,Sell!G:L,1,0) -> SUNADV | N30: =IFERROR(VLOOKUP(G30,Sell!G:L,2,0),0) -> 410 | O30: =IFERROR(VLOOKUP(G30,Sell!G:L,6,0),0) -> 123341.67 | P30: =H30-N30 -> 0 | Q30: =O30-L30 -> -8687.9977 | R30: =IF(P30=0,Q30,0) -> -8687.9977 | S30: =IF(R30>0,R30,0) -> 0 | T30: =IF(R30>0,0,R30) -> -8687.9977 | U30: =IF(AND(LEN(G30)>0,R30=0),"Open","")
A31: TATPOW | B31: 1000 | C31: 69 | D31: 69000 | E31: 512.8071 | G31: SUNPHA | H31: 1640 | I31: 2708.2 | J31: 692344 | K31: 621.7325 | L31: =J31+K31 -> 692965.73 | M31: =VLOOKUP(G31,Sell!G:L,1,0) -> SUNPHA | N31: =IFERROR(VLOOKUP(G31,Sell!G:L,2,0),0) -> 1640 | O31: =IFERROR(VLOOKUP(G31,Sell!G:L,6,0),0) -> 689597.96 | P31: =H31-N31 -> 0 | Q31: =O31-L31 -> -3367.7699 | R31: =IF(P31=0,Q31,0) -> -3367.7699 | S31: =IF(R31>0,R31,0) -> 0 | T31: =IF(R31>0,0,R31) -> -3367.7699 | U31: =IF(AND(LEN(G31)>0,R31=0),"Open","")
A32: TVSMOT | B32: 200 | C32: 767.93 | D32: 76793.35 | E32: 578.464 | G32: TATPOW | H32: 1000 | I32: 69 | J32: 69000 | K32: 512.8071 | L32: =J32+K32 -> 69512.807 | M32: =VLOOKUP(G32,Sell!G:L,1,0) -> TATPOW | N32: =IFERROR(VLOOKUP(G32,Sell!G:L,2,0),0) -> 1000 | O32: =IFERROR(VLOOKUP(G32,Sell!G:L,6,0),0) -> 69663.034 | P32: =H32-N32 -> 0 | Q32: =O32-L32 -> 150.2264 | R32: =IF(P32=0,Q32,0) -> 150.2264 | S32: =IF(R32>0,R32,0) -> 150.2264 | T32: =IF(R32>0,0,R32) -> 0 | U32: =IF(AND(LEN(G32)>0,R32=0),"Open","")
A33: ZENINF | B33: 475 | C33: 11.15 | D33: 5296.25 | E33: 45.0191 | G33: TVSMOT | H33: 200 | I33: 767.93 | J33: 76793.35 | K33: 578.464 | L33: =J33+K33 -> 77371.814 | M33: =VLOOKUP(G33,Sell!G:L,1,0) -> TVSMOT | N33: =IFERROR(VLOOKUP(G33,Sell!G:L,2,0),0) -> 200 | O33: =IFERROR(VLOOKUP(G33,Sell!G:L,6,0),0) -> 79332.533 | P33: =H33-N33 -> 0 | Q33: =O33-L33 -> 1960.7186 | R33: =IF(P33=0,Q33,0) -> 1960.7186 | S33: =IF(R33>0,R33,0) -> 1960.7186 | T33: =IF(R33>0,0,R33) -> 0 | U33: =IF(AND(LEN(G33)>0,R33=0),"Open","")
A34: SUZENE | B34: 27500 | C34: 95.15 | D34: 439375 | E34: 2194.7199 | G34: ZENINF | H34: 475 | I34: 11.15 | J34: 5296.25 | K34: 45.0191 | L34: =J34+K34 -> 5341.2691 | M34: =VLOOKUP(G34,Sell!G:L,1,0) -> #N/A | N34: =IFERROR(VLOOKUP(G34,Sell!G:L,2,0),0) -> 0 | O34: =IFERROR(VLOOKUP(G34,Sell!G:L,6,0),0) -> 0 | P34: =H34-N34 -> 475 | Q34: =O34-L34 -> -5341.2691 | R34: =IF(P34=0,Q34,0) -> 0 | S34: =IF(R34>0,R34,0) -> 0 | T34: =IF(R34>0,0,R34) -> 0 | U34: =IF(AND(LEN(G34)>0,R34=0),"Open","") -> Open
A35: FINCHE | B35: 10250 | C35: 908.37 | D35: 709439.05 | E35: 3494.3405 | G35: SUZENE | H35: 27500 | I35: 95.15 | J35: 439375 | K35: 2194.7199 | L35: =J35+K35 -> 441569.72 | M35: =VLOOKUP(G35,Sell!G:L,1,0) -> SUZENE | N35: =IFERROR(VLOOKUP(G35,Sell!G:L,2,0),0) -> 27500 | O35: =IFERROR(VLOOKUP(G35,Sell!G:L,6,0),0) -> 436255.19 | P35: =H35-N35 -> 0 | Q35: =O35-L35 -> -5314.5313 | R35: =IF(P35=0,Q35,0) -> -5314.5313 | S35: =IF(R35>0,R35,0) -> 0 | T35: =IF(R35>0,0,R35) -> -5314.5313 | U35: =IF(AND(LEN(G35)>0,R35=0),"Open","")
A36: BANMAH | B36: 5000 | C36: 24 | D36: 120000 | E36: 82.6 | G36: FINCHE | H36: 10250 | I36: 908.37 | J36: 709439.05 | K36: 3494.3405 | L36: =J36+K36 -> 712933.39 | M36: =VLOOKUP(G36,Sell!G:L,1,0) -> FINCHE | N36: =IFERROR(VLOOKUP(G36,Sell!G:L,2,0),0) -> 9850 | O36: =IFERROR(VLOOKUP(G36,Sell!G:L,6,0),0) -> 689043.33 | P36: =H36-N36 -> 400 | Q36: =O36-L36 -> -23890.056 | R36: =IF(P36=0,Q36,0) -> 0 | S36: =IF(R36>0,R36,0) -> 0 | T36: =IF(R36>0,0,R36) -> 0 | U36: =IF(AND(LEN(G36)>0,R36=0),"Open","") -> Open
... A118: Grand Total | B118: 721333 | C118: 184740.78 | D118: 1.0839727e+08 | E118: 133558.56 | G118: INDHO | H118: 1000 | I118: 608.85 | J118: 202558.9 | K118: 0 | L118: =J118+K118 -> 202558.9 | M118: =VLOOKUP(G118,Sell!G:L,1,0) -> INDHO | N118: =IFERROR(VLOOKUP(G118,Sell!G:L,2,0),0) -> 1000 | O118: =IFERROR(VLOOKUP(G118,Sell!G:L,6,0),0) -> 206525.85 | P118: =H118-N118 -> 0 | Q118: =O118-L118 -> 3966.95 | R118: =IF(P118=0,Q118,0) -> 3966.95 | S118: =IF(R118>0,R118,0) -> 3966.95 | T118: =IF(R118>0,0,R118) -> 0 | U118: =IF(AND(LEN(G118)>0,R118=0),"Open","")
L119: =J119+K119 -> 0 | M119: =VLOOKUP(G119,Sell!G:L,1,0) -> #N/A | N119: =IFERROR(VLOOKUP(G119,Sell!G:L,2,0),0) -> 0 | O119: =IFERROR(VLOOKUP(G119,Sell!G:L,6,0),0) -> 0 | P119: =H119-N119 -> 0 | Q119: =O119-L119 -> 0 | R119: =IF(P119=0,Q119,0) -> 0 | S119: =IF(R119>0,R119,0) -> 0 | T119: =IF(R119>0,0,R119) -> 0 | U119: =IF(AND(LEN(G119)>0,R119=0),"Open","")
L120: =J120+K120 -> 0 | M120: =VLOOKUP(G120,Sell!G:L,1,0) -> #N/A | N120: =IFERROR(VLOOKUP(G120,Sell!G:L,2,0),0) -> 0 | O120: =IFERROR(VLOOKUP(G120,Sell!G:L,6,0),0) -> 0 | P120: =H120-N120 -> 0 | Q120: =O120-L120 -> 0 | R120: =IF(P120=0,Q120,0) -> 0 | S120: =IF(R120>0,R120,0) -> 0 | T120: =IF(R120>0,0,R120) -> 0 | U120: =IF(AND(LEN(G120)>0,R120=0),"Open","")
L121: =J121+K121 -> 0 | M121: =VLOOKUP(G121,Sell!G:L,1,0) -> #N/A | N121: =IFERROR(VLOOKUP(G121,Sell!G:L,2,0),0) -> 0 | O121: =IFERROR(VLOOKUP(G121,Sell!G:L,6,0),0) -> 0 | P121: =H121-N121 -> 0 | Q121: =O121-L121 -> 0 | R121: =IF(P121=0,Q121,0) -> 0 | S121: =IF(R121>0,R121,0) -> 0 | T121: =IF(R121>0,0,R121) -> 0 | U121: =IF(AND(LEN(G121)>0,R121=0),"Open","")
L122: =J122+K122 -> 0 | M122: =VLOOKUP(G122,Sell!G:L,1,0) -> #N/A | N122: =IFERROR(VLOOKUP(G122,Sell!G:L,2,0),0) -> 0 | O122: =IFERROR(VLOOKUP(G122,Sell!G:L,6,0),0) -> 0 | P122: =H122-N122 -> 0 | Q122: =O122-L122 -> 0 | R122: =IF(P122=0,Q122,0) -> 0 | S122: =IF(R122>0,R122,0) -> 0 | T122: =IF(R122>0,0,R122) -> 0 | U122: =IF(AND(LEN(G122)>0,R122=0),"Open","")
L123: =J123+K123 -> 0 | M123: =VLOOKUP(G123,Sell!G:L,1,0) -> #N/A | N123: =IFERROR(VLOOKUP(G123,Sell!G:L,2,0),0) -> 0 | O123: =IFERROR(VLOOKUP(G123,Sell!G:L,6,0),0) -> 0 | P123: =H123-N123 -> 0 | Q123: =O123-L123 -> 0 | R123: =IF(P123=0,Q123,0) -> 0 | S123: =IF(R123>0,R123,0) -> 0 | T123: =IF(R123>0,0,R123) -> 0 | U123: =IF(AND(LEN(G123)>0,R123=0),"Open","")
...

Sheet Sell
A1: Action | B1: Sell
B3: Values | H3: Values
A4: Row Labels | B4: Sum of Qty | C4: Sum of Price | D4: Sum of Trade Value | E4: Sum of Brokerage incl. taxes | G4: Row Labels | H4: Sum of Qty | I4: Sum of Price | J4: Sum of Trade Value | K4: Sum of Brokerage incl. taxes | L4: SellValue
A5: ARVLIM | B5: 100 | C5: 373 | D5: 37300 | E5: 278.1509 | G5: ARVLIM | H5: 100 | I5: 373 | J5: 37300 | K5: 278.1509 | L5: =J5-K5 -> 37021.849
A6: ASHLEY | B6: 8450 | C6: 1026.24 | D6: 1007879.8 | E6: 1075.1057 | G6: ASHLEY | H6: 8450 | I6: 1026.24 | J6: 1007879.8 | K6: 1075.1057 | L6: =J6-K6 -> 1006804.7
A7: CENBAN | B7: 349 | C7: 159.2 | D7: 27900 | E7: 231.0026 | G7: CENBAN | H7: 349 | I7: 159.2 | J7: 27900 | K7: 231.0026 | L7: =J7-K7 -> 27668.997
A8: GATLIM | B8: 13139 | C8: 2026.98 | D8: 1703019.6 | E8: 3889.2426 | G8: GATLIM | H8: 13139 | I8: 2026.98 | J8: 1703019.6 | K8: 3889.2426 | L8: =J8-K8 -> 1699130.4
A9: GMRINF | B9: 25325 | C9: 145.36 | D9: 421590 | E9: 2132.6962 | G9: GMRINF | H9: 25325 | I9: 145.36 | J9: 421590 | K9: 2132.6962 | L9: =J9-K9 -> 419457.3
A10: HINCOP | B10: 500 | C10: 81 | D10: 40500 | E10: 299.588 | G10: HINCOP | H10: 500 | I10: 81 | J10: 40500 | K10: 299.588 | L10: =J10-K10 -> 40200.412
A11: INFTEC | B11: 300 | C11: 2702 | D11: 270200 | E11: 1003.6592 | G11: INFTEC | H11: 300 | I11: 2702 | J11: 270200 | K11: 1003.6592 | L11: =J11-K11 -> 269196.34
A12: JAIASS | B12: 500 | C12: 83.5 | D12: 41750 | E12: 305.5627 | G12: JAIASS | H12: 500 | I12: 83.5 | J12: 41750 | K12: 305.5627 | L12: =J12-K12 -> 41444.437
A13: JAIPOW | B13: 3000 | C13: 23.4 | D13: 33750 | E13: 250.9846 | G13: JAIPOW | H13: 3000 | I13: 23.4 | J13: 33750 | K13: 250.9846 | L13: =J13-K13 -> 33499.015
A14: JBCHEM | B14: 1381 | C14: 1615.44 | D14: 424303.55 | E14: 832.7839 | G14: JBCHEM | H14: 1381 | I14: 1615.44 | J14: 424303.55 | K14: 832.7839 | L14: =J14-K14 -> 423470.77
A15: KOHFOO | B15: 1000 | C15: 71.35 | D15: 71345.05 | E15: 539.1687 | G15: KOHFOO | H15: 1000 | I15: 71.35 | J15: 71345.05 | K15: 539.1687 | L15: =J15-K15 -> 70805.881
A16: LANINF | B16: 3000 | C16: 14.6 | D16: 21200 | E16: 188.1432 | G16: LANINF | H16: 3000 | I16: 14.6 | J16: 21200 | K16: 188.1432 | L16: =J16-K16 -> 21011.857
... A112: INDHO | B112: 1000 | C112: 630.63 | D112: 206525.85 | E112: 0 | G112: INDHO | H112: 1000 | I112: 630.63 | J112: 206525.85 | K112: 0 | L112: =J112-K112 -> 206525.85
A113: Grand Total | B113: 718813 | C113: 167248.16 | D113: 107746859 | E113: 153186.23 | L113: =J113-K113 -> 0
L114: =J114-K114 -> 0
L115: =J115-K115 -> 0
L116: =J116-K116 -> 0
L117: =J117-K117 -> 0
L118: =J118-K118 -> 0
L119: =J119-K119 -> 0
L120: =J120-K120 -> 0
L121: =J121-K121 -> 0
L122: =J122-K122 -> 0
L123: =J123-K123 -> 0
L124: =J124-K124 -> 0
L125: =J125-K125 -> 0
... L1000: =J1000-K1000 -> 0

Sheet P and L
A1: Status
A3: Row Labels | B3: Sum of P/L | F3: Row Labels | G3: Sum of P/L
A4: ARRGRE | B4: 433.8164 | F4: ICIBAN | G4: -88856.136
A5: ARVLIM | B5: 1050.691 | F5: SINPLA | G5: -77773.549
A6: ASHLEY | B6: -14867.491 | F6: GATLIM | G6: -62065.465
A7: BANBAR | B7: -3590.2206 | F7: MINLIM | G7: -42993.528
A8: BANMAH | B8: -1936.9032 | F8: GMRINF | G8: -35544.769
A9: BHAELE | B9: -16431.7 | F9: HINPET | G9: -33094.949
A10: BHEL | B10: 3821.0238 | F10: CANHOM | G10: -29205.768
A11: BHUST | B11: -13399.066 | F11: MUTFIN | G11: -28917.591
A12: BURCEM | B12: -28608.626 | F12: BURCEM | G12: -28608.626
A13: CANHOM | B13: -29205.768 | F13: FEDBAN | G13: -28238.223
A14: CENBAN | B14: 3314.8373 | F14: RELPOW | G14: -23207.975
A15: CROGRE | B15: 1.6078 | F15: NAGCON | G15: -22830.282
... A105: WELCOR | B105: 178.7102 | F105: RELDEF | G105: 46542.244
A106: INDHO | B106: 3966.95
A107: Grand Total | B107: -685647.23
