Workbook

Sheet Sheet2
A1: Stock | B1: YESBAN
A3: Sum of Qty | B3: Column Labels
A4: Row Labels | B4: Buy | C4: Sell | D4: Grand Total
A5: 43368 | B5: 1000 | C5: 1000 | D5: 2000 | E5: =B5-C5 -> 0
A6: 43370 | B6: 1000 | C6: 1000 | D6: 2000 | E6: =B6-C6 -> 0
A7: 43388 | B7: 2000 | C7: 2000 | D7: 4000 | E7: =B7-C7 -> 0
A8: 43630 | B8: 3000 | C8: 3000 | D8: 6000 | E8: =B8-C8 -> 0
A9: 43635 | B9: 500 | C9: 500 | D9: 1000 | E9: =B9-C9 -> 0
A10: 43636 | B10: 1000 | C10: 1000 | D10: 2000 | E10: =B10-C10 -> 0
A11: 43640 | B11: 2500 | C11: 2500 | D11: 5000 | E11: =B11-C11 -> 0
A12: 43671 | B12: 250 | C12: 250 | D12: 500 | E12: =B12-C12 -> 0
A13: 43676 | B13: 100 | C13: 100 | D13: 200 | E13: =B13-C13 -> 0
A14: 43707 | B14: 1000 | C14: 1000 | D14: 2000 | E14: =B14-C14 -> 0
A15: 43727 | B15: 10 | D15: 10 | E15: =B15-C15 -> 10
A16: 43735 | B16: 10 | D16: 10 | E16: =B16-C16 -> 10
A17: 43738 | B17: 30 | D17: 30 | E17: =B17-C17 -> 30
A18: 43739 | B18: 125 | D18: 125 | E18: =B18-C18 -> 125
A19: 43769 | B19: 25 | D19: 25 | E19: =B19-C19 -> 25
A20: 43818 | B20: 5000 | D20: 5000 | E20: =B20-C20 -> 5000
A21: 43822 | B21: 5000 | C21: 10000 | D21: 15000 | E21: =B21-C21 -> -5000
A22: 43843 | B22: 50 | D22: 50 | E22: =B22-C22 -> 50
A23: 43844 | B23: 50 | D23: 50 | E23: =B23-C23 -> 50
A24: 43866 | B24: 200 | D24: 200 | E24: =B24-C24 -> 200
A25: 43893 | B25: 250 | D25: 250 | E25: =B25-C25 -> 250
A26: 43894 | B26: 250 | D26: 250 | E26: =B26-C26 -> 250
A27: 43895 | B27: 100 | D27: 100 | E27: =B27-C27 -> 100
A28: 43899 | B28: 1000 | D28: 1000 | E28: =B28-C28 -> 1000
A29: 44007 | B29: 100 | D29: 100 | E29: =B29-C29 -> 100
A30: 44013 | B30: 100 | D30: 100 | E30: =B30-C30 -> 100
A31: 44019 | B31: 100 | D31: 100 | E31: =B31-C31 -> 100
A32: 44040 | B32: 100 | D32: 100 | E32: =B32-C32 -> 100
A33: 44204 | B33: 100 | D33: 100 | E33: =B33-C33 -> 100
... A40: 45349 | B40: 1000 | D40: 1000 | E40: =B40-C40 -> 1000
A41: 45350 | C41: 5000 | D41: 5000 | E41: =B41-C41 -> -5000
A42: 45523 | C42: 500 | D42: 500 | E42: =SUM(E5:E41) -> 500
A43: Grand Total | B43: 27850 | C43: 27850 | D43: 55700

Sheet 8502271974_TradeBook
A1: Date | B1: Stock | C1: Action | D1: Qty | E1: Price | F1: Trade Value | G1: Order Ref. | H1: Settlement | I1: Segment | J1: DP Id - Client DP Id | K1: Exchange | L1: STT | M1: Transaction and SEBI Turnover charges | N1: Stamp Duty | O1: Brokerage + Service Tax | P1: Brokerage incl. taxes
A2: 40995 | B2: MUTFIN | C2: Buy | D2: 6 | E2: 139.45 | F2: 836.7 | G2: 20120327N900002419 | H2: 2012059 | I2: Rolling | J2: IN302679-38296183 | K2: NSE | L2: 1 | M2: 0.03 | N2: 0.08 | O2: 23.07 | P2: 24.183
A3: 41079 | B3: MUTFIN | C3: Sell | D3: 5 | E3: 121.45 | F3: 607.25 | G3: 20120619N100000027 | H3: 2012116 | I3: Rolling | J3: IN302679-38296183 | K3: NSE | L3: 1 | M3: 0.02 | N3: 0.06 | O3: 17.05 | P3: 18.1325
A4: 41263 | B4: MUTFIN | C4: Buy | D4: 10 | E4: 205.2 | F4: 2052 | G4: 20121220N600000154 | H4: 2012241 | I4: Rolling | J4: IN302679-38296183 | K4: NSE | L4: 2 | M4: 0.07 | N4: 0.21 | O4: 39.33 | P4: 41.6091
A5: 41269 | B5: MUTFIN | C5: Buy | D5: 7 | E5: 196.3 | F5: 1374.1 | G5: 20121226N600000243 | H5: 2012244 | I5: Rolling | J5: IN302679-38296183 | K5: NSE | L5: 1 | M5: 0.05 | N5: 0.14 | O5: 38.6 | P5: 39.7869
A6: 41274 | B6: CENBAN | C6: Buy | D6: 12 | E6: 84.1 | F6: 1009.2 | G6: 20121231N500007436 | H6: 2012247 | I6: Rolling | J6: IN302679-38296183 | K6: NSE | L6: 0.99 | M6: 0.04 | N6: 0 | O6: 28.35 | P6: 29.3763
A7: 41274 | B7: CENBAN | C7: Buy | D7: 12 | E7: 83.9 | F7: 1006.8 | G7: 20121231N600001615 | H7: 2012247 | I7: Rolling | J7: IN302679-38296183 | K7: NSE | L7: 1.01 | M7: 0.04 | N7: 0.2 | O7: 28.28 | P7: 29.5278
A8: 41282 | B8: GMRINF | C8: Buy | D8: 75 | E8: 20.15 | F8: 1511.25 | G8: 20130108N500013186 | H8: 2013006 | I8: Rolling | J8: IN302679-38296183 | K8: NSE | L8: 2 | M8: 0.05 | N8: 0.15 | O8: 39.33 | P8: 41.5355
A9: 41352 | B9: GMRINF | C9: Sell | D9: 75 | E9: 21.5 | F9: 1612.5 | G9: 20130319N600003247 | H9: 2013056 | I9: Rolling | J9: IN302679-38296183 | K9: NSE | L9: 2 | M9: 0.06 | N9: 0.16 | O9: 39.33 | P9: 41.5494
A10: 41414 | B10: MUTFIN | C10: Buy | D10: 100 | E10: 157.1 | F10: 15710 | G10: 20130520B100002658 | H10: 201314036 | I10: Rolling | J10: IN302679-38296183 | K10: BSE | L10: 16 | M10: 0.5 | N10: 1.57 | O10: 97.08 | P10: 115.1536
A11: 41463 | B11: MUTFIN | C11: Buy | D11: 50 | E11: 95.9 | F11: 4795 | G11: 20130708B100001936 | H11: 201314071 | I11: Rolling | J11: IN302679-38296183 | K11: BSE | L11: 5 | M11: 0.15 | N11: 0.48 | O11: 39.33 | P11: 44.9629
A12: 41470 | B12: MUTFIN | C12: Sell | D12: 50 | E12: 100.1 | F12: 5005 | G12: 20130715N500012051 | H12: 2013135 | I12: Rolling | J12: IN302679-38296183 | K12: NSE | L12: 5 | M12: 0.18 | N12: 0.5 | O12: 39.33 | P12: 45.0107
A13: 41477 | B13: MUTFIN | C13: Buy | D13: 100 | E13: 97 | F13: 9700 | G13: 20130722N600000032 | H13: 2013140 | I13: Rolling | J13: IN302679-38296183 | K13: NSE | L13: 10 | M13: 0.35 | N13: 0.97 | O13: 59.94 | P13: 71.2592
... A1116: 43628 | B1116: BANIND | C1116: Buy | D1116: 5000 | E1116: 87.5 | F1116: 437500 | G1116: 20190612N300022940 | H1116: 2019110 | I1116: Rolling | J1116: IN302679-38296183 | K1116: NSE | L1116: 0 | M1116: 15.75 | N1116: 0 | O1116: 260.96 | P1116: 276.71
A1117: 43628 | B1117: BIOCON | C1117: Buy | D1117: 10 | E1117: 0 | F1117: 0 | G1117: 20190502N300028221 | H1117: 2019082 | I1117: Rolling | J1117: IN302679-38296183 | K1117: NSE | L1117: 0 | M1117: 0 | N1117: 0 | O1117: 0 | P1117: 0 | Q1117: Bonus Issue 1:1
A1118: 43629 | B1118: BIOCON | C1118: Sell | D1118: 2000 | E1118: 253.5 | F1118: 507000 | G1118: 20190613N300016875 | H1118: 2019111 | I1118: Rolling | J1118: IN302679-38296183 | K1118: NSE | L1118: 126.49 | M1118: 18.25 | N1118: 49.5 | O1118: 302.4 | P1118: 496.6423
A1119: 43629 | B1119: BIOCON | C1119: Buy | D1119: 2000 | E1119: 252.5 | F1119: 505000 | G1119: 20190613N300017249 | H1119: 2019111 | I1119: Rolling | J1119: IN302679-38296183 | K1119: NSE | L1119: 0 | M1119: 18.18 | N1119: 0 | O1119: 301.23 | P1119: 319.41
A1120: 43629 | B1120: RELIND | C1120: Sell | D1120: 10 | E1120: 1323 | F1120: 13230 | G1120: 20190613N300020046 | H1120: 2019111 | I1120: Rolling | J1120: IN302679-38296183 | K1120: NSE | L1120: 3.3 | M1120: 0.48 | N1120: 0 | O1120: 29.59 | P1120: 33.3663
A1121: 43629 | B1121: BIOCON | C1121: Sell | D1121: 1000 | E1121: 252 | F1121: 252000 | G1121: 20190613N300020100 | H1121: 2019111 | I1121: Rolling | J1121: IN302679-38296183 | K1121: NSE | L1121: 63.14 | M1121: 9.07 | N1121: 0 | O1121: 150.31 | P1121: 222.522
A1122: 43629 | B1122: BIOCON | C1122: Buy | D1122: 1000 | E1122: 251.25 | F1122: 251250 | G1122: 20190613N300020300 | H1122: 2019111 | I1122: Rolling | J1122: IN302679-38296183 | K1122: NSE | L1122: 0 | M1122: 9.05 | N1122: 0 | O1122: 149.87 | P1122: 158.9151
A1123: 43629 | B1123: RELIND | C1123: Buy | D1123: 10 | E1123: 1317 | F1123: 13170 | G1123: 20190613N300020333 | H1123: 2019111 | I1123: Rolling | J1123: IN302679-38296183 | K1123: NSE | L1123: 0 | M1123: 0.47 | N1123: 0 | O1123: 29.59 | P1123: 30.0642
A1124: 43629 | B1124: NATMIN | C1124: Sell | D1124: 500 | E1124: 104.5 | F1124: 52250 | G1124: 20190613N300025384 | H1124: 2019111 | I1124: Rolling | J1124: IN302679-38296183 | K1124: NSE | L1124: 13.11 | M1124: 1.88 | N1124: 0 | O1124: 31.17 | P1124: 46.1611
A1125: 43629 | B1125: NATMIN | C1125: Buy | D1125: 500 | E1125: 105.3 | F1125: 52650 | G1125: 20190613N300025535 | H1125: 2019111 | I1125: Rolling | J1125: IN302679-38296183 | K1125: NSE | L1125: 0 | M1125: 1.9 | N1125: 0 | O1125: 31.4 | P1125: 33.2955
A1126: 43629 | B1126: JETAIR | C1126: Sell | D1126: 20 | E1126: 98 | F1126: 1960 | G1126: 20190613N900015727 | H1126: 2019111 | I1126: Rolling | J1126: IN302679-38296183 | K1126: NSE | L1126: 1.96 | M1126: 0.07 | N1126: 0 | O1126: 41.31 | P1126: 43.3406
A1127: 43630 | B1127: YESBAN | C1127: Sell | D1127: 1000 | E1127: 115 | F1127: 115000 | G1127: 20190614N300017279 | H1127: 2019112 | I1127: Rolling | J1127: IN302679-38296183 | K1127: NSE | L1127: 29.01 | M1127: 4.14 | N1127: 0 | O1127: 68.6 | P1127: 101.75
A1128: 43630 | B1128: YESBAN | C1128: Buy | D1128: 1000 | E1128: 113 | F1128: 113000 | G1128: 20190614N300017360 | H1128: 2019112 | I1128: Rolling | J1128: IN302679-38296183 | K1128: NSE | L1128: 0 | M1128: 4.07 | N1128: 0 | O1128: 67.4 | P1128: 71.468
A1129: 43630 | B1129: RELINF | C1129: Buy | D1129: 500 | E1129: 58.4 | F1129: 29200 | G1129: 20190614N300020334 | H1129: 2019112 | I1129: Rolling | J1129: IN302679-38296183 | K1129: NSE | L1129: 0 | M1129: 1.05 | N1129: 0 | O1129: 29.69 | P1129: 30.7412
... A4951: 45635 | B4951: VAKRAN | C4951: Sell | D4951: 4500 | E4951: 26.01 | F4951: 117045 | G4951: 20241209Z200024529 | H4951: 2024232 | I4951: Rolling T1 | J4951: IN302679-38296183 | K4951: NSE | L4951: 117 | M4951: 3.71 | N4951: 0 | O4951: 207.85 | P4951: 328.5604
A4952: 45656 | B4952: VLEGIT | C4952: Buy | D4952: 550 | E4952: 0 | F4952: 0 | G4952: 20241230Z200014737 | H4952: 2024246 | I4952: TT T1 | J4952: IN302679-38296183 | K4952: NSE | L4952: 0 | M4952: 0 | N4952: 0 | O4952: 0 | P4952: 0 | Q4952: Credited as Bonus Shares
A4953: 45656 | B4953: VLEGIT | C4953: Sell | D4953: 550 | E4953: 173 | F4953: 95150 | G4953: 20241230Z200014737 | H4953: 2024246 | I4953: TT T1 | J4953: IN302679-38296183 | K4953: NSE | L4953: 95 | M4953: 3.02 | N4953: 0 | O4953: 168.96 | P4953: 266.9763
A4954: 45660 | B4954: ROTPUM | C4954: Sell | D4954: 25 | E4954: 309 | F4954: 7725 | G4954: 20250103Z200032323 | H4954: 2025003 | I4954: Rolling T1 | J4954: IN302679-38296183 | K4954: NSE | L4954: 8 | M4954: 0.24 | N4954: 0 | O4954: 29.54 | P4954: 37.7849
A4955: 45681 | B4955: GRAWEI | C4955: Sell | D4955: 105 | E4955: 99.25 | F4955: 10421.25 | G4955: 20250124B300006930 | H4955: 2025018 | I4955: Rolling T1 | J4955: IN302679-38296183 | K4955: BSE | L4955: 10.42 | M4955: 0.4 | N4955: 0 | O4955: 29.58 | P4955: 40.4012
A4956: 45681 | B4956: STESW | C4956: Sell | D4956: 25 | E4956: 184.9 | F4956: 4622.5 | G4956: 20250124Z200019291 | H4956: 2025018 | I4956: Rolling T1 | J4956: IN302679-38296183 | K4956: NSE | L4956: 4.58 | M4956: 0.15 | N4956: 0 | O4956: 29.53 | P4956: 34.2565
A4957: 45737 | B4957: FUTENT | C4957: Sell | D4957: 600 | E4957: 3.63 | F4957: 2177 | G4957: 20250321Z100001029 | H4957: 2025057 | I4957: TT T1 | J4957: IN302679-38296183 | K4957: NSE | L4957: 2 | M4957: 0.07 | N4957: 0 | O4957: 19.28 | P4957: 21.349
A4958: 45737 | B4958: MENBEA | C4958: Sell | D4958: 10 | E4958: 91.98 | F4958: 919.8 | G4958: 20250321Z100001183 | H4958: 2025057 | I4958: Rolling T1 | J4958: IN302679-38296183 | K4958: NSE | L4958: 0.92 | M4958: 0.03 | N4958: 0 | O4958: 8.15 | P4958: 9.0991
A4959: 45737 | B4959: RAJEXP | C4959: Sell | D4959: 10 | E4959: 183.6 | F4959: 1836 | G4959: 20250321Z100001346 | H4959: 2025057 | I4959: Rolling T1 | J4959: IN302679-38296183 | K4959: NSE | L4959: 2.08 | M4959: 0.06 | N4959: 0 | O4959: 16.26 | P4959: 18.3982
A4960: 45748 | B4960: ICIGOL | C4960: Buy | D4960: 25 | E4960: 78.52 | F4960: 1963 | G4960: 20250401Z100017389 | H4960: 2025063 | I4960: Rolling T1 | J4960: IN302679-38296183 | K4960: NSE | L4960: 0 | M4960: 0.06 | N4960: 0 | O4960: 11.81 | P4960: 11.8723
A4961: 45756 | B4961: RELCOM | C4961: Sell | D4961: 1500 | E4961: 1.49 | F4961: 2235 | G4961: 20250409Z100031397 | H4961: 2025069 | I4961: TT T1 | J4961: IN302679-38296183 | K4961: NSE | L4961: 2 | M4961: 0.07 | N4961: 0 | O4961: 19.79 | P4961: 21.8608

Sheet Buy
L1: BuyVal | O1: Sell Val | Q1: ValDiff | R1: P/L | S1: P | T1: L
L2: =SUM(L10:L1000) -> 7.9116915e+08 | O2: =SUM(O10:O1000) -> 7.896308e+08 | Q2: =SUM(Q10:Q1000) -> -1538345.6 | R2: =SUM(R10:R1000) -> -1583190.6 | S2: =SUM(S10:S1000) -> 700885.76 | T2: =SUM(T10:T1000) -> -2284076.3
R3: -5341.2691 | S3: 0 | T3: -5341.2691
R4: =R2+R3 -> -1588531.8 | S4: =S2+S3 -> 700885.76 | T4: =T2+T3 -> -2289417.6
A5: Action | B5: Buy
B7: Values
A8: Row Labels | B8: Sum of Qty | C8: Sum of Price | D8: Sum of Trade Value | E8: Sum of Brokerage incl. taxes | H8: Values | M8: SELL Lookup | P8: Analysis
A9: ARVLIM | B9: 100 | C9: 357 | D9: 35700 | E9: 271.1581 | G9: Row Labels | H9: Sum of Qty | I9: Sum of Price | J9: Sum of Trade Value | K9: Sum of Brokerage incl. taxes | L9: BuyVal | M9: Stk | N9: SQTY | O9: Sell Val | P9: QtyDiff | Q9: ValDiff | R9: P/L | S9: P | T9: L | U9: Status
A10: ASHLEY | B10: 63121 | C10: 1572.14 | D10: 4911234.2 | E10: 2264.7055 | G10: ARVLIM | H10: 100 | I10: 357 | J10: 35700 | K10: 271.1581 | L10: =J10+K10 -> 35971.158 | M10: =VLOOKUP(G10,Sell!G:L,1,0) -> ARVLIM | N10: =IFERROR(VLOOKUP(G10,Sell!G:L,2,0),0) -> 100 | O10: =IFERROR(VLOOKUP(G10,Sell!G:L,6,0),0) -> 37021.849 | P10: =H10-N10 -> 0 | Q10: =O10-L10 -> 1050.691 | R10: =IF(P10=0,Q10,0) -> 1050.691 | S10: =IF(R10>0,R10,0) -> 1050.691 | T10: =IF(R10>0,0,R10) -> 0 | U10: =IF(AND(LEN(G10)>0,R10=0),"Open","")
A11: CENBAN | B11: 5349 | C11: 408.5 | D11: 134103.5 | E11: 334.6101 | G11: ASHLEY | H11: 63121 | I11: 1572.14 | J11: 4911234.2 | K11: 2264.7055 | L11: =J11+K11 -> 4913498.9 | M11: =VLOOKUP(G11,Sell!G:L,1,0) -> ASHLEY | N11: =IFERROR(VLOOKUP(G11,Sell!G:L,2,0),0) -> 63121 | O11: =IFERROR(VLOOKUP(G11,Sell!G:L,6,0),0) -> 4810237 | P11: =H11-N11 -> 0 | Q11: =O11-L11 -> -103261.93 | R11: =IF(P11=0,Q11,0) -> -103261.93 | S11: =IF(R11>0,R11,0) -> 0 | T11: =IF(R11>0,0,R11) -> -103261.93 | U11: =IF(AND(LEN(G11)>0,R11=0),"Open","")
A12: GATLIM | B12: 13239 | C12: 2817.18 | D12: 1766066.1 | E12: 4970.1555 | G12: CENBAN | H12: 5349 | I12: 408.5 | J12: 134103.5 | K12: 334.6101 | L12: =J12+K12 -> 134438.11 | M12: =VLOOKUP(G12,Sell!G:L,1,0) -> CENBAN | N12: =IFERROR(VLOOKUP(G12,Sell!G:L,2,0),0) -> 5349 | O12: =IFERROR(VLOOKUP(G12,Sell!G:L,6,0),0) -> 145640.5 | P12: =H12-N12 -> 0 | Q12: =O12-L12 -> 11202.39 | R12: =IF(P12=0,Q12,0) -> 11202.39 | S12: =IF(R12>0,R12,0) -> 11202.39 | T12: =IF(R12>0,0,R12) -> 0 | U12: =IF(AND(LEN(G12)>0,R12=0),"Open","")
A13: GMRINF | B13: 25325 | C13: 200.39 | D13: 452689.75 | E13: 2312.3229 | G13: GATLIM | H13: 13239 | I13: 2817.18 | J13: 1766066.1 | K13: 4970.1555 | L13: =J13+K13 -> 1771036.2 | M13: =VLOOKUP(G13,Sell!G:L,1,0) -> GATLIM | N13: =IFERROR(VLOOKUP(G13,Sell!G:L,2,0),0) -> 13239 | O13: =IFERROR(VLOOKUP(G13,Sell!G:L,6,0),0) -> 1709145 | P13: =H13-N13 -> 0 | Q13: =O13-L13 -> -61891.228 | R13: =IF(P13=0,Q13,0) -> -61891.228 | S13: =IF(R13>0,R13,0) -> 0 | T13: =IF(R13>0,0,R13) -> -61891.228 | U13: =IF(AND(LEN(G13)>0,R13=0),"Open","")
A14: HINCOP | B14: 500 | C14: 77 | D14: 38500 | E14: 282.0019 | G14: GMRINF | H14: 25325 | I14: 200.39 | J14: 452689.75 | K14: 2312.3229 | L14: =J14+K14 -> 455002.07 | M14: =VLOOKUP(G14,Sell!G:L,1,0) -> GMRINF | N14: =IFERROR(VLOOKUP(G14,Sell!G:L,2,0),0) -> 25325 | O14: =IFERROR(VLOOKUP(G14,Sell!G:L,6,0),0) -> 419457.3 | P14: =H14-N14 -> 0 | Q14: =O14-L14 -> -35544.769 | R14: =IF(P14=0,Q14,0) -> -35544.769 | S14: =IF(R14>0,R14,0) -> 0 | T14: =IF(R14>0,0,R14) -> -35544.769 | U14: =IF(AND(LEN(G14)>0,R14=0),"Open","")
A15: INFTEC | B15: 925 | C15: 14355.11 | D15: 924734.8 | E15: 2054.05 | G15: HINCOP | H15: 500 | I15: 77 | J15: 38500 | K15: 282.0019 | L15: =J15+K15 -> 38782.002 | M15: =VLOOKUP(G15,Sell!G:L,1,0) -> HINCOP | N15: =IFERROR(VLOOKUP(G15,Sell!G:L,2,0),0) -> 500 | O15: =IFERROR(VLOOKUP(G15,Sell!G:L,6,0),0) -> 40200.412 | P15: =H15-N15 -> 0 | Q15: =O15-L15 -> 1418.4101 | R15: =IF(P15=0,Q15,0) -> 1418.4101 | S15: =IF(R15>0,R15,0) -> 1418.4101 | T15: =IF(R15>0,0,R15) -> 0 | U15: =IF(AND(LEN(G15)>0,R15=0),"Open","")
A16: JAIASS | B16: 500 | C16: 66 | D16: 33000 | E16: 238.618 | G16: INFTEC | H16: 925 | I16: 14355.11 | J16: 924734.8 | K16: 2054.05 | L16: =J16+K16 -> 926788.85 | M16: =VLOOKUP(G16,Sell!G:L,1,0) -> INFTEC | N16: =IFERROR(VLOOKUP(G16,Sell!G:L,2,0),0) -> 925 | O16: =IFERROR(VLOOKUP(G16,Sell!G:L,6,0),0) -> 950826.03 | P16: =H16-N16 -> 0 | Q16: =O16-L16 -> 24037.182 | R16: =IF(P16=0,Q16,0) -> 24037.182 | S16: =IF(R16>0,R16,0) -> 24037.182 | T16: =IF(R16>0,0,R16) -> 0 | U16: =IF(AND(LEN(G16)>0,R16=0),"Open","")
A17: JAIPOW | B17: 3000 | C17: 34.7 | D17: 46200 | E17: 335.6274 | G17: JAIASS | H17: 500 | I17: 66 | J17: 33000 | K17: 238.618 | L17: =J17+K17 -> 33238.618 | M17: =VLOOKUP(G17,Sell!G:L,1,0) -> JAIASS | N17: =IFERROR(VLOOKUP(G17,Sell!G:L,2,0),0) -> 500 | O17: =IFERROR(VLOOKUP(G17,Sell!G:L,6,0),0) -> 41444.437 | P17: =H17-N17 -> 0 | Q17: =O17-L17 -> 8205.8193 | R17: =IF(P17=0,Q17,0) -> 8205.8193 | S17: =IF(R17>0,R17,0) -> 8205.8193 | T17: =IF(R17>0,0,R17) -> 0 | U17: =IF(AND(LEN(G17)>0,R17=0),"Open","")
A18: JBCHEM | B18: 1381 | C18: 2024.17 | D18: 440892.9 | E18: 956.7433 | G18: JAIPOW | H18: 3000 | I18: 34.7 | J18: 46200 | K18: 335.6274 | L18: =J18+K18 -> 46535.627 | M18: =VLOOKUP(G18,Sell!G:L,1,0) -> JAIPOW | N18: =IFERROR(VLOOKUP(G18,Sell!G:L,2,0),0) -> 3000 | O18: =IFERROR(VLOOKUP(G18,Sell!G:L,6,0),0) -> 33499.015 | P18: =H18-N18 -> 0 | Q18: =O18-L18 -> -13036.612 | R18: =IF(P18=0,Q18,0) -> -13036.612 | S18: =IF(R18>0,R18,0) -> 0 | T18: =IF(R18>0,0,R18) -> -13036.612 | U18: =IF(AND(LEN(G18)>0,R18=0),"Open","")
A19: KOHFOO | B19: 1000 | C19: 78.65 | D19: 78650 | E19: 596.336 | G19: JBCHEM | H19: 1381 | I19: 2024.17 | J19: 440892.9 | K19: 956.7433 | L19: =J19+K19 -> 441849.64 | M19: =VLOOKUP(G19,Sell!G:L,1,0) -> JBCHEM | N19: =IFERROR(VLOOKUP(G19,Sell!G:L,2,0),0) -> 1381 | O19: =IFERROR(VLOOKUP(G19,Sell!G:L,6,0),0) -> 423470.77 | P19: =H19-N19 -> 0 | Q19: =O19-L19 -> -18378.877 | R19: =IF(P19=0,Q19,0) -> -18378.877 | S19: =IF(R19>0,R19,0) -> 0 | T19: =IF(R19>0,0,R19) -> -18378.877 | U19: =IF(AND(LEN(G19)>0,R19=0),"Open","")
A20: LANINF | B20: 3000 | C20: 14.5 | D20: 22250 | E20: 128.666 | G20: KOHFOO | H20: 1000 | I20: 78.65 | J20: 78650 | K20: 596.336 | L20: =J20+K20 -> 79246.336 | M20: =VLOOKUP(G20,Sell!G:L,1,0) -> KOHFOO | N20: =IFERROR(VLOOKUP(G20,Sell!G:L,2,0),0) -> 1000 | O20: =IFERROR(VLOOKUP(G20,Sell!G:L,6,0),0) -> 70805.881 | P20: =H20-N20 -> 0 | Q20: =O20-L20 -> -8440.4547 | R20: =IF(P20=0,Q20,0) -> -8440.4547 | S20: =IF(R20>0,R20,0) -> 0 | T20: =IF(R20>0,0,R20) -> -8440.4547 | U20: =IF(AND(LEN(G20)>0,R20=0),"Open","")
A21: LTOVER | B21: 50550 | C21: 1405.39 | D21: 1740027.9 | E21: 3721.7815 | G21: LANINF | H21: 3000 | I21: 14.5 | J21: 22250 | K21: 128.666 | L21: =J21+K21 -> 22378.666 | M21: =VLOOKUP(G21,Sell!G:L,1,0) -> LANINF | N21: =IFERROR(VLOOKUP(G21,Sell!G:L,2,0),0) -> 3000 | O21: =IFERROR(VLOOKUP(G21,Sell!G:L,6,0),0) -> 21011.857 | P21: =H21-N21 -> 0 | Q21: =O21-L21 -> -1366.8092 | R21: =IF(P21=0,Q21,0) -> -1366.8092 | S21: =IF(R21>0,R21,0) -> 0 | T21: =IF(R21>0,0,R21) -> -1366.8092 | U21: =IF(AND(LEN(G21)>0,R21=0),"Open","")
... A23: MINLIM | B23: 5985 | C23: 23612.33 | D23: 5993746 | E23: 3160.3289 | G23: MANAFI | H23: 100 | I23: 92 | J23: 9200 | K23: 68.4936 | L23: =J23+K23 -> 9268.4936 | M23: =VLOOKUP(G23,Sell!G:L,1,0) -> MANAFI | N23: =IFERROR(VLOOKUP(G23,Sell!G:L,2,0),0) -> 100 | O23: =IFERROR(VLOOKUP(G23,Sell!G:L,6,0),0) -> 9670.4983 | P23: =H23-N23 -> 0 | Q23: =O23-L23 -> 402.0047 | R23: =IF(P23=0,Q23,0) -> 402.0047 | S23: =IF(R23>0,R23,0) -> 402.0047 | T23: =IF(R23>0,0,R23) -> 0 | U23: =IF(AND(LEN(G23)>0,R23=0),"Open","")
A24: MUTFIN | B24: 11273 | C24: 21027.09 | D24: 7348338.3 | E24: 6144.1483 | G24: MINLIM | H24: 5985 | I24: 23612.33 | J24: 5993746 | K24: 3160.3289 | L24: =J24+K24 -> 5996906.3 | M24: =VLOOKUP(G24,Sell!G:L,1,0) -> MINLIM | N24: =IFERROR(VLOOKUP(G24,Sell!G:L,2,0),0) -> 5995 | O24: =IFERROR(VLOOKUP(G24,Sell!G:L,6,0),0) -> 5902689.8 | P24: 0 | Q24: =O24-L24 -> -94216.514 | R24: =IF(P24=0,Q24,0) -> -94216.514 | S24: =IF(R24>0,R24,0) -> 0 | T24: =IF(R24>0,0,R24) -> -94216.514 | U24: =IF(AND(LEN(G24)>0,R24=0),"Open","")
A25: NHPC | B25: 700 | C25: 20 | D25: 14000 | E25: 102.424 | G25: MUTFIN | H25: 11273 | I25: 21027.09 | J25: 7348338.3 | K25: 6144.1483 | L25: =J25+K25 -> 7354482.4 | M25: =VLOOKUP(G25,Sell!G:L,1,0) -> MUTFIN | N25: =IFERROR(VLOOKUP(G25,Sell!G:L,2,0),0) -> 11273 | O25: =IFERROR(VLOOKUP(G25,Sell!G:L,6,0),0) -> 7330741.5 | P25: =H25-N25 -> 0 | Q25: =O25-L25 -> -23740.925 | R25: =IF(P25=0,Q25,0) -> -23740.925 | S25: =IF(R25>0,R25,0) -> 0 | T25: =IF(R25>0,0,R25) -> -23740.925 | U25: =IF(AND(LEN(G25)>0,R25=0),"Open","")
A26: PUNBAN | B26: 181050 | C26: 2644.21 | D26: 7967567 | E26: 4152.3388 | G26: NHPC | H26: 700 | I26: 20 | J26: 14000 | K26: 102.424 | L26: =J26+K26 -> 14102.424 | M26: =VLOOKUP(G26,Sell!G:L,1,0) -> NHPC | N26: =IFERROR(VLOOKUP(G26,Sell!G:L,2,0),0) -> 700 | O26: =IFERROR(VLOOKUP(G26,Sell!G:L,6,0),0) -> 14176.956 | P26: =H26-N26 -> 0 | Q26: =O26-L26 -> 74.5319 | R26: =IF(P26=0,Q26,0) -> 74.5319 | S26: =IF(R26>0,R26,0) -> 74.5319 | T26: =IF(R26>0,0,R26) -> 0 | U26: =IF(AND(LEN(G26)>0,R26=0),"Open","")
A27: RELDEF | B27: 11500 | C27: 658.35 | D27: 674385.3 | E27: 4912.8277 | G27: PUNBAN | H27: 181050 | I27: 2644.21 | J27: 7967567 | K27: 4152.3388 | L27: =J27+K27 -> 7971719.4 | M27: =VLOOKUP(G27,Sell!G:L,1,0) -> PUNBAN | N27: =IFERROR(VLOOKUP(G27,Sell!G:L,2,0),0) -> 181050 | O27: =IFERROR(VLOOKUP(G27,Sell!G:L,6,0),0) -> 7961266.8 | P27: =H27-N27 -> 0 | Q27: =O27-L27 -> -10452.582 | R27: =IF(P27=0,Q27,0) -> -10452.582 | S27: =IF(R27>0,R27,0) -> 0 | T27: =IF(R27>0,0,R27) -> -10452.582 | U27: =IF(AND(LEN(G27)>0,R27=0),"Open","")
A28: RELPOW | B28: 575 | C28: 212 | D28: 60500 | E28: 441.1785 | G28: RELDEF | H28: 11500 | I28: 658.35 | J28: 674385.3 | K28: 4912.8277 | L28: =J28+K28 -> 679298.13 | M28: =VLOOKUP(G28,Sell!G:L,1,0) -> RELDEF | N28: =IFERROR(VLOOKUP(G28,Sell!G:L,2,0),0) -> 11500 | O28: =IFERROR(VLOOKUP(G28,Sell!G:L,6,0),0) -> 725840.37 | P28: =H28-N28 -> 0 | Q28: =O28-L28 -> 46542.244 | R28: =IF(P28=0,Q28,0) -> 46542.244 | S28: =IF(R28>0,R28,0) -> 46542.244 | T28: =IF(R28>0,0,R28) -> 0 | U28: =IF(AND(LEN(G28)>0,R28=0),"Open","")
A29: SUNADV | B29: 2510 | C29: 1790.98 | D29: 643678.25 | E29: 868.5447 | G29: RELPOW | H29: 575 | I29: 212 | J29: 60500 | K29: 441.1785 | L29: =J29+K29 -> 60941.179 | M29: =VLOOKUP(G29,Sell!G:L,1,0) -> RELPOW | N29: =IFERROR(VLOOKUP(G29,Sell!G:L,2,0),0) -> 575 | O29: =IFERROR(VLOOKUP(G29,Sell!G:L,6,0),0) -> 37733.204 | P29: =H29-N29 -> 0 | Q29: =O29-L29 -> -23207.975 | R29: =IF(P29=0,Q29,0) -> -23207.975 | S29: =IF(R29>0,R29,0) -> 0 | T29: =IF(R29>0,0,R29) -> -23207.975 | U29: =IF(AND(LEN(G29)>0,R29=0),"Open","")
A30: SUNPHA | B30: 4340 | C30: 7798.56 | D30: 1934780.5 | E30: 1148.8728 | G30: SUNADV | H30: 2510 | I30: 1790.98 | J30: 643678.25 | K30: 868.5447 | L30: =J30+K30 -> 644546.79 | M30: =VLOOKUP(G30,Sell!G:L,1,0) -> SUNADV | N30: =IFERROR(VLOOKUP(G30,Sell!G:L,2,0),0) -> 2510 | O30: =IFERROR(VLOOKUP(G30,Sell!G:L,6,0),0) -> 638444.01 | P30: =H30-N30 -> 0 | Q30: =O30-L30 -> -6102.781 | R30: =IF(P30=0,Q30,0) -> -6102.781 | S30: =IF(R30>0,R30,0) -> 0 | T30: =IF(R30>0,0,R30) -> -6102.781 | U30: =IF(AND(LEN(G30)>0,R30=0),"Open","")
A31: TATPOW | B31: 1000 | C31: 69 | D31: 69000 | E31: 512.8071 | G31: SUNPHA | H31: 4340 | I31: 7798.56 | J31: 1934780.5 | K31: 1148.8728 | L31: =J31+K31 -> 1935929.4 | M31: =VLOOKUP(G31,Sell!G:L,1,0) -> SUNPHA | N31: =IFERROR(VLOOKUP(G31,Sell!G:L,2,0),0) -> 4340 | O31: =IFERROR(VLOOKUP(G31,Sell!G:L,6,0),0) -> 1938139.2 | P31: =H31-N31 -> 0 | Q31: =O31-L31 -> 2209.7858 | R31: =IF(P31=0,Q31,0) -> 2209.7858 | S31: =IF(R31>0,R31,0) -> 2209.7858 | T31: =IF(R31>0,0,R31) -> 0 | U31: =IF(AND(LEN(G31)>0,R31=0),"Open","")
A32: TVSMOT | B32: 200 | C32: 767.93 | D32: 76793.35 | E32: 578.464 | G32: TATPOW | H32: 1000 | I32: 69 | J32: 69000 | K32: 512.8071 | L32: =J32+K32 -> 69512.807 | M32: =VLOOKUP(G32,Sell!G:L,1,0) -> TATPOW | N32: =IFERROR(VLOOKUP(G32,Sell!G:L,2,0),0) -> 1000 | O32: =IFERROR(VLOOKUP(G32,Sell!G:L,6,0),0) -> 69663.034 | P32: =H32-N32 -> 0 | Q32: =O32-L32 -> 150.2264 | R32: =IF(P32=0,Q32,0) -> 150.2264 | S32: =IF(R32>0,R32,0) -> 150.2264 | T32: =IF(R32>0,0,R32) -> 0 | U32: =IF(AND(LEN(G32)>0,R32=0),"Open","")
A33: ZENINF | B33: 475 | C33: 11.15 | D33: 5296.25 | E33: 45.0191 | G33: TVSMOT | H33: 200 | I33: 767.93 | J33: 76793.35 | K33: 578.464 | L33: =J33+K33 -> 77371.814 | M33: =VLOOKUP(G33,Sell!G:L,1,0) -> TVSMOT | N33: =IFERROR(VLOOKUP(G33,Sell!G:L,2,0),0) -> 200 | O33: =IFERROR(VLOOKUP(G33,Sell!G:L,6,0),0) -> 79332.533 | P33: =H33-N33 -> 0 | Q33: =O33-L33 -> 1960.7186 | R33: =IF(P33=0,Q33,0) -> 1960.7186 | S33: =IF(R33>0,R33,0) -> 1960.7186 | T33: =IF(R33>0,0,R33) -> 0 | U33: =IF(AND(LEN(G33)>0,R33=0),"Open","")
A34: SUZENE | B34: 27500 | C34: 95.15 | D34: 439375 | E34: 2194.7199 | G34: ZENINF | H34: 475 | I34: 11.15 | J34: 5296.25 | K34: 45.0191 | L34: =J34+K34 -> 5341.2691 | M34: =VLOOKUP(G34,Sell!G:L,1,0) -> #N/A | N34: =IFERROR(VLOOKUP(G34,Sell!G:L,2,0),0) -> 0 | O34: =IFERROR(VLOOKUP(G34,Sell!G:L,6,0),0) -> 0 | P34: =H34-N34 -> 475 | Q34: =O34-L34 -> -5341.2691 | R34: =IF(P34=0,Q34,0) -> 0 | S34: =IF(R34>0,R34,0) -> 0 | T34: =IF(R34>0,0,R34) -> 0 | U34: =IF(AND(LEN(G34)>0,R34=0),"Open","") -> Open
A35: FINCHE | B35: 11910 | C35: 1533.14 | D35: 748836.05 | E35: 3921.1503 | G35: SUZENE | H35: 27500 | I35: 95.15 | J35: 439375 | K35: 2194.7199 | L35: =J35+K35 -> 441569.72 | M35: =VLOOKUP(G35,Sell!G:L,1,0) -> SUZENE | N35: =IFERROR(VLOOKUP(G35,Sell!G:L,2,0),0) -> 27500 | O35: =IFERROR(VLOOKUP(G35,Sell!G:L,6,0),0) -> 436255.19 | P35: =H35-N35 -> 0 | Q35: =O35-L35 -> -5314.5313 | R35: =IF(P35=0,Q35,0) -> -5314.5313 | S35: =IF(R35>0,R35,0) -> 0 | T35: =IF(R35>0,0,R35) -> -5314.5313 | U35: =IF(AND(LEN(G35)>0,R35=0),"Open","")
A36: BANMAH | B36: 5000 | C36: 24 | D36: 120000 | E36: 82.6 | G36: FINCHE | H36: 11910 | I36: 1533.14 | J36: 748836.05 | K36: 3921.1503 | L36: =J36+K36 -> 752757.2 | M36: =VLOOKUP(G36,Sell!G:L,1,0) -> FINCHE | N36: =IFERROR(VLOOKUP(G36,Sell!G:L,2,0),0) -> 11910 | O36: =IFERROR(VLOOKUP(G36,Sell!G:L,6,0),0) -> 762344.37 | P36: =H36-N36 -> 0 | Q36: =O36-L36 -> 9587.1678 | R36: =IF(P36=0,Q36,0) -> 9587.1678 | S36: =IF(R36>0,R36,0) -> 9587.1678 | T36: =IF(R36>0,0,R36) -> 0 | U36: =IF(AND(LEN(G36)>0,R36=0),"Open","")
... A72: YESBAN | B72: 27850 | C72: 2402.07 | D72: 2398094.5 | E72: 3993.9529 | G72: CROGRE | H72: 1500 | I72: 115.35 | J72: 86625 | K72: 72.1189 | L72: =J72+K72 -> 86697.119 | M72: =VLOOKUP(G72,Sell!G:L,1,0) -> CROGRE | N72: =IFERROR(VLOOKUP(G72,Sell!G:L,2,0),0) -> 1500 | O72: =IFERROR(VLOOKUP(G72,Sell!G:L,6,0),0) -> 86698.727 | P72: =H72-N72 -> 0 | Q72: =O72-L72 -> 1.6078 | R72: =IF(P72=0,Q72,0) -> 1.6078 | S72: =IF(R72>0,R72,0) -> 1.6078 | T72: =IF(R72>0,0,R72) -> 0 | U72: =IF(AND(LEN(G72)>0,R72=0),"Open","")
A73: DEWHOU | B73: 2900 | C73: 1160.73 | D73: 250243.85 | E73: 210.0674 | G73: YESBAN | H73: 27850 | I73: 2402.07 | J73: 2398094.5 | K73: 3993.9529 | L73: =J73+K73 -> 2402088.5 | M73: =VLOOKUP(G73,Sell!G:L,1,0) -> YESBAN | N73: =IFERROR(VLOOKUP(G73,Sell!G:L,2,0),0) -> 27850 | O73: =IFERROR(VLOOKUP(G73,Sell!G:L,6,0),0) -> 2442475.4 | P73: =H73-N73 -> 0 | Q73: =O73-L73 -> 40386.941 | R73: =IF(P73=0,Q73,0) -> 40386.941 | S73: =IF(R73>0,R73,0) -> 40386.941 | T73: =IF(R73>0,0,R73) -> 0 | U73: =IF(AND(LEN(G73)>0,R73=0),"Open","") | V73: Take the Transactions again as 1000 qty difference occurs
A74: KNRCON | B74: 5105 | C74: 6915.92 | D74: 1140943.7 | E74: 1012.567 | G74: DEWHOU | H74: 2900 | I74: 1160.73 | J74: 250243.85 | K74: 210.0674 | L74: =J74+K74 -> 250453.92 | M74: =VLOOKUP(G74,Sell!G:L,1,0) -> DEWHOU | N74: =IFERROR(VLOOKUP(G74,Sell!G:L,2,0),0) -> 2900 | O74: =IFERROR(VLOOKUP(G74,Sell!G:L,6,0),0) -> 249087.56 | P74: =H74-N74 -> 0 | Q74: =O74-L74 -> -1366.3571 | R74: =IF(P74=0,Q74,0) -> -1366.3571 | S74: =IF(R74>0,R74,0) -> 0 | T74: =IF(R74>0,0,R74) -> -1366.3571 | U74: =IF(AND(LEN(G74)>0,R74=0),"Open","")
A75: GUJMI | B75: 10 | C75: 111.45 | D75: 1114.5 | E75: 34.2135 | G75: KNRCON | H75: 5105 | I75: 6915.92 | J75: 1140943.7 | K75: 1012.567 | L75: =J75+K75 -> 1141956.3 | M75: =VLOOKUP(G75,Sell!G:L,1,0) -> KNRCON | N75: =IFERROR(VLOOKUP(G75,Sell!G:L,2,0),0) -> 5105 | O75: =IFERROR(VLOOKUP(G75,Sell!G:L,6,0),0) -> 1159809.5 | P75: =H75-N75 -> 0 | Q75: =O75-L75 -> 17853.244 | R75: =IF(P75=0,Q75,0) -> 17853.244 | S75: =IF(R75>0,R75,0) -> 17853.244 | T75: =IF(R75>0,0,R75) -> 0 | U75: =IF(AND(LEN(G75)>0,R75=0),"Open","")
A76: TV18BR | B76: 1000 | C76: 39.3 | D76: 39300 | E76: 30.8891 | G76: GUJMI | H76: 10 | I76: 111.45 | J76: 1114.5 | K76: 34.2135 | L76: =J76+K76 -> 1148.7135 | M76: =VLOOKUP(G76,Sell!G:L,1,0) -> GUJMI | N76: =IFERROR(VLOOKUP(G76,Sell!G:L,2,0),0) -> 10 | O76: =IFERROR(VLOOKUP(G76,Sell!G:L,6,0),0) -> 933.601 | P76: =H76-N76 -> 0 | Q76: =O76-L76 -> -215.1125 | R76: =IF(P76=0,Q76,0) -> -215.1125 | S76: =IF(R76>0,R76,0) -> 0 | T76: =IF(R76>0,0,R76) -> -215.1125 | U76: =IF(AND(LEN(G76)>0,R76=0),"Open","")
A77: BANBAN | B77: 406195 | C77: 89382.78 | D77: 1.1315554e+08 | E77: 32921.912 | G77: TV18BR | H77: 1000 | I77: 39.3 | J77: 39300 | K77: 30.8891 | L77: =J77+K77 -> 39330.889 | M77: =VLOOKUP(G77,Sell!G:L,1,0) -> TV18BR | N77: =IFERROR(VLOOKUP(G77,Sell!G:L,2,0),0) -> 1000 | O77: =IFERROR(VLOOKUP(G77,Sell!G:L,6,0),0) -> 39559.612 | P77: =H77-N77 -> 0 | Q77: =O77-L77 -> 228.7229 | R77: =IF(P77=0,Q77,0) -> 228.7229 | S77: =IF(R77>0,R77,0) -> 228.7229 | T77: =IF(R77>0,0,R77) -> 0 | U77: =IF(AND(LEN(G77)>0,R77=0),"Open","")
...

Sheet Sell
A1: Action | B1: Sell
B3: Values | H3: Values
A4: Row Labels | B4: Sum of Qty | C4: Sum of Price | D4: Sum of Trade Value | E4: Sum of Brokerage incl. taxes | G4: Row Labels | H4: Sum of Qty | I4: Sum of Price | J4: Sum of Trade Value | K4: Sum of Brokerage incl. taxes | L4: SellValue
A5: ARVLIM | B5: 100 | C5: 373 | D5: 37300 | E5: 278.1509 | G5: ARVLIM | H5: 100 | I5: 373 | J5: 37300 | K5: 278.1509 | L5: =J5-K5 -> 37021.849
A6: ASHLEY | B6: 63121 | C6: 2271.54 | D6: 4813688.7 | E6: 3451.7233 | G6: ASHLEY | H6: 63121 | I6: 2271.54 | J6: 4813688.7 | K6: 3451.7233 | L6: =J6-K6 -> 4810237
A7: CENBAN | B7: 5349 | C7: 182.81 | D7: 145972.75 | E7: 332.2501 | G7: CENBAN | H7: 5349 | I7: 182.81 | J7: 145972.75 | K7: 332.2501 | L7: =J7-K7 -> 145640.5
A8: GATLIM | B8: 13239 | C8: 2228.66 | D8: 1713103.6 | E8: 3958.6223 | G8: GATLIM | H8: 13239 | I8: 2228.66 | J8: 1713103.6 | K8: 3958.6223 | L8: =J8-K8 -> 1709145
A9: GMRINF | B9: 25325 | C9: 145.36 | D9: 421590 | E9: 2132.6962 | G9: GMRINF | H9: 25325 | I9: 145.36 | J9: 421590 | K9: 2132.6962 | L9: =J9-K9 -> 419457.3
A10: HINCOP | B10: 500 | C10: 81 | D10: 40500 | E10: 299.588 | G10: HINCOP | H10: 500 | I10: 81 | J10: 40500 | K10: 299.588 | L10: =J10-K10 -> 40200.412
A11: INFTEC | B11: 925 | C11: 9702.55 | D11: 952985.75 | E11: 2159.7184 | G11: INFTEC | H11: 925 | I11: 9702.55 | J11: 952985.75 | K11: 2159.7184 | L11: =J11-K11 -> 950826.03
A12: JAIASS | B12: 500 | C12: 83.5 | D12: 41750 | E12: 305.5627 | G12: JAIASS | H12: 500 | I12: 83.5 | J12: 41750 | K12: 305.5627 | L12: =J12-K12 -> 41444.437
A13: JAIPOW | B13: 3000 | C13: 23.4 | D13: 33750 | E13: 250.9846 | G13: JAIPOW | H13: 3000 | I13: 23.4 | J13: 33750 | K13: 250.9846 | L13: =J13-K13 -> 33499.015
A14: JBCHEM | B14: 1381 | C14: 1615.44 | D14: 424303.55 | E14: 832.7839 | G14: JBCHEM | H14: 1381 | I14: 1615.44 | J14: 424303.55 | K14: 832.7839 | L14: =J14-K14 -> 423470.77
A15: KOHFOO | B15: 1000 | C15: 71.35 | D15: 71345.05 | E15: 539.1687 | G15: KOHFOO | H15: 1000 | I15: 71.35 | J15: 71345.05 | K15: 539.1687 | L15: =J15-K15 -> 70805.881
A16: LANINF | B16: 3000 | C16: 14.6 | D16: 21200 | E16: 188.1432 | G16: LANINF | H16: 3000 | I16: 14.6 | J16: 21200 | K16: 188.1432 | L16: =J16-K16 -> 21011.857
... A141: VLEGIT | B141: 550 | C141: 173 | D141: 95150 | E141: 266.9763 | G141: VLEGIT | H141: 550 | I141: 173 | J141: 95150 | K141: 266.9763 | L141: =J141-K141 -> 94883.024
A142: Grand Total | B142: 3775063 | C142: 821834.08 | D142: 7.9014755e+08 | E142: 516752.46 | L142: =J142-K142 -> 0
L143: =J143-K143 -> 0
L144: =J144-K144 -> 0
L145: =J145-K145 -> 0
L146: =J146-K146 -> 0
L147: =J147-K147 -> 0
L148: =J148-K148 -> 0
L149: =J149-K149 -> 0
L150: =J150-K150 -> 0
L151: =J151-K151 -> 0
L152: =J152-K152 -> 0
L153: =J153-K153 -> 0
L154: =J154-K154 -> 0
... L1000: =J1000-K1000 -> 0

Sheet P and L
A1: Status
A3: Row Labels | B3: Sum of P/L | D3: Row Labels | E3: Sum of P/L
A4: ARRGRE | B4: 433.8164 | D4: ICIBAN | E4: -448920.01
A5: ARVLIM | B5: 1050.691 | D5: BANBAN | E5: -358863.81
A6: ASHLEY | B6: -103261.93 | D6: FEDBAN | E6: -191506.52
A7: BANBAR | B7: -21402.24 | D7: ASHLEY | E7: -103261.93
A8: BANMAH | B8: -1936.9032 | D8: MINLIM | E8: -94216.514
A9: BHAELE | B9: 6513.646 | D9: JSWSTE | E9: -83651.419
A10: BHEL | B10: 8934.6349 | D10: SINPLA | E10: -77773.549
A11: BHUST | B11: -13399.066 | D11: STABAN | E11: -71390.092
A12: BIOCON | B12: -223311.08 | D12: CANBAN | E12: -52812.268
A13: BURCEM | B13: -28608.626 | D13: BHAAIR | E13: -46194.516
A14: CANHOM | B14: -24527.286 | D14: GMRINF | E14: -35544.769
A15: CENBAN | B15: 11202.39 | D15: HINPET | E15: -33094.949
... A128: IRCINT | B128: 105444.75 | D128: IRCINT | E128: 105444.75
A129: VARBEV | B129: 2701.0946
A130: JAYMAR | B130: 2561.6266
A131: ONE97 | B131: 198.0352
A132: AMBCE | B132: 385.8586
A133: ZOMLIM | B133: 37744.56
A134: FSNECO | B134: 580.9964
A135: RAJEXP | B135: -1399.4202
A136: STESW | B136: -1250.9722
A137: GRAWEI | B137: 2286.6533
A138: VLEGIT | B138: 94883.024
A139: Grand Total | B139: -1623577.5

Sheet Sheet1
A1: Date | B1: Stock | C1: Action | D1: Qty | E1: Price | F1: Trade Value | G1: Order Ref. | H1: Settlement | I1: Segment | J1: DP Id - Client DP Id | K1: Exchange | L1: STT | M1: Transaction and SEBI Turnover charges | N1: Stamp Duty | O1: Brokerage + Service Tax | P1: Brokerage incl. taxes | Q1: BuyValue | R1: SellValue | S1: =SUM(Q:Q) -> 1.3276761e+08 | T1: =SUM(R:R) -> 1.3168303e+08 | U1: =T1-S1 -> -1084580.4
A2: 43817 | B2: JSWSTE | C2: Sell | D2: 2500 | E2: 257.5 | F2: 643750 | G2: 20191218N300015716 | H2: 2019237 | I2: Rolling | J2: IN302679-38296183 | K2: NSE | L2: 0 | M2: 0 | N2: 0 | O2: 0 | P2: 0 | Q2: =IF(C2="Buy",F2+P2,0) -> 0 | R2: =IF(C2="Sell",F2-P2,0) -> 643750
A3: 43817 | B3: JSWSTE | C3: Buy | D3: 1036 | E3: 260.93 | F3: 270322.4 | G3: 20191218N300017034 | H3: 2019237 | I3: Rolling | J3: IN302679-38296183 | K3: NSE | L3: 0 | M3: 0 | N3: 0 | O3: 0 | P3: 0 | Q3: =IF(C3="Buy",F3+P3,0) -> 270322.4 | R3: =IF(C3="Sell",F3-P3,0) -> 0
A4: 43817 | B4: JSWSTE | C4: Sell | D4: 1000 | E4: 263 | F4: 263000 | G4: 20191218N300018267 | H4: 2019237 | I4: Rolling | J4: IN302679-38296183 | K4: NSE | L4: 0 | M4: 0 | N4: 0 | O4: 0 | P4: 0 | Q4: =IF(C4="Buy",F4+P4,0) -> 0 | R4: =IF(C4="Sell",F4-P4,0) -> 263000
A5: 43817 | B5: JSWSTE | C5: Sell | D5: 1000 | E5: 262.5 | F5: 262500 | G5: 20191218N300020799 | H5: 2019237 | I5: Rolling | J5: IN302679-38296183 | K5: NSE | L5: 0 | M5: 0 | N5: 0 | O5: 0 | P5: 0 | Q5: =IF(C5="Buy",F5+P5,0) -> 0 | R5: =IF(C5="Sell",F5-P5,0) -> 262500
A6: 43817 | B6: JSWSTE | C6: Buy | D6: 1445 | E6: 265.45 | F6: 383575.25 | G6: 20191218N300027081 | H6: 2019237 | I6: Rolling | J6: IN302679-38296183 | K6: NSE | L6: 0 | M6: 0 | N6: 0 | O6: 0 | P6: 0 | Q6: =IF(C6="Buy",F6+P6,0) -> 383575.25 | R6: =IF(C6="Sell",F6-P6,0) -> 0
A7: 43817 | B7: JSWSTE | C7: Buy | D7: 2019 | E7: 263.95 | F7: 532915.05 | G7: 20191218N300032550 | H7: 2019237 | I7: Rolling | J7: IN302679-38296183 | K7: NSE | L7: 0 | M7: 0 | N7: 0 | O7: 0 | P7: 0 | Q7: =IF(C7="Buy",F7+P7,0) -> 532915.05 | R7: =IF(C7="Sell",F7-P7,0) -> 0
A8: 43816 | B8: JSWSTE | C8: Buy | D8: 2500 | E8: 261 | F8: 652500 | G8: 20191217N300021604 | H8: 2019236 | I8: Rolling | J8: IN302679-38296183 | K8: NSE | L8: 0 | M8: 14.36 | N8: 0 | O8: 387.56 | P8: 401.915 | Q8: =IF(C8="Buy",F8+P8,0) -> 652901.92 | R8: =IF(C8="Sell",F8-P8,0) -> 0
A9: 43816 | B9: JSWSTE | C9: Sell | D9: 2500 | E9: 258.9 | F9: 647250 | G9: 20191217N300028896 | H9: 2019236 | I9: Rolling | J9: IN302679-38296183 | K9: NSE | L9: 162 | M9: 14.24 | N9: 39 | O9: 384.46 | P9: 599.6994 | Q9: =IF(C9="Buy",F9+P9,0) -> 0 | R9: =IF(C9="Sell",F9-P9,0) -> 646650.3
A10: 43815 | B10: INDHO | C10: Sell | D10: 2500 | E10: 317.8 | F10: 794511.75 | G10: 20191216N300015908 | H10: 2019235 | I10: Rolling | J10: IN302679-38296183 | K10: NSE | L10: 196 | M10: 17.48 | N10: 47.1 | O10: 471.92 | P10: 732.4995 | Q10: =IF(C10="Buy",F10+P10,0) -> 0 | R10: =IF(C10="Sell",F10-P10,0) -> 793779.25
A11: 43815 | B11: INDHO | C11: Buy | D11: 2500 | E11: 309 | F11: 772500 | G11: 20191216N300016628 | H11: 2019235 | I11: Rolling | J11: IN302679-38296183 | K11: NSE | L11: 0 | M11: 17 | N11: 0 | O11: 458.84 | P11: 475.8357 | Q11: =IF(C11="Buy",F11+P11,0) -> 772975.84 | R11: =IF(C11="Sell",F11-P11,0) -> 0
A12: 43812 | B12: JAGPRA | C12: Buy | D12: 2500 | E12: 56.29 | F12: 140714.8 | G12: 20191213N300015089 | H12: 2019234 | I12: Rolling | J12: IN302679-38296183 | K12: NSE | L12: 0 | M12: 3.1 | N12: 0 | O12: 83.57 | P12: 86.6658 | Q12: =IF(C12="Buy",F12+P12,0) -> 140801.47 | R12: =IF(C12="Sell",F12-P12,0) -> 0
A13: 43812 | B13: INDHO | C13: Buy | D13: 500 | E13: 297 | F13: 148500 | G13: 20191213N300016088 | H13: 2019234 | I13: Rolling | J13: IN302679-38296183 | K13: NSE | L13: 0 | M13: 3.27 | N13: 0 | O13: 88.21 | P13: 91.477 | Q13: =IF(C13="Buy",F13+P13,0) -> 148591.48 | R13: =IF(C13="Sell",F13-P13,0) -> 0
... A1597: 40995 | B1597: MUTFIN | C1597: Buy | D1597: 6 | E1597: 139.45 | F1597: 836.7 | G1597: 20120327N900002419 | H1597: 2012059 | I1597: Rolling | J1597: IN302679-38296183 | K1597: NSE | L1597: 1 | M1597: 0.03 | N1597: 0.08 | O1597: 23.07 | P1597: 24.183 | Q1597: =IF(C1597="Buy",F1597+P1597,0) -> 860.883 | R1597: =IF(C1597="Sell",F1597-P1597,0) -> 0

Sheet StockHistory
B3: Column Labels
B4: Buy | D4: Sell | F4: Total Sum of Trade Value | G4: Total Sum of Brokerage incl. taxes
A5: Row Labels | B5: Sum of Trade Value | C5: Sum of Brokerage incl. taxes | D5: Sum of Trade Value | E5: Sum of Brokerage incl. taxes
A6: STABAN | B6: 710000 | C6: 464.4735 | D6: 962550 | E6: 853.3361 | F6: 1672550 | G6: 1317.8096
A7: 43125 | B7: 327000 | C7: 205.4675 | D7: 320000 | E7: 281.95 | F7: 647000 | G7: 487.4175 | H7: =B7+C7 -> 327205.47 | I7: =D7-E7 -> 319718.05 | J7: =I7-H7 -> -7487.4175
A8: 43741 | B8: 383000 | C8: 259.006 | D8: 383450 | E8: 332.1959 | F8: 766450 | G8: 591.2019 | H8: =B8+C8 -> 383259.01 | I8: =D8-E8 -> 383117.8 | J8: =I8-H8 -> -141.2019
A9: 43742 | D9: 259100 | E9: 239.1902 | F9: 259100 | G9: 239.1902 | H9: =B9+C9 -> 0 | I9: =D9-E9 -> 258860.81 | J9: =I9-H9 -> 258860.81
A10: JSWSTE | B10: 1839312.7 | C10: 401.915 | D10: 1816500 | E10: 599.6994 | F10: 3655812.7 | G10: 1001.6144 | H10: =B10+C10 -> 1839714.6 | I10: =D10-E10 -> 1815900.3 | J10: =I10-H10 -> -23814.314
A11: 43817 | B11: 1186812.7 | C11: 0 | D11: 1169250 | E11: 0 | F11: 2356062.7 | G11: 0 | H11: =B11+C11 -> 1186812.7 | I11: =D11-E11 -> 1169250 | J11: =I11-H11 -> -17562.7
A12: 43816 | B12: 652500 | C12: 401.915 | D12: 647250 | E12: 599.6994 | F12: 1299750 | G12: 1001.6144 | H12: =B12+C12 -> 652901.92 | I12: =D12-E12 -> 646650.3 | J12: =I12-H12 -> -6251.6144
A13: INDHO | B13: 5293477.5 | C13: 3569.2776 | D13: 5315242.4 | E13: 4657.4062 | F13: 10608720 | G13: 8226.6838 | H13: =B13+C13 -> 5297046.8 | I13: =D13-E13 -> 5310585 | J13: =I13-H13 -> 13538.216
A14: 43801 | B14: 57801.45 | C14: 69.2015 | D14: 58270 | E14: 50.772 | F14: 116071.45 | G14: 119.9735 | H14: =B14+C14 -> 57870.651 | I14: =D14-E14 -> 58219.228 | J14: =I14-H14 -> 348.5765
A15: 43815 | B15: 772500 | C15: 475.8357 | D15: 794511.75 | E15: 732.4995 | F15: 1567011.8 | G15: 1208.3352 | H15: =B15+C15 -> 772975.84 | I15: =D15-E15 -> 793779.25 | J15: =I15-H15 -> 20803.415
A16: 43812 | B16: 2439528.9 | C16: 1665.8699 | D16: 2426783 | E16: 2103.2098 | F16: 4866311.9 | G16: 3769.0797 | H16: =B16+C16 -> 2441194.8 | I16: =D16-E16 -> 2424679.8 | J16: =I16-H16 -> -16514.98
A17: 43798 | B17: 72800 | C17: 54.7416 | D17: 72850 | E17: 63.0827 | F17: 145650 | G17: 117.8243 | H17: =B17+C17 -> 72854.742 | I17: =D17-E17 -> 72786.917 | J17: =I17-H17 -> -67.8243
A18: 43797 | B18: 149000 | C18: 91.778 | D18: 152560.35 | E18: 141.2864 | F18: 301560.35 | G18: 233.0644 | H18: =B18+C18 -> 149091.78 | I18: =D18-E18 -> 152419.06 | J18: =I18-H18 -> 3327.2856
A19: 43795 | B19: 269425 | C19: 165.9475 | D19: 265767.3 | E19: 230.5968 | F19: 535192.3 | G19: 396.5443 | H19: =B19+C19 -> 269590.95 | I19: =D19-E19 -> 265536.7 | J19: =I19-H19 -> -4054.2443
A20: 43794 | B20: 1532422.2 | C20: 1045.9034 | D20: 1544500 | E20: 1335.959 | F20: 3076922.2 | G20: 2381.8624 | H20: =B20+C20 -> 1533468.1 | I20: =D20-E20 -> 1543164 | J20: =I20-H20 -> 9695.9876
A21: JAGPRA | B21: 460035.45 | C21: 1526.6306 | D21: 344977.25 | E21: 261.4496 | F21: 805012.7 | G21: 1788.0802 | H21: =B21+C21 -> 461562.08 | I21: =D21-E21 -> 344715.8 | J21: =I21-H21 -> -116846.28
A22: 43802 | B22: 60142.35 | C22: 464.8331 | F22: 60142.35 | G22: 464.8331 | H22: =B22+C22 -> 60607.183 | I22: =D22-E22 -> 0 | J22: =I22-H22 -> -60607.183
A23: 43808 | B23: 118431.95 | C23: 888.4354 | D23: 61500 | E23: 16.223 | F23: 179931.95 | G23: 904.6584 | H23: =B23+C23 -> 119320.39 | I23: =D23-E23 -> 61483.777 | J23: =I23-H23 -> -57836.608
A24: 43812 | B24: 281461.15 | C24: 173.3621 | D24: 283477.25 | E24: 245.2266 | F24: 564938.4 | G24: 418.5887 | H24: =B24+C24 -> 281634.51 | I24: =D24-E24 -> 283232.02 | J24: =I24-H24 -> 1597.5113
A25: RELCOM | B25: 6000 | C25: 301.452 | F25: 6000 | G25: 301.452 | H25: =B25+C25 -> 6301.452 | I25: =D25-E25 -> 0 | J25: =I25-H25 -> -6301.452
A26: 43805 | B26: 6000 | C26: 301.452 | F26: 6000 | G26: 301.452 | H26: =B26+C26 -> 6301.452 | I26: =D26-E26 -> 0 | J26: =I26-H26 -> -6301.452
A27: BHAAIR | B27: 1689393.2 | C27: 1040.6167 | D27: 1691095 | E27: 1566.3541 | F27: 3380488.3 | G27: 2606.9708 | H27: =B27+C27 -> 1690433.9 | I27: =D27-E27 -> 1689528.7 | J27: =I27-H27 -> -905.1708
A28: 43804 | B28: 1689393.2 | C28: 1040.6167 | D28: 1691095 | E28: 1566.3541 | F28: 3380488.3 | G28: 2606.9708 | H28: =B28+C28 -> 1690433.9 | I28: =D28-E28 -> 1689528.7 | J28: =I28-H28 -> -905.1708
A29: RBLBAN | B29: 93161.2 | C29: 57.3794 | D29: 94527.5 | E29: 81.6797 | F29: 187688.7 | G29: 139.0591 | H29: =B29+C29 -> 93218.579 | I29: =D29-E29 -> 94445.82 | J29: =I29-H29 -> 1227.2409
A30: 43802 | B30: 93161.2 | C30: 57.3794 | D30: 94527.5 | E30: 81.6797 | F30: 187688.7 | G30: 139.0591 | H30: =B30+C30 -> 93218.579 | I30: =D30-E30 -> 94445.82 | J30: =I30-H30 -> 1227.2409
A31: FEDBAN | B31: 89000 | C31: 54.818 | D31: 91100 | E31: 78.9042 | F31: 180100 | G31: 133.7222
A32: 43798 | B32: 89000 | C32: 54.818 | D32: 91100 | E32: 78.9042 | F32: 180100 | G32: 133.7222
A33: BIOCON | B33: 191292.5 | C33: 129.5285 | D33: 193830 | E33: 167.3942 | F33: 385122.5 | G33: 296.9227
A34: 43796 | B34: 191292.5 | C34: 129.5285 | D34: 193830 | E34: 167.3942 | F34: 385122.5 | G34: 296.9227
A35: LTOVER | B35: 2210 | C35: 59.6586 | F35: 2210 | G35: 59.6586
A36: 43795 | B36: 2210 | C36: 59.6586 | F36: 2210 | G36: 59.6586
A37: SUNPHA | B37: 159700 | C37: 101.0536 | D37: 160650 | E37: 141.6944 | F37: 320350 | G37: 242.748
A38: 43794 | B38: 159700 | C38: 101.0536 | D38: 160650 | E38: 141.6944 | F38: 320350 | G38: 242.748
A39: Grand Total | B39: 10533583 | C39: 7706.8035 | D39: 10670472 | E39: 8407.9179 | F39: 21204055 | G39: 16114.721
