Workbook

Sheet Pivot
A3: Sum of Amount | C3: Action
A4: FinPeriod | B4: MonthName | C4: Buy | D4: Sell | E4: Grand Total | H4: FinPeriod | I4: MonthName | J4: Sum of Amount | K4: RoundTotal
A5: 202411 | B5: Feb-25 | C5: -100491.2 | D5: 103222.12 | E5: 2730.92 | H5: 202411 | I5: Feb-25 | J5: 2730.92 | K5: =J5/1000 -> 2.73092
A6: 202412 | B6: Mar-25 | C6: -194752.9 | D6: 155224.38 | E6: -39528.52 | H6: 202412 | I6: Mar-25 | J6: -39528.52 | K6: =J6/1000 -> -39.52852
A7: 202501 | B7: Apr-25 | C7: -113602.68 | D7: 94301.42 | E7: -19301.26 | H7: 202501 | I7: Apr-25 | J7: -19301.26 | K7: =J7/1000 -> -19.30126
A8: Grand Total | C8: -408846.78 | D8: 352747.92 | E8: -56098.86 | H8: Grand Total | J8: -56098.86 | K8: =J8/1000 -> -56.09886
K9: =J9/1000 -> 0
K10: =J10/1000 -> 0
K11: =J11/1000 -> 0
K12: =J12/1000 -> 0
K13: =J13/1000 -> 0
K14: =J14/1000 -> 0
K15: =J15/1000 -> 0
K16: =J16/1000 -> 0
K17: =J17/1000 -> 0
K18: =J18/1000 -> 0
K19: =J19/1000 -> 0

Sheet Details
A1: Trade Date | B1: Contract Descriptor | C1: Exch | D1: Action | E1: Qty | F1: Qty Unit | G1: Price | H1: Price Unit | I1: Price Multiplier | J1: General Multiplier | K1: Value | L1: Brokerage | M1: Taxes(Incl of all charges) | N1: Order Ref. | O1: Contract Note no. | P1: Commodity Transaction Tax-CTT | Q1: Transaction Charges | R1: Stamp Duty | S1: SEBI Turnover Charges | T1: Brokerage | U1: GST | V1: Total Charges | W1: CalYear | X1: CalMonth | Y1: FinYear | Z1: FinMonth | AA1: FinMonth2 | AB1: FinPeriod | AC1: MonthName | AD1: Amount
A2: 45707 | B2: OPT-NATGAS-21-Feb-2025-360-C-E-C | C2: MCX | D2: Sell | E2: 1250 | F2: mmBtu | G2: 13.95 | H2: RS/1mmBtu | I2: 1 | J2: 1 | K2: 17437.5 | L2: 20 | M2: 20.95 | N2: #20250219X100041262 | O2: #20250219X100041262 | P2: 8.72 | Q2: 7.29 | R2: 0 | S2: 0.02 | T2: 20 | U2: 4.92 | V2: 40.95 | W2: =YEAR(A2) -> 2025 | X2: =MONTH(A2) -> 2 | Y2: =IF(X2<4,W2-1,W2) -> 2024 | Z2: =IF(X2<4,X2+9,X2-3) -> 11 | AA2: =IF(LEN(Z2)=1,_xlfn.CONCAT(0,Z2),Z2) -> 11 | AB2: =_xlfn.CONCAT(Y2,AA2) -> 202411 | AC2: =_xlfn.CONCAT(TEXT(A2,"MMM"),"-",MID(W2,3,2)) -> Feb-25 | AD2: =IFERROR(IF(D2="Sell",(K2-(M2+V2)),-(K2+(M2+V2))),0) -> 17375.6
A3: 45707 | B3: OPT-NATGAS-21-Feb-2025-360-C-E-C | C3: MCX | D3: Buy | E3: 1250 | F3: mmBtu | G3: 13.5 | H3: RS/1mmBtu | I3: 1 | J3: 1 | K3: 16875 | L3: 20 | M3: 12.46 | N3: #20250219X100038552 | O3: #20250219X100038552 | P3: 0 | Q3: 7.05 | R3: 0.51 | S3: 0.02 | T3: 20 | U3: 4.88 | V3: 32.46 | W3: =YEAR(A3) -> 2025 | X3: =MONTH(A3) -> 2 | Y3: =IF(X3<4,W3-1,W3) -> 2024 | Z3: =IF(X3<4,X3+9,X3-3) -> 11 | AA3: =IF(LEN(Z3)=1,_xlfn.CONCAT(0,Z3),Z3) -> 11 | AB3: =_xlfn.CONCAT(Y3,AA3) -> 202411 | AC3: =_xlfn.CONCAT(TEXT(A3,"MMM"),"-",MID(W3,3,2)) -> Feb-25 | AD3: =IFERROR(IF(D3="Sell",(K3-(M3+V3)),-(K3+(M3+V3))),0) -> -16919.92
A4: 45707 | B4: OPT-NATGAS-21-Feb-2025-350-C-E-C | C4: MCX | D4: Sell | E4: 1250 | F4: mmBtu | G4: 19.95 | H4: RS/1mmBtu | I4: 1 | J4: 1 | K4: 24937.5 | L4: 20 | M4: 28.2 | N4: #20250219X100033469 | O4: #20250219X100033469 | P4: 12.28 | Q4: 10.42 | R4: 0 | S4: 0.02 | T4: 20 | U4: 5.48 | V4: 48.2 | W4: =YEAR(A4) -> 2025 | X4: =MONTH(A4) -> 2 | Y4: =IF(X4<4,W4-1,W4) -> 2024 | Z4: =IF(X4<4,X4+9,X4-3) -> 11 | AA4: =IF(LEN(Z4)=1,_xlfn.CONCAT(0,Z4),Z4) -> 11 | AB4: =_xlfn.CONCAT(Y4,AA4) -> 202411 | AC4: =_xlfn.CONCAT(TEXT(A4,"MMM"),"-",MID(W4,3,2)) -> Feb-25 | AD4: =IFERROR(IF(D4="Sell",(K4-(M4+V4)),-(K4+(M4+V4))),0) -> 24861.1
A5: 45707 | B5: OPT-NATGAS-21-Feb-2025-350-C-E-C | C5: MCX | D5: Buy | E5: 1250 | F5: mmBtu | G5: 18.15 | H5: RS/1mmBtu | I5: 1 | J5: 1 | K5: 22687.5 | L5: 20 | M5: 15.5 | N5: #20250219X100033297 | O5: #20250219X100033297 | P5: 0 | Q5: 9.48 | R5: 0.68 | S5: 0.02 | T5: 20 | U5: 5.32 | V5: 35.5 | W5: =YEAR(A5) -> 2025 | X5: =MONTH(A5) -> 2 | Y5: =IF(X5<4,W5-1,W5) -> 2024 | Z5: =IF(X5<4,X5+9,X5-3) -> 11 | AA5: =IF(LEN(Z5)=1,_xlfn.CONCAT(0,Z5),Z5) -> 11 | AB5: =_xlfn.CONCAT(Y5,AA5) -> 202411 | AC5: =_xlfn.CONCAT(TEXT(A5,"MMM"),"-",MID(W5,3,2)) -> Feb-25 | AD5: =IFERROR(IF(D5="Sell",(K5-(M5+V5)),-(K5+(M5+V5))),0) -> -22738.5
A6: 45708 | B6: OPT-NATGAS-21-Feb-2025-355-C-E-C | C6: MCX | D6: Sell | E6: 1250 | F6: mmBtu | G6: 5.5 | H6: RS/1mmBtu | I6: 1 | J6: 1 | K6: 6875 | L6: 20 | M6: 10 | N6: #20250220X200024928 | O6: #20250220X200024928 | P6: 3 | Q6: 2.87 | R6: 0 | S6: 0.01 | T6: 20 | U6: 4.12 | V6: 30 | W6: =YEAR(A6) -> 2025 | X6: =MONTH(A6) -> 2 | Y6: =IF(X6<4,W6-1,W6) -> 2024 | Z6: =IF(X6<4,X6+9,X6-3) -> 11 | AA6: =IF(LEN(Z6)=1,_xlfn.CONCAT(0,Z6),Z6) -> 11 | AB6: =_xlfn.CONCAT(Y6,AA6) -> 202411 | AC6: =_xlfn.CONCAT(TEXT(A6,"MMM"),"-",MID(W6,3,2)) -> Feb-25 | AD6: =IFERROR(IF(D6="Sell",(K6-(M6+V6)),-(K6+(M6+V6))),0) -> 6835
A7: 45708 | B7: OPT-NATGAS-21-Feb-2025-355-C-E-C | C7: MCX | D7: Buy | E7: 1250 | F7: mmBtu | G7: 6.8 | H7: RS/1mmBtu | I7: 1 | J7: 1 | K7: 8500 | L7: 20 | M7: 8.06 | N7: #20250220X200024482 | O7: #20250220X200024482 | P7: 0 | Q7: 3.55 | R7: 0.26 | S7: 0.01 | T7: 20 | U7: 4.24 | V7: 28.06 | W7: =YEAR(A7) -> 2025 | X7: =MONTH(A7) -> 2 | Y7: =IF(X7<4,W7-1,W7) -> 2024 | Z7: =IF(X7<4,X7+9,X7-3) -> 11 | AA7: =IF(LEN(Z7)=1,_xlfn.CONCAT(0,Z7),Z7) -> 11 | AB7: =_xlfn.CONCAT(Y7,AA7) -> 202411 | AC7: =_xlfn.CONCAT(TEXT(A7,"MMM"),"-",MID(W7,3,2)) -> Feb-25 | AD7: =IFERROR(IF(D7="Sell",(K7-(M7+V7)),-(K7+(M7+V7))),0) -> -8536.12
A8: 45716 | B8: OPT-NATGAS-24-Mar-2025-335-C-E-C | C8: MCX | D8: Sell | E8: 1250 | F8: mmBtu | G8: 20.25 | H8: RS/1mmBtu | I8: 1 | J8: 1 | K8: 25312.5 | L8: 20 | M8: 28.77 | N8: #20250228X200020899 | O8: #20250228X200020899 | P8: 12.66 | Q8: 10.58 | R8: 0 | S8: 0.03 | T8: 20 | U8: 5.5 | V8: 48.77 | W8: =YEAR(A8) -> 2025 | X8: =MONTH(A8) -> 2 | Y8: =IF(X8<4,W8-1,W8) -> 2024 | Z8: =IF(X8<4,X8+9,X8-3) -> 11 | AA8: =IF(LEN(Z8)=1,_xlfn.CONCAT(0,Z8),Z8) -> 11 | AB8: =_xlfn.CONCAT(Y8,AA8) -> 202411 | AC8: =_xlfn.CONCAT(TEXT(A8,"MMM"),"-",MID(W8,3,2)) -> Feb-25 | AD8: =IFERROR(IF(D8="Sell",(K8-(M8+V8)),-(K8+(M8+V8))),0) -> 25234.96
A9: 45716 | B9: OPT-NATGAS-24-Mar-2025-335-C-E-C | C9: MCX | D9: Buy | E9: 1250 | F9: mmBtu | G9: 19.65 | H9: RS/1mmBtu | I9: 1 | J9: 1 | K9: 24562.5 | L9: 20 | M9: 15.75 | N9: #20250228X200020080 | O9: #20250228X200020080 | P9: 0 | Q9: 10.27 | R9: 0 | S9: 0.02 | T9: 20 | U9: 5.46 | V9: 35.75 | W9: =YEAR(A9) -> 2025 | X9: =MONTH(A9) -> 2 | Y9: =IF(X9<4,W9-1,W9) -> 2024 | Z9: =IF(X9<4,X9+9,X9-3) -> 11 | AA9: =IF(LEN(Z9)=1,_xlfn.CONCAT(0,Z9),Z9) -> 11 | AB9: =_xlfn.CONCAT(Y9,AA9) -> 202411 | AC9: =_xlfn.CONCAT(TEXT(A9,"MMM"),"-",MID(W9,3,2)) -> Feb-25 | AD9: =IFERROR(IF(D9="Sell",(K9-(M9+V9)),-(K9+(M9+V9))),0) -> -24614
A10: 45716 | B10: OPT-NATGAS-24-Mar-2025-335-C-E-C | C10: MCX | D10: Sell | E10: 1250 | F10: mmBtu | G10: 23.2 | H10: RS/1mmBtu | I10: 1 | J10: 1 | K10: 29000 | L10: 20 | M10: 32.27 | N10: #20250228X200013675 | O10: #20250228X200013675 | P10: 14.34 | Q10: 12.12 | R10: 0 | S10: 0.03 | T10: 20 | U10: 5.78 | V10: 52.27 | W10: =YEAR(A10) -> 2025 | X10: =MONTH(A10) -> 2 | Y10: =IF(X10<4,W10-1,W10) -> 2024 | Z10: =IF(X10<4,X10+9,X10-3) -> 11 | AA10: =IF(LEN(Z10)=1,_xlfn.CONCAT(0,Z10),Z10) -> 11 | AB10: =_xlfn.CONCAT(Y10,AA10) -> 202411 | AC10: =_xlfn.CONCAT(TEXT(A10,"MMM"),"-",MID(W10,3,2)) -> Feb-25 | AD10: =IFERROR(IF(D10="Sell",(K10-(M10+V10)),-(K10+(M10+V10))),0) -> 28915.46
A11: 45716 | B11: OPT-NATGAS-24-Mar-2025-335-C-E-C | C11: MCX | D11: Buy | E11: 1250 | F11: mmBtu | G11: 22.1 | H11: RS/1mmBtu | I11: 1 | J11: 1 | K11: 27625 | L11: 20 | M11: 18.83 | N11: #20250228X200013025 | O11: #20250228X200013025 | P11: 0 | Q11: 11.55 | R11: 1.57 | S11: 0.03 | T11: 20 | U11: 5.68 | V11: 38.83 | W11: =YEAR(A11) -> 2025 | X11: =MONTH(A11) -> 2 | Y11: =IF(X11<4,W11-1,W11) -> 2024 | Z11: =IF(X11<4,X11+9,X11-3) -> 11 | AA11: =IF(LEN(Z11)=1,_xlfn.CONCAT(0,Z11),Z11) -> 11 | AB11: =_xlfn.CONCAT(Y11,AA11) -> 202411 | AC11: =_xlfn.CONCAT(TEXT(A11,"MMM"),"-",MID(W11,3,2)) -> Feb-25 | AD11: =IFERROR(IF(D11="Sell",(K11-(M11+V11)),-(K11+(M11+V11))),0) -> -27682.66
A12: 45720 | B12: OPT-NATGAS-24-Mar-2025-360-P-E-C | C12: MCX | D12: Buy | E12: 1250 | F12: mmBtu | G12: 15.05 | H12: RS/1mmBtu | I12: 1 | J12: 1 | K12: 18812.5 | L12: 20 | M12: 13.46 | N12: #20250304X200016399 | O12: #20250304X200016399 | P12: 0 | Q12: 7.86 | R12: 0.56 | S12: 0.02 | T12: 20 | U12: 5.02 | V12: 33.46 | W12: =YEAR(A12) -> 2025 | X12: =MONTH(A12) -> 3 | Y12: =IF(X12<4,W12-1,W12) -> 2024 | Z12: =IF(X12<4,X12+9,X12-3) -> 12 | AA12: =IF(LEN(Z12)=1,_xlfn.CONCAT(0,Z12),Z12) -> 12 | AB12: =_xlfn.CONCAT(Y12,AA12) -> 202412 | AC12: =_xlfn.CONCAT(TEXT(A12,"MMM"),"-",MID(W12,3,2)) -> Mar-25 | AD12: =IFERROR(IF(D12="Sell",(K12-(M12+V12)),-(K12+(M12+V12))),0) -> -18859.42
A13: 45721 | B13: OPT-NATGAS-24-Mar-2025-360-P-E-C | C13: MCX | D13: Sell | E13: 1250 | F13: mmBtu | G13: 13 | H13: RS/1mmBtu | I13: 1 | J13: 1 | K13: 16250 | L13: 20 | M13: 19.63 | N13: #20250305X200000421 | O13: #20250305X200000421 | P13: 8 | Q13: 6.79 | R13: 0 | S13: 0.02 | T13: 20 | U13: 4.82 | V13: 39.63 | W13: =YEAR(A13) -> 2025 | X13: =MONTH(A13) -> 3 | Y13: =IF(X13<4,W13-1,W13) -> 2024 | Z13: =IF(X13<4,X13+9,X13-3) -> 12 | AA13: =IF(LEN(Z13)=1,_xlfn.CONCAT(0,Z13),Z13) -> 12 | AB13: =_xlfn.CONCAT(Y13,AA13) -> 202412 | AC13: =_xlfn.CONCAT(TEXT(A13,"MMM"),"-",MID(W13,3,2)) -> Mar-25 | AD13: =IFERROR(IF(D13="Sell",(K13-(M13+V13)),-(K13+(M13+V13))),0) -> 16190.74
... A39: 45750 | B39: OPT-NATGAS-23-Apr-2025-350-P-E-C | C39: MCX | D39: Buy | E39: 1250 | F39: mmBtu | G39: 19.1 | H39: RS/1mmBtu | I39: 1 | J39: 1 | K39: 23875 | L39: 20 | M39: 16.75 | N39: #20250403X200016737 | O39: #20250403X200016737 | P39: 0 | Q39: 9.98 | R39: 1.35 | S39: 0.02 | T39: 20 | U39: 5.4 | V39: 36.75 | W39: =YEAR(A39) -> 2025 | X39: =MONTH(A39) -> 4 | Y39: =IF(X39<4,W39-1,W39) -> 2025 | Z39: =IF(X39<4,X39+9,X39-3) -> 1 | AA39: =IF(LEN(Z39)=1,_xlfn.CONCAT(0,Z39),Z39) -> 01 | AB39: =_xlfn.CONCAT(Y39,AA39) -> 202501 | AC39: =_xlfn.CONCAT(TEXT(A39,"MMM"),"-",MID(W39,3,2)) -> Apr-25 | AD39: =IFERROR(IF(D39="Sell",(K39-(M39+V39)),-(K39+(M39+V39))),0) -> -23928.5

Sheet OI Trend
A1: 350 | B1: call OI | C1: Put OI | D1: Diff | E1: Go with | G1: =A1+5 -> 355 | H1: call OI | I1: Put OI | J1: Diff | K1: Go with | M1: =G1+5 -> 360 | N1: call OI | O1: Put OI | P1: Diff | Q1: Go with | S1: Outcome
A2: 9.2 | B2: 2909 | C2: 4277 | D2: =C2-B2 -> 1368 | E2: =IF(D2>=2000,"Strong Call",IF(D2>1000,"Call",IF(D2>=-1000,"Wait",IF(D2>=-2000,"Put","Strong Put")))) -> Call | G2: 9.2 | H2: 1045 | I2: 917 | J2: =I2-H2 -> -128 | K2: =IF(J2>=2000,"Strong Call",IF(J2>1000,"Call",IF(J2>=-1000,"Wait",IF(J2>=-2000,"Put","Strong Put")))) -> Wait | M2: 9.2 | N2: 2870 | O2: 1589 | P2: =O2-N2 -> -1281 | Q2: =IF(P2>=2000,"Strong Call",IF(P2>1000,"Call",IF(P2>=-1000,"Wait",IF(P2>=-2000,"Put","Strong Put")))) -> Put | R2: =E2&K2&Q2 -> CallWaitPut | S2: =VLOOKUP(R2,Strategy!A:E,5,0) -> Rangebound
A3: 9.3 | B3: 2918 | C3: 4159 | D3: =C3-B3 -> 1241 | E3: =IF(D3>=2000,"Strong Call",IF(D3>1000,"Call",IF(D3>=-1000,"Wait",IF(D3>=-2000,"Put","Strong Put")))) -> Call | G3: 9.3 | I3: 894 | J3: =I3-H3 -> 894 | K3: =IF(J3>=2000,"Strong Call",IF(J3>1000,"Call",IF(J3>=-1000,"Wait",IF(J3>=-2000,"Put","Strong Put")))) -> Wait | M3: 9.3 | N3: 2814 | O3: 1565 | P3: =O3-N3 -> -1249 | Q3: =IF(P3>=2000,"Strong Call",IF(P3>1000,"Call",IF(P3>=-1000,"Wait",IF(P3>=-2000,"Put","Strong Put")))) -> Put | R3: =E3&K3&Q3 -> CallWaitPut | S3: =VLOOKUP(R3,Strategy!A:E,5,0) -> Rangebound
A4: 9.45 | B4: 2963 | C4: 4216 | D4: =C4-B4 -> 1253 | E4: =IF(D4>=2000,"Strong Call",IF(D4>1000,"Call",IF(D4>=-1000,"Wait",IF(D4>=-2000,"Put","Strong Put")))) -> Call | G4: 9.45 | I4: 882 | J4: =I4-H4 -> 882 | K4: =IF(J4>=2000,"Strong Call",IF(J4>1000,"Call",IF(J4>=-1000,"Wait",IF(J4>=-2000,"Put","Strong Put")))) -> Wait | M4: 9.45 | N4: 2841 | O4: 1562 | P4: =O4-N4 -> -1279 | Q4: =IF(P4>=2000,"Strong Call",IF(P4>1000,"Call",IF(P4>=-1000,"Wait",IF(P4>=-2000,"Put","Strong Put")))) -> Put | R4: =E4&K4&Q4 -> CallWaitPut | S4: =VLOOKUP(R4,Strategy!A:E,5,0) -> Rangebound | T4: Continous Strong Put/Call implies Rangebound Trade
A5: 9.55 | D5: =C5-B5 -> 0 | E5: =IF(D5>=2000,"Strong Call",IF(D5>1000,"Call",IF(D5>=-1000,"Wait",IF(D5>=-2000,"Put","Strong Put")))) -> Wait | G5: 9.55 | J5: =I5-H5 -> 0 | K5: =IF(J5>=2000,"Strong Call",IF(J5>1000,"Call",IF(J5>=-1000,"Wait",IF(J5>=-2000,"Put","Strong Put")))) -> Wait | M5: 9.55 | P5: =O5-N5 -> 0 | Q5: =IF(P5>=2000,"Strong Call",IF(P5>1000,"Call",IF(P5>=-1000,"Wait",IF(P5>=-2000,"Put","Strong Put")))) -> Wait | R5: =E5&K5&Q5 -> WaitWaitWait | S5: =VLOOKUP(R5,Strategy!A:E,5,0) -> Rangebound
A6: 10.05 | D6: =C6-B6 -> 0 | E6: =IF(D6>=2000,"Strong Call",IF(D6>1000,"Call",IF(D6>=-1000,"Wait",IF(D6>=-2000,"Put","Strong Put")))) -> Wait | G6: 10.05 | J6: =I6-H6 -> 0 | K6: =IF(J6>=2000,"Strong Call",IF(J6>1000,"Call",IF(J6>=-1000,"Wait",IF(J6>=-2000,"Put","Strong Put")))) -> Wait | M6: 10.05 | P6: =O6-N6 -> 0 | Q6: =IF(P6>=2000,"Strong Call",IF(P6>1000,"Call",IF(P6>=-1000,"Wait",IF(P6>=-2000,"Put","Strong Put")))) -> Wait | R6: =E6&K6&Q6 -> WaitWaitWait | S6: =VLOOKUP(R6,Strategy!A:E,5,0) -> Rangebound
A7: 10.25 | D7: =C7-B7 -> 0 | E7: =IF(D7>=2000,"Strong Call",IF(D7>1000,"Call",IF(D7>=-1000,"Wait",IF(D7>=-2000,"Put","Strong Put")))) -> Wait | G7: 10.25 | J7: =I7-H7 -> 0 | K7: =IF(J7>=2000,"Strong Call",IF(J7>1000,"Call",IF(J7>=-1000,"Wait",IF(J7>=-2000,"Put","Strong Put")))) -> Wait | M7: 10.25 | P7: =O7-N7 -> 0 | Q7: =IF(P7>=2000,"Strong Call",IF(P7>1000,"Call",IF(P7>=-1000,"Wait",IF(P7>=-2000,"Put","Strong Put")))) -> Wait | R7: =E7&K7&Q7 -> WaitWaitWait | S7: =VLOOKUP(R7,Strategy!A:E,5,0) -> Rangebound
A8: 10.4 | D8: =C8-B8 -> 0 | E8: =IF(D8>=2000,"Strong Call",IF(D8>1000,"Call",IF(D8>=-1000,"Wait",IF(D8>=-2000,"Put","Strong Put")))) -> Wait | G8: 10.4 | J8: =I8-H8 -> 0 | K8: =IF(J8>=2000,"Strong Call",IF(J8>1000,"Call",IF(J8>=-1000,"Wait",IF(J8>=-2000,"Put","Strong Put")))) -> Wait | M8: 10.4 | P8: =O8-N8 -> 0 | Q8: =IF(P8>=2000,"Strong Call",IF(P8>1000,"Call",IF(P8>=-1000,"Wait",IF(P8>=-2000,"Put","Strong Put")))) -> Wait | R8: =E8&K8&Q8 -> WaitWaitWait | S8: =VLOOKUP(R8,Strategy!A:E,5,0) -> Rangebound
A9: 10.55 | D9: =C9-B9 -> 0 | E9: =IF(D9>=2000,"Strong Call",IF(D9>1000,"Call",IF(D9>=-1000,"Wait",IF(D9>=-2000,"Put","Strong Put")))) -> Wait | G9: 10.55 | J9: =I9-H9 -> 0 | K9: =IF(J9>=2000,"Strong Call",IF(J9>1000,"Call",IF(J9>=-1000,"Wait",IF(J9>=-2000,"Put","Strong Put")))) -> Wait | M9: 10.55 | P9: =O9-N9 -> 0 | Q9: =IF(P9>=2000,"Strong Call",IF(P9>1000,"Call",IF(P9>=-1000,"Wait",IF(P9>=-2000,"Put","Strong Put")))) -> Wait | R9: =E9&K9&Q9 -> WaitWaitWait | S9: =VLOOKUP(R9,Strategy!A:E,5,0) -> Rangebound
A10: 11.05 | D10: =C10-B10 -> 0 | E10: =IF(D10>=2000,"Strong Call",IF(D10>1000,"Call",IF(D10>=-1000,"Wait",IF(D10>=-2000,"Put","Strong Put")))) -> Wait | G10: 11.05 | J10: =I10-H10 -> 0 | K10: =IF(J10>=2000,"Strong Call",IF(J10>1000,"Call",IF(J10>=-1000,"Wait",IF(J10>=-2000,"Put","Strong Put")))) -> Wait | M10: 11.05 | P10: =O10-N10 -> 0 | Q10: =IF(P10>=2000,"Strong Call",IF(P10>1000,"Call",IF(P10>=-1000,"Wait",IF(P10>=-2000,"Put","Strong Put")))) -> Wait | R10: =E10&K10&Q10 -> WaitWaitWait | S10: =VLOOKUP(R10,Strategy!A:E,5,0) -> Rangebound
A11: 11.25 | D11: =C11-B11 -> 0 | E11: =IF(D11>=2000,"Strong Call",IF(D11>1000,"Call",IF(D11>=-1000,"Wait",IF(D11>=-2000,"Put","Strong Put")))) -> Wait | G11: 11.25 | J11: =I11-H11 -> 0 | K11: =IF(J11>=2000,"Strong Call",IF(J11>1000,"Call",IF(J11>=-1000,"Wait",IF(J11>=-2000,"Put","Strong Put")))) -> Wait | M11: 11.25 | P11: =O11-N11 -> 0 | Q11: =IF(P11>=2000,"Strong Call",IF(P11>1000,"Call",IF(P11>=-1000,"Wait",IF(P11>=-2000,"Put","Strong Put")))) -> Wait | R11: =E11&K11&Q11 -> WaitWaitWait | S11: =VLOOKUP(R11,Strategy!A:E,5,0) -> Rangebound
A12: 11.35 | D12: =C12-B12 -> 0 | E12: =IF(D12>=2000,"Strong Call",IF(D12>1000,"Call",IF(D12>=-1000,"Wait",IF(D12>=-2000,"Put","Strong Put")))) -> Wait | G12: 11.35 | J12: =I12-H12 -> 0 | K12: =IF(J12>=2000,"Strong Call",IF(J12>1000,"Call",IF(J12>=-1000,"Wait",IF(J12>=-2000,"Put","Strong Put")))) -> Wait | M12: 11.35 | P12: =O12-N12 -> 0 | Q12: =IF(P12>=2000,"Strong Call",IF(P12>1000,"Call",IF(P12>=-1000,"Wait",IF(P12>=-2000,"Put","Strong Put")))) -> Wait | R12: =E12&K12&Q12 -> WaitWaitWait | S12: =VLOOKUP(R12,Strategy!A:E,5,0) -> Rangebound
A13: 12.25 | D13: =C13-B13 -> 0 | E13: =IF(D13>=2000,"Strong Call",IF(D13>1000,"Call",IF(D13>=-1000,"Wait",IF(D13>=-2000,"Put","Strong Put")))) -> Wait | G13: 12.25 | J13: =I13-H13 -> 0 | K13: =IF(J13>=2000,"Strong Call",IF(J13>1000,"Call",IF(J13>=-1000,"Wait",IF(J13>=-2000,"Put","Strong Put")))) -> Wait | M13: 12.25 | P13: =O13-N13 -> 0 | Q13: =IF(P13>=2000,"Strong Call",IF(P13>1000,"Call",IF(P13>=-1000,"Wait",IF(P13>=-2000,"Put","Strong Put")))) -> Wait | R13: =E13&K13&Q13 -> WaitWaitWait | S13: =VLOOKUP(R13,Strategy!A:E,5,0) -> Rangebound
A14: 1.25 | D14: =C14-B14 -> 0 | E14: =IF(D14>=2000,"Strong Call",IF(D14>1000,"Call",IF(D14>=-1000,"Wait",IF(D14>=-2000,"Put","Strong Put")))) -> Wait | G14: 1.25 | J14: =I14-H14 -> 0 | K14: =IF(J14>=2000,"Strong Call",IF(J14>1000,"Call",IF(J14>=-1000,"Wait",IF(J14>=-2000,"Put","Strong Put")))) -> Wait | M14: 1.25 | P14: =O14-N14 -> 0 | Q14: =IF(P14>=2000,"Strong Call",IF(P14>1000,"Call",IF(P14>=-1000,"Wait",IF(P14>=-2000,"Put","Strong Put")))) -> Wait | R14: =E14&K14&Q14 -> WaitWaitWait | S14: =VLOOKUP(R14,Strategy!A:E,5,0) -> Rangebound
A15: 2.15 | D15: =C15-B15 -> 0 | E15: =IF(D15>=2000,"Strong Call",IF(D15>1000,"Call",IF(D15>=-1000,"Wait",IF(D15>=-2000,"Put","Strong Put")))) -> Wait | G15: 2.15 | J15: =I15-H15 -> 0 | K15: =IF(J15>=2000,"Strong Call",IF(J15>1000,"Call",IF(J15>=-1000,"Wait",IF(J15>=-2000,"Put","Strong Put")))) -> Wait | M15: 2.15 | P15: =O15-N15 -> 0 | Q15: =IF(P15>=2000,"Strong Call",IF(P15>1000,"Call",IF(P15>=-1000,"Wait",IF(P15>=-2000,"Put","Strong Put")))) -> Wait | R15: =E15&K15&Q15 -> WaitWaitWait | S15: =VLOOKUP(R15,Strategy!A:E,5,0) -> Rangebound

Sheet Sheet1
A1: Checklist | B1: Values | C1: 45754 | D1: 45755 | E1: 45756 | F1: 45757 | G1: 45758 | H1: 45759 | I1: 45760 | J1: 45761 | K1: 45762 | L1: 45763 | M1: 45764 | N1: 45765 | O1: 45766 | P1: 45767
A2: Daytype | B2: Normal/Expiry/Critical | C2: Normal | D2: Normal
A3: OI Favourable | B3: Normal/Rangebound/Volatile | C3: Normal | D3: Normal
A4: Indicators Favourable | B4: YES/NO | C4: YES | D4: NO
A5: CD Pattern | B5: Horizontal/Vertical/Fooling/Spinning | C5: Vertical | D5: Fooling
A6: Triangle Pattern | B6: YES/NO | C6: YES | D6: NO
A7: SL: Prev Candle bottom | B7: YES/NO | C7: YES | D7: NO
A8: Reversal Bulk Buy | B8: YES/NO | C8: NO | D8: NO
A9: Hurry Buy | B9: YES/NO | C9: NO | D9: YES
A10: Pulse | B10: Normal/Fear/Careless/Greed | C10: Normal | D10: Normal
A11: 15 Mins Period | B11: YES/NO | C11: YES | D11: NO
A12: Bought below 10 | B12: YES/NO | C12: NO | D12: NO
A13: Situation Based Trade | B13: YES/NO | C13: YES | D13: NO
A14: Trade Level | C14: =SUM(IF(C2="Normal",1,0))+SUM(IF(C3="Normal",1,-1))+SUM(IF(C4="YES",1,0))+SUM(IF(C5="Vertical",1,-1))+ SUM(IF(C6="YES",1,0))+SUM(IF(C7="YES",1,0))+SUM(IF(C8="YES",-1,1))+SUM(IF(C9="YES",-1,1))+SUM(IF(C10="Normal",1,-1))+ SUM(IF(C11="YES",1,-1))+SUM(IF(C11="YES",-1,1))+SUM(IF(C12="YES",1,0))+SUM(IF(C13="YES",1,0)) -> 10 | D14: =SUM(IF(D2="Normal",1,0))+SUM(IF(D3="Normal",1,-1))+SUM(IF(D4="YES",1,0))+SUM(IF(D5="Vertical",1,-1))+ SUM(IF(D6="YES",1,0))+SUM(IF(D7="YES",1,0))+SUM(IF(D8="YES",-1,1))+SUM(IF(D9="YES",-1,1))+SUM(IF(D10="Normal",1,-1))+ SUM(IF(D11="YES",1,-1))+SUM(IF(D11="YES",-1,1))+SUM(IF(D12="YES",1,0))+SUM(IF(D13="YES",1,0)) -> 2 | E14: =SUM(IF(E2="Normal",1,0))+SUM(IF(E3="Normal",1,-1))+SUM(IF(E4="YES",1,0))+SUM(IF(E5="Vertical",1,-1))+ SUM(IF(E6="YES",1,0))+SUM(IF(E7="YES",1,0))+SUM(IF(E8="YES",-1,1))+SUM(IF(E9="YES",-1,1))+SUM(IF(E10="Normal",1,-1))+ SUM(IF(E11="YES",1,-1))+SUM(IF(E11="YES",-1,1))+SUM(IF(E12="YES",1,0))+SUM(IF(E13="YES",1,0)) -> -1 | F14: =SUM(IF(F2="Normal",1,0))+SUM(IF(F3="Normal",1,-1))+SUM(IF(F4="YES",1,0))+SUM(IF(F5="Vertical",1,-1))+ SUM(IF(F6="YES",1,0))+SUM(IF(F7="YES",1,0))+SUM(IF(F8="YES",-1,1))+SUM(IF(F9="YES",-1,1))+SUM(IF(F10="Normal",1,-1))+ SUM(IF(F11="YES",1,-1))+SUM(IF(F11="YES",-1,1))+SUM(IF(F12="YES",1,0))+SUM(IF(F13="YES",1,0)) -> -1 | G14: =SUM(IF(G2="Normal",1,0))+SUM(IF(G3="Normal",1,-1))+SUM(IF(G4="YES",1,0))+SUM(IF(G5="Vertical",1,-1))+ SUM(IF(G6="YES",1,0))+SUM(IF(G7="YES",1,0))+SUM(IF(G8="YES",-1,1))+SUM(IF(G9="YES",-1,1))+SUM(IF(G10="Normal",1,-1))+ SUM(IF(G11="YES",1,-1))+SUM(IF(G11="YES",-1,1))+SUM(IF(G12="YES",1,0))+SUM(IF(G13="YES",1,0)) -> -1 | H14: =SUM(IF(H2="Normal",1,0))+SUM(IF(H3="Normal",1,-1))+SUM(IF(H4="YES",1,0))+SUM(IF(H5="Vertical",1,-1))+ SUM(IF(H6="YES",1,0))+SUM(IF(H7="YES",1,0))+SUM(IF(H8="YES",-1,1))+SUM(IF(H9="YES",-1,1))+SUM(IF(H10="Normal",1,-1))+ SUM(IF(H11="YES",1,-1))+SUM(IF(H11="YES",-1,1))+SUM(IF(H12="YES",1,0))+SUM(IF(H13="YES",1,0)) -> -1 | I14: =SUM(IF(I2="Normal",1,0))+SUM(IF(I3="Normal",1,-1))+SUM(IF(I4="YES",1,0))+SUM(IF(I5="Vertical",1,-1))+ SUM(IF(I6="YES",1,0))+SUM(IF(I7="YES",1,0))+SUM(IF(I8="YES",-1,1))+SUM(IF(I9="YES",-1,1))+SUM(IF(I10="Normal",1,-1))+ SUM(IF(I11="YES",1,-1))+SUM(IF(I11="YES",-1,1))+SUM(IF(I12="YES",1,0))+SUM(IF(I13="YES",1,0)) -> -1 | J14: =SUM(IF(J2="Normal",1,0))+SUM(IF(J3="Normal",1,-1))+SUM(IF(J4="YES",1,0))+SUM(IF(J5="Vertical",1,-1))+ SUM(IF(J6="YES",1,0))+SUM(IF(J7="YES",1,0))+SUM(IF(J8="YES",-1,1))+SUM(IF(J9="YES",-1,1))+SUM(IF(J10="Normal",1,-1))+ SUM(IF(J11="YES",1,-1))+SUM(IF(J11="YES",1,-1))+SUM(IF(J12="YES",0,1))+SUM(IF(J13="YES",1,0)) -> -2 | K14: =IF(SUM(IF(K2="Normal",1,0))+SUM(IF(K3="Normal",1,-1))+SUM(IF(K7="YES",1,0))+SUM(IF(K4="YES",1,0))+SUM(IF(K6="YES",1,0))+SUM(IF(K8="YES",-1,0))<=0,"",SUM(IF(K2="Normal",1,0))+SUM(IF(K3="Normal",1,-1))+SUM(IF(K7="YES",1,0))+SUM(IF(K4="YES",1,0))+SUM(IF(K6="YES",1,0))+SUM(IF(K8="YES",-1,1)+SUM(IF(K9="YES",-1,1))+SUM(IF(K10="Normal",1,-1))+SUM(IF(K11="YES",1,-1)+SUM(IF(K5="Vertical",1,-1))))) | L14: =IF(SUM(IF(L2="Normal",1,0))+SUM(IF(L3="Normal",1,-1))+SUM(IF(L7="YES",1,0))+SUM(IF(L4="YES",1,0))+SUM(IF(L6="YES",1,0))+SUM(IF(L8="YES",-1,0))<=0,"",SUM(IF(L2="Normal",1,0))+SUM(IF(L3="Normal",1,-1))+SUM(IF(L7="YES",1,0))+SUM(IF(L4="YES",1,0))+SUM(IF(L6="YES",1,0))+SUM(IF(L8="YES",-1,1)+SUM(IF(L9="YES",-1,1))+SUM(IF(L10="Normal",1,-1))+SUM(IF(L11="YES",1,-1)+SUM(IF(L5="Vertical",1,-1))))) | M14: =IF(SUM(IF(M2="Normal",1,0))+SUM(IF(M3="Normal",1,-1))+SUM(IF(M7="YES",1,0))+SUM(IF(M4="YES",1,0))+SUM(IF(M6="YES",1,0))+SUM(IF(M8="YES",-1,0))<=0,"",SUM(IF(M2="Normal",1,0))+SUM(IF(M3="Normal",1,-1))+SUM(IF(M7="YES",1,0))+SUM(IF(M4="YES",1,0))+SUM(IF(M6="YES",1,0))+SUM(IF(M8="YES",-1,1)+SUM(IF(M9="YES",-1,1))+SUM(IF(M10="Normal",1,-1))+SUM(IF(M11="YES",1,-1)+SUM(IF(M5="Vertical",1,-1))))) | N14: =IF(SUM(IF(N2="Normal",1,0))+SUM(IF(N3="Normal",1,-1))+SUM(IF(N7="YES",1,0))+SUM(IF(N4="YES",1,0))+SUM(IF(N6="YES",1,0))+SUM(IF(N8="YES",-1,0))<=0,"",SUM(IF(N2="Normal",1,0))+SUM(IF(N3="Normal",1,-1))+SUM(IF(N7="YES",1,0))+SUM(IF(N4="YES",1,0))+SUM(IF(N6="YES",1,0))+SUM(IF(N8="YES",-1,1)+SUM(IF(N9="YES",-1,1))+SUM(IF(N10="Normal",1,-1))+SUM(IF(N11="YES",1,-1)+SUM(IF(N5="Vertical",1,-1))))) | O14: =IF(SUM(IF(O2="Normal",1,0))+SUM(IF(O3="Normal",1,-1))+SUM(IF(O7="YES",1,0))+SUM(IF(O4="YES",1,0))+SUM(IF(O6="YES",1,0))+SUM(IF(O8="YES",-1,0))<=0,"",SUM(IF(O2="Normal",1,0))+SUM(IF(O3="Normal",1,-1))+SUM(IF(O7="YES",1,0))+SUM(IF(O4="YES",1,0))+SUM(IF(O6="YES",1,0))+SUM(IF(O8="YES",-1,1)+SUM(IF(O9="YES",-1,1))+SUM(IF(O10="Normal",1,-1))+SUM(IF(O11="YES",1,-1)+SUM(IF(O5="Vertical",1,-1))))) | P14: =IF(SUM(IF(P2="Normal",1,0))+SUM(IF(P3="Normal",1,-1))+SUM(IF(P7="YES",1,0))+SUM(IF(P4="YES",1,0))+SUM(IF(P6="YES",1,0))+SUM(IF(P8="YES",-1,0))<=0,"",SUM(IF(P2="Normal",1,0))+SUM(IF(P3="Normal",1,-1))+SUM(IF(P7="YES",1,0))+SUM(IF(P4="YES",1,0))+SUM(IF(P6="YES",1,0))+SUM(IF(P8="YES",-1,1)+SUM(IF(P9="YES",-1,1))+SUM(IF(P10="Normal",1,-1))+SUM(IF(P11="YES",1,-1)+SUM(IF(P5="Vertical",1,-1)))))
A15: Trade Quality | C15: =IF(C14>=10,"Very Good",IF(C14 >=7,"Good",IF(C14>=5,"Avg",IF(C14<5,"Poor",IF(C14="","Poor","Poor"))))) -> Very Good | D15: =IF(D14>=10,"Very Good",IF(D14 >=7,"Good",IF(D14>=5,"Avg",IF(D14<5,"Poor",IF(D14="","Poor","Poor"))))) -> Poor | E15: =IF(E14>=10,"Very Good",IF(E14 >=7,"Good",IF(E14>=5,"Avg",IF(E14<5,"Poor",IF(E14="","Poor","Poor"))))) -> Poor | F15: =IF(F14>=10,"Very Good",IF(F14 >=7,"Good",IF(F14>=5,"Avg",IF(F14<5,"Poor",IF(F14="","Poor","Poor"))))) -> Poor | G15: =IF(G14>=10,"Very Good",IF(G14 >=7,"Good",IF(G14>=5,"Avg",IF(G14<5,"Poor",IF(G14="","Poor","Poor"))))) -> Poor | H15: =IF(H14>=10,"Very Good",IF(H14 >=7,"Good",IF(H14>=5,"Avg",IF(H14<5,"Poor",IF(H14="","Poor","Poor"))))) -> Poor | I15: =IF(I14>=10,"Very Good",IF(I14 >=7,"Good",IF(I14>=5,"Avg",IF(I14<5,"Poor",IF(I14="","Poor","Poor"))))) -> Poor | J15: =IF(J14>=10,"Very Good",IF(J14 >=7,"Good",IF(J14>=5,"Avg",IF(J14<5,"Poor",IF(J14="","Poor","Poor"))))) -> Poor | ... M15: =IF(M14>=10,"Very Good",IF(M14 >=7,"Good",IF(M14>=5,"Avg",IF(M14<5,"Poor",IF(M14="","Poor","Poor"))))) -> Very Good
C16: 0.70347222 | D16: 0.72986111
C17: 0.71388889 | D17: 0.74027778
C18: 0.7125 | D18: 0.39583333
C19: =C18-C16 -> 0.0090277778 | D19: 0.70833333
B20: Total Lots | C20: 1 | D20: 1
A21: =SUM(C21:P21) -> -4812.5 | B21: Estimated P/L | C21: 1687.5 | D21: -6500
A22: =SUM(C22:P22) -> 0 | B22: Actual P/L
A23: =SUM(C23:P23) -> -4812.5 | B23: Brokerage | C23: =C21-C22 -> 1687.5 | D23: =D21-D22 -> -6500 | E23: =E21-E22 -> 0 | F23: =F21-F22 -> 0 | G23: =G21-G22 -> 0 | H23: =H21-H22 -> 0 | I23: =I21-I22 -> 0 | J23: =J21-J22 -> 0 | ... M23: =M21-M22 -> 0
A24: =SUM(C24:P24) -> 80 | B24: Commission | C24: =C20*40 -> 40 | D24: =D20*40 -> 40 | E24: =E20*40 -> 0 | F24: =F20*40 -> 0 | G24: =G20*40 -> 0 | H24: =H20*40 -> 0 | I24: =I20*40 -> 0 | J24: =J20*40 -> 0 | ... M24: =M20*40 -> 0
A25: =SUM(C25:P25) -> -4892.5 | B25: Tax | C25: =C23-C24 -> 1647.5 | D25: =D23-D24 -> -6540 | E25: =E23-E24 -> 0 | F25: =F23-F24 -> 0 | G25: =G23-G24 -> 0 | H25: =H23-H24 -> 0 | I25: =I23-I24 -> 0 | J25: =J23-J24 -> 0 | ... M25: =M23-M24 -> 0
C26: =C22/C21 -> 0 | D26: =D22/D21 -> 0 | E26: =E22/E21 -> #DIV/0! | F26: =F22/F21 -> #DIV/0! | G26: =G22/G21 -> #DIV/0! | H26: =H22/H21 -> #DIV/0! | I26: =I22/I21 -> #DIV/0! | J26: =J22/J21 -> #DIV/0! | ... M26: =M22/M21 -> #DIV/0!
C27: =C23/C21 -> 1 | D27: =D23/D21 -> 1 | E27: =E23/E21 -> #DIV/0! | F27: =F23/F21 -> #DIV/0! | G27: =G23/G21 -> #DIV/0! | H27: =H23/H21 -> #DIV/0! | I27: =I23/I21 -> #DIV/0! | J27: =J23/J21 -> #DIV/0! | ... M27: =M23/M21 -> #DIV/0!

Sheet Sheet4
A1: Column1 | C1: Column1 | E1: Column1 | G1: Column1 | I1: Column1
A2: Normal | C2: YES | E2: Normal | G2: Horizontal | I2: Normal
A3: Expiry | C3: NO | E3: Fear | G3: Vertical | I3: Rangebound
A4: Critical | E4: Careless | G4: Fooling | I4: Volatile
E5: Greed | G5: Spinning

Sheet Strategy
A1: ColA | B1: low | C1: middle | D1: high | E1: Strategy | H1: Stop Loss Followed | K1: Amnt Total | L1: 24000
A2: =B2&C2&D2 -> CallCallCall | B2: Call | C2: Call | D2: Call | E2: Strong Call | H2: Later Trading | K2: In Hand | L2: 5000
A3: =B3&C3&D3 -> CallCallWait | B3: Call | C3: Call | D3: Wait | E3: Turning to Call | H3: Opposite Trading | K3: Avl for Trade | L3: =L1-L2 -> 19000
A4: =B4&C4&D4 -> CallCallPut | B4: Call | C4: Call | D4: Put | E4: Wait | K4: Trade Amnt 1 | L4: =205*75 -> 15375 | M4: =(L4/L3) -> 0.80921053 | N4: Bal | O4: =L3-L4 -> 3625
A5: =B5&C5&D5 -> CallCallStrong Call | B5: Call | C5: Call | D5: Strong Call | E5: Strong Call | K5: Trade Amnt 2
A6: =B6&C6&D6 -> CallCallStrong Put | B6: Call | C6: Call | D6: Strong Put | E6: waiting for call breakout | K6: Trade Amnt 3
A7: =B7&C7&D7 -> CallWaitCall | B7: Call | C7: Wait | D7: Call | E7: Call
A8: =B8&C8&D8 -> CallWaitWait | B8: Call | C8: Wait | D8: Wait | E8: Rangebound
A9: =B9&C9&D9 -> CallWaitPut | B9: Call | C9: Wait | D9: Put | E9: Rangebound
A10: =B10&C10&D10 -> CallWaitStrong Put | B10: Call | C10: Wait | D10: Strong Put | E10: Wait | M10: =K10*L10 -> 0
A11: =B11&C11&D11 -> CallWaitStrong Call | B11: Call | C11: Wait | D11: Strong Call | E11: Call | M11: =K11*L11 -> 0
A12: =B12&C12&D12 -> CallPutCall | B12: Call | C12: Put | D12: Call | E12: Rangebound | M12: =K12*L12 -> 0
A13: =B13&C13&D13 -> CallPutWait | B13: Call | C13: Put | D13: Wait | E13: Rangebound | M13: =K13*L13 -> 0
A14: =B14&C14&D14 -> CallPutPut | B14: Call | C14: Put | D14: Put | E14: Turning to Put | M14: =K14*L14 -> 0
A15: =B15&C15&D15 -> CallPutStrong Put | B15: Call | C15: Put | D15: Strong Put | E15: Strong Put | M15: =K15*L15 -> 0
A16: =B16&C16&D16 -> CallPutStrong Call | B16: Call | C16: Put | D16: Strong Call | E16: Call | K16: =SUM(K10:K15) -> 0 | L16: =M16/K16 -> #DIV/0! | M16: =SUM(M10:M15) -> 0
A17: =B17&C17&D17 -> CallStrong CallCall | B17: Call | C17: Strong Call | D17: Call | E17: Strong Call
A18: =B18&C18&D18 -> CallStrong CallWait | B18: Call | C18: Strong Call | D18: Wait | E18: Call
A19: =B19&C19&D19 -> CallStrong CallPut | B19: Call | C19: Strong Call | D19: Put | E19: Call
A20: =B20&C20&D20 -> CallStrong CallStrong Call | B20: Call | C20: Strong Call | D20: Strong Call | E20: Strong Call | K20: 16.95 | L20: 9.36 | M20: =K20+K20*(L20/100) -> 18.53652 | N20: 5 | O20: =M20+M20*(N20/100) -> 19.463346
A21: =B21&C21&D21 -> CallStrong CallStrong Put | B21: Call | C21: Strong Call | D21: Strong Put | E21: Breakout to Happen | K21: 16.7 | L21: 10.7 | M21: =K21+K21*(L21/100) -> 18.4869 | N21: 5 | O21: =M21+M21*(N21/100) -> 19.411245
A22: =B22&C22&D22 -> CallStrong PutCall | B22: Call | C22: Strong Put | D22: Call | E22: NA
A23: =B23&C23&D23 -> CallStrong PutWait | B23: Call | C23: Strong Put | D23: Wait | E23: NA
A24: =B24&C24&D24 -> CallStrong PutPut | B24: Call | C24: Strong Put | D24: Put | E24: NA
A25: =B25&C25&D25 -> CallStrong PutStrong Call | B25: Call | C25: Strong Put | D25: Strong Call | E25: Breakout to Happen
A26: =B26&C26&D26 -> CallStrong PutStrong Put | B26: Call | C26: Strong Put | D26: Strong Put | E26: Strong Put
A27: =B27&C27&D27 -> WaitCallCall | B27: Wait | C27: Call | D27: Call | E27: Turning to Call
A28: =B28&C28&D28 -> WaitCallWait | B28: Wait | C28: Call | D28: Wait | E28: Wait
A29: =B29&C29&D29 -> WaitCallPut | B29: Wait | C29: Call | D29: Put | E29: Rangebound
A30: =B30&C30&D30 -> WaitCallStrong Call | B30: Wait | C30: Call | D30: Strong Call | E30: Strong Call
A31: =B31&C31&D31 -> WaitCallStrong Put | B31: Wait | C31: Call | D31: Strong Put | E31: Rangebound
A32: =B32&C32&D32 -> WaitWaitCall | B32: Wait | C32: Wait | D32: Call | E32: Rangebound
A33: =B33&C33&D33 -> WaitWaitWait | B33: Wait | C33: Wait | D33: Wait | E33: Rangebound
... A104: =B104&C104&D104 -> Strong PutCallPut | B104: Strong Put | C104: Call | D104: Put | E104: NA
A105: =B105&C105&D105
A106: =B106&C106&D106 -> Strong PutCallStrong Put | B106: Strong Put | C106: Call | D106: Strong Put | E106: Strong Put
A107: =B107&C107&D107 -> Strong PutWaitCall | B107: Strong Put | C107: Wait | D107: Call | E107: NA
A108: =B108&C108&D108 -> Strong PutWaitWait | B108: Strong Put | C108: Wait | D108: Wait | E108: NA
A109: =B109&C109&D109 -> Strong PutWaitPut | B109: Strong Put | C109: Wait | D109: Put | E109: Put
A110: =B110&C110&D110
...
