Workbook

Sheet Details
A1: Trade Date | B1: Contract Descriptor | C1: Exch | D1: Action | E1: Qty | F1: LTP | G1: Price | H1: Value | I1: Order Ref. | J1: Securities Transaction Tax-STT | K1: Transaction Charges | L1: Stamp Duty | M1: SEBI Turnover Charges | N1: Brokerage | O1: Service Tax On Brokerage | P1: Total Charges | Q1: CalYear | R1: CalMonth | S1: FinYear | T1: FinMonth | U1: FinMonth2 | V1: FinPeriod | W1: MonthName | X1: Amount | Y1: Amount1 | Z1: Amount2
A2: 45300 | B2: OPT-NIFFIN-09-Jan-2024-21450-P-E-I | C2: NSE | D2: Sell | E2: 600 | F2: 0 | G2: 51.9 | H2: 31140 | I2: #202401093700019945 | J2: 19 | K2: 15.73 | L2: 0 | M2: 0.03 | N2: 300 | O2: 56.84 | P2: 391.6 | Q2: =YEAR(A2) -> 2024 | R2: =MONTH(A2) -> 1 | S2: =IF(R2<4,Q2-1,Q2) -> 2023 | T2: =IF(R2<4,R2+9,R2-3) -> 10 | U2: =IF(LEN(T2)=1,_xlfn.CONCAT(0,T2),T2) -> 10 | V2: =_xlfn.CONCAT(S2,U2) -> 202310 | W2: =_xlfn.CONCAT(TEXT(A2,"MMM"),"-",MID(Q2,3,2)) -> Jan-24 | X2: =IFERROR(IF(D2="Sell",(H2-P2),-(H2+P2)),0) -> 30748.4 | Y2: =IF(X2>0,X2,"") -> 30748.4 | Z2: =IF(X2<0,X2,"")
A3: 45300 | B3: OPT-NIFFIN-09-Jan-2024-21450-P-E-I | C3: NSE | D3: Buy | E3: 40 | F3: 0 | G3: 17.7 | H3: 708 | I3: #202401093700017300 | J3: 0 | K3: 0.36 | L3: 0 | M3: 0 | N3: 20 | O3: 3.66 | P3: 24.02 | Q3: =YEAR(A3) -> 2024 | R3: =MONTH(A3) -> 1 | S3: =IF(R3<4,Q3-1,Q3) -> 2023 | T3: =IF(R3<4,R3+9,R3-3) -> 10 | U3: =IF(LEN(T3)=1,_xlfn.CONCAT(0,T3),T3) -> 10 | V3: =_xlfn.CONCAT(S3,U3) -> 202310 | W3: =_xlfn.CONCAT(TEXT(A3,"MMM"),"-",MID(Q3,3,2)) -> Jan-24 | X3: =IFERROR(IF(D3="Sell",(H3-P3),-(H3+P3)),0) -> -732.02 | Y3: =IF(X3>0,X3,"") | Z3: =IF(X3<0,X3,"") -> -732.02
A4: 45300 | B4: OPT-NIFFIN-09-Jan-2024-21450-P-E-I | C4: NSE | D4: Buy | E4: 40 | F4: 0 | G4: 21.1 | H4: 844 | I4: #202401093700015973 | J4: 0 | K4: 0.43 | L4: 0 | M4: 0 | N4: 20 | O4: 3.68 | P4: 24.11 | Q4: =YEAR(A4) -> 2024 | R4: =MONTH(A4) -> 1 | S4: =IF(R4<4,Q4-1,Q4) -> 2023 | T4: =IF(R4<4,R4+9,R4-3) -> 10 | U4: =IF(LEN(T4)=1,_xlfn.CONCAT(0,T4),T4) -> 10 | V4: =_xlfn.CONCAT(S4,U4) -> 202310 | W4: =_xlfn.CONCAT(TEXT(A4,"MMM"),"-",MID(Q4,3,2)) -> Jan-24 | X4: =IFERROR(IF(D4="Sell",(H4-P4),-(H4+P4)),0) -> -868.11 | Y4: =IF(X4>0,X4,"") | Z4: =IF(X4<0,X4,"") -> -868.11
A5: 45300 | B5: OPT-NIFFIN-09-Jan-2024-21450-P-E-I | C5: NSE | D5: Buy | E5: 40 | F5: 0 | G5: 23.3 | H5: 932 | I5: #202401093700015743 | J5: 0 | K5: 0.47 | L5: 0 | M5: 0 | N5: 20 | O5: 3.68 | P5: 24.15 | Q5: =YEAR(A5) -> 2024 | R5: =MONTH(A5) -> 1 | S5: =IF(R5<4,Q5-1,Q5) -> 2023 | T5: =IF(R5<4,R5+9,R5-3) -> 10 | U5: =IF(LEN(T5)=1,_xlfn.CONCAT(0,T5),T5) -> 10 | V5: =_xlfn.CONCAT(S5,U5) -> 202310 | W5: =_xlfn.CONCAT(TEXT(A5,"MMM"),"-",MID(Q5,3,2)) -> Jan-24 | X5: =IFERROR(IF(D5="Sell",(H5-P5),-(H5+P5)),0) -> -956.15 | Y5: =IF(X5>0,X5,"") | Z5: =IF(X5<0,X5,"") -> -956.15
A6: 45300 | B6: OPT-NIFFIN-09-Jan-2024-21450-P-E-I | C6: NSE | D6: Buy | E6: 40 | F6: 0 | G6: 22.1 | H6: 884 | I6: #202401093700015658 | J6: 0 | K6: 0.45 | L6: 0 | M6: 0 | N6: 20 | O6: 3.68 | P6: 24.13 | Q6: =YEAR(A6) -> 2024 | R6: =MONTH(A6) -> 1 | S6: =IF(R6<4,Q6-1,Q6) -> 2023 | T6: =IF(R6<4,R6+9,R6-3) -> 10 | U6: =IF(LEN(T6)=1,_xlfn.CONCAT(0,T6),T6) -> 10 | V6: =_xlfn.CONCAT(S6,U6) -> 202310 | W6: =_xlfn.CONCAT(TEXT(A6,"MMM"),"-",MID(Q6,3,2)) -> Jan-24 | X6: =IFERROR(IF(D6="Sell",(H6-P6),-(H6+P6)),0) -> -908.13 | Y6: =IF(X6>0,X6,"") | Z6: =IF(X6<0,X6,"") -> -908.13
A7: 45300 | B7: OPT-NIFFIN-09-Jan-2024-21450-P-E-I | C7: NSE | D7: Buy | E7: 40 | F7: 0 | G7: 23.05 | H7: 922 | I7: #202401093700015607 | J7: 0 | K7: 0.47 | L7: 0 | M7: 0 | N7: 20 | O7: 3.68 | P7: 24.15 | Q7: =YEAR(A7) -> 2024 | R7: =MONTH(A7) -> 1 | S7: =IF(R7<4,Q7-1,Q7) -> 2023 | T7: =IF(R7<4,R7+9,R7-3) -> 10 | U7: =IF(LEN(T7)=1,_xlfn.CONCAT(0,T7),T7) -> 10 | V7: =_xlfn.CONCAT(S7,U7) -> 202310 | W7: =_xlfn.CONCAT(TEXT(A7,"MMM"),"-",MID(Q7,3,2)) -> Jan-24 | X7: =IFERROR(IF(D7="Sell",(H7-P7),-(H7+P7)),0) -> -946.15 | Y7: =IF(X7>0,X7,"") | Z7: =IF(X7<0,X7,"") -> -946.15
A8: 45300 | B8: OPT-NIFFIN-09-Jan-2024-21450-P-E-I | C8: NSE | D8: Buy | E8: 40 | F8: 0 | G8: 28.7 | H8: 1148 | I8: #202401093700014789 | J8: 0 | K8: 0.58 | L8: 0 | M8: 0 | N8: 20 | O8: 3.7 | P8: 24.28 | Q8: =YEAR(A8) -> 2024 | R8: =MONTH(A8) -> 1 | S8: =IF(R8<4,Q8-1,Q8) -> 2023 | T8: =IF(R8<4,R8+9,R8-3) -> 10 | U8: =IF(LEN(T8)=1,_xlfn.CONCAT(0,T8),T8) -> 10 | V8: =_xlfn.CONCAT(S8,U8) -> 202310 | W8: =_xlfn.CONCAT(TEXT(A8,"MMM"),"-",MID(Q8,3,2)) -> Jan-24 | X8: =IFERROR(IF(D8="Sell",(H8-P8),-(H8+P8)),0) -> -1172.28 | Y8: =IF(X8>0,X8,"") | Z8: =IF(X8<0,X8,"") -> -1172.28
A9: 45300 | B9: OPT-NIFFIN-09-Jan-2024-21450-P-E-I | C9: NSE | D9: Buy | E9: 40 | F9: 0 | G9: 26.65 | H9: 1066 | I9: #202401093700014597 | J9: 0 | K9: 0.54 | L9: 0 | M9: 0 | N9: 20 | O9: 3.7 | P9: 24.24 | Q9: =YEAR(A9) -> 2024 | R9: =MONTH(A9) -> 1 | S9: =IF(R9<4,Q9-1,Q9) -> 2023 | T9: =IF(R9<4,R9+9,R9-3) -> 10 | U9: =IF(LEN(T9)=1,_xlfn.CONCAT(0,T9),T9) -> 10 | V9: =_xlfn.CONCAT(S9,U9) -> 202310 | W9: =_xlfn.CONCAT(TEXT(A9,"MMM"),"-",MID(Q9,3,2)) -> Jan-24 | X9: =IFERROR(IF(D9="Sell",(H9-P9),-(H9+P9)),0) -> -1090.24 | Y9: =IF(X9>0,X9,"") | Z9: =IF(X9<0,X9,"") -> -1090.24
A10: 45300 | B10: OPT-NIFFIN-09-Jan-2024-21450-P-E-I | C10: NSE | D10: Buy | E10: 40 | F10: 0 | G10: 29 | H10: 1160 | I10: #202401093700014487 | J10: 0 | K10: 0.59 | L10: 0 | M10: 0 | N10: 20 | O10: 3.7 | P10: 24.29 | Q10: =YEAR(A10) -> 2024 | R10: =MONTH(A10) -> 1 | S10: =IF(R10<4,Q10-1,Q10) -> 2023 | T10: =IF(R10<4,R10+9,R10-3) -> 10 | U10: =IF(LEN(T10)=1,_xlfn.CONCAT(0,T10),T10) -> 10 | V10: =_xlfn.CONCAT(S10,U10) -> 202310 | W10: =_xlfn.CONCAT(TEXT(A10,"MMM"),"-",MID(Q10,3,2)) -> Jan-24 | X10: =IFERROR(IF(D10="Sell",(H10-P10),-(H10+P10)),0) -> -1184.29 | Y10: =IF(X10>0,X10,"") | Z10: =IF(X10<0,X10,"") -> -1184.29
A11: 45300 | B11: OPT-NIFFIN-09-Jan-2024-21450-P-E-I | C11: NSE | D11: Buy | E11: 40 | F11: 0 | G11: 32.6 | H11: 1304 | I11: #202401093700014363 | J11: 0 | K11: 0.66 | L11: 0 | M11: 0 | N11: 20 | O11: 3.72 | P11: 24.38 | Q11: =YEAR(A11) -> 2024 | R11: =MONTH(A11) -> 1 | S11: =IF(R11<4,Q11-1,Q11) -> 2023 | T11: =IF(R11<4,R11+9,R11-3) -> 10 | U11: =IF(LEN(T11)=1,_xlfn.CONCAT(0,T11),T11) -> 10 | V11: =_xlfn.CONCAT(S11,U11) -> 202310 | W11: =_xlfn.CONCAT(TEXT(A11,"MMM"),"-",MID(Q11,3,2)) -> Jan-24 | X11: =IFERROR(IF(D11="Sell",(H11-P11),-(H11+P11)),0) -> -1328.38 | Y11: =IF(X11>0,X11,"") | Z11: =IF(X11<0,X11,"") -> -1328.38
A12: 45300 | B12: OPT-NIFFIN-09-Jan-2024-21450-P-E-I | C12: NSE | D12: Buy | E12: 40 | F12: 0 | G12: 33.85 | H12: 1354 | I12: #202401093700014217 | J12: 0 | K12: 0.68 | L12: 0 | M12: 0 | N12: 20 | O12: 3.72 | P12: 24.4 | Q12: =YEAR(A12) -> 2024 | R12: =MONTH(A12) -> 1 | S12: =IF(R12<4,Q12-1,Q12) -> 2023 | T12: =IF(R12<4,R12+9,R12-3) -> 10 | U12: =IF(LEN(T12)=1,_xlfn.CONCAT(0,T12),T12) -> 10 | V12: =_xlfn.CONCAT(S12,U12) -> 202310 | W12: =_xlfn.CONCAT(TEXT(A12,"MMM"),"-",MID(Q12,3,2)) -> Jan-24 | X12: =IFERROR(IF(D12="Sell",(H12-P12),-(H12+P12)),0) -> -1378.4 | Y12: =IF(X12>0,X12,"") | Z12: =IF(X12<0,X12,"") -> -1378.4
A13: 45300 | B13: OPT-NIFFIN-09-Jan-2024-21450-P-E-I | C13: NSE | D13: Buy | E13: 160 | F13: 0 | G13: 37.15 | H13: 5944 | I13: #202401093700013489 | J13: 0 | K13: 3 | L13: 1 | M13: 0 | N13: 80 | O13: 14.94 | P13: 98.94 | Q13: =YEAR(A13) -> 2024 | R13: =MONTH(A13) -> 1 | S13: =IF(R13<4,Q13-1,Q13) -> 2023 | T13: =IF(R13<4,R13+9,R13-3) -> 10 | U13: =IF(LEN(T13)=1,_xlfn.CONCAT(0,T13),T13) -> 10 | V13: =_xlfn.CONCAT(S13,U13) -> 202310 | W13: =_xlfn.CONCAT(TEXT(A13,"MMM"),"-",MID(Q13,3,2)) -> Jan-24 | X13: =IFERROR(IF(D13="Sell",(H13-P13),-(H13+P13)),0) -> -6042.94 | Y13: =IF(X13>0,X13,"") | Z13: =IF(X13<0,X13,"") -> -6042.94
... A28: 45301 | B28: OPT-CIPLA-25-Jan-2024-1320-C-E-S | C28: NSE | D28: Buy | E28: 650 | F28: 0 | G28: 30.45 | H28: 19792.5 | I28: #202401103700008838 | J28: 0 | K28: 10 | L28: 0.59 | M28: 0.02 | N28: 20 | O28: 5.4 | P28: 36.01 | Q28: =YEAR(A28) -> 2024 | R28: =MONTH(A28) -> 1 | S28: =IF(R28<4,Q28-1,Q28) -> 2023 | T28: =IF(R28<4,R28+9,R28-3) -> 10 | U28: =IF(LEN(T28)=1,_xlfn.CONCAT(0,T28),T28) -> 10 | V28: =_xlfn.CONCAT(S28,U28) -> 202310 | W28: =_xlfn.CONCAT(TEXT(A28,"MMM"),"-",MID(Q28,3,2)) -> Jan-24 | X28: =IFERROR(IF(D28="Sell",(H28-P28),-(H28+P28)),0) -> -19828.51 | Y28: =IF(X28>0,X28,"") | Z28: =IF(X28<0,X28,"") -> -19828.51
A29: 45301 | B29: OPT-CNXBAN-10-Jan-2024-47200-P-E-I | C29: NSE | D29: Buy Closeout | E29: 5010 | F29: 0 | G29: 0 | H29: #Exchange Initiated | I29: 0 | J29: 0 | K29: 0 | L29: 0 | M29: 0 | N29: 0 | O29: 0 | Q29: =YEAR(A29) -> 2024 | R29: =MONTH(A29) -> 1 | S29: =IF(R29<4,Q29-1,Q29) -> 2023 | T29: =IF(R29<4,R29+9,R29-3) -> 10 | U29: =IF(LEN(T29)=1,_xlfn.CONCAT(0,T29),T29) -> 10 | V29: =_xlfn.CONCAT(S29,U29) -> 202310 | W29: =_xlfn.CONCAT(TEXT(A29,"MMM"),"-",MID(Q29,3,2)) -> Jan-24 | X29: =IFERROR(IF(D29="Sell",(H29-P29),-(H29+P29)),0) -> 0 | Y29: =IF(X29>0,X29,"") | Z29: =IF(X29<0,X29,"")
A30: 45302 | B30: OPT-NIFFIN-16-Jan-2024-21200-P-E-I | C30: NSE | D30: Sell | E30: 40 | F30: 0 | G30: 105 | H30: 4200 | I30: #202401113700017478 | J30: 3 | K30: 2.12 | L30: 0 | M30: 0 | N30: 20 | O30: 3.98 | P30: 29.1 | Q30: =YEAR(A30) -> 2024 | R30: =MONTH(A30) -> 1 | S30: =IF(R30<4,Q30-1,Q30) -> 2023 | T30: =IF(R30<4,R30+9,R30-3) -> 10 | U30: =IF(LEN(T30)=1,_xlfn.CONCAT(0,T30),T30) -> 10 | V30: =_xlfn.CONCAT(S30,U30) -> 202310 | W30: =_xlfn.CONCAT(TEXT(A30,"MMM"),"-",MID(Q30,3,2)) -> Jan-24 | X30: =IFERROR(IF(D30="Sell",(H30-P30),-(H30+P30)),0) -> 4170.9 | Y30: =IF(X30>0,X30,"") -> 4170.9 | Z30: =IF(X30<0,X30,"")
A31: 45302 | B31: OPT-NIFFIN-16-Jan-2024-21200-P-E-I | C31: NSE | D31: Buy | E31: 40 | F31: 0 | G31: 75.75 | H31: 3030 | I31: #202401113700017099 | J31: 0 | K31: 1.53 | L31: 0 | M31: 0 | N31: 20 | O31: 3.88 | P31: 25.41 | Q31: =YEAR(A31) -> 2024 | R31: =MONTH(A31) -> 1 | S31: =IF(R31<4,Q31-1,Q31) -> 2023 | T31: =IF(R31<4,R31+9,R31-3) -> 10 | U31: =IF(LEN(T31)=1,_xlfn.CONCAT(0,T31),T31) -> 10 | V31: =_xlfn.CONCAT(S31,U31) -> 202310 | W31: =_xlfn.CONCAT(TEXT(A31,"MMM"),"-",MID(Q31,3,2)) -> Jan-24 | X31: =IFERROR(IF(D31="Sell",(H31-P31),-(H31+P31)),0) -> -3055.41 | Y31: =IF(X31>0,X31,"") | Z31: =IF(X31<0,X31,"") -> -3055.41
A32: 45308 | B32: OPT-CNXBAN-17-Jan-2024-46700-C-E-I | C32: NSE | D32: Sell | E32: 600 | F32: 0 | G32: 16.15 | H32: 9690 | I32: #202401173700021397 | J32: 6.06 | K32: 4.9 | L32: 0 | M32: 0.01 | N32: 800 | O32: 144.88 | P32: 955.85 | Q32: =YEAR(A32) -> 2024 | R32: =MONTH(A32) -> 1 | S32: =IF(R32<4,Q32-1,Q32) -> 2023 | T32: =IF(R32<4,R32+9,R32-3) -> 10 | U32: =IF(LEN(T32)=1,_xlfn.CONCAT(0,T32),T32) -> 10 | V32: =_xlfn.CONCAT(S32,U32) -> 202310 | W32: =_xlfn.CONCAT(TEXT(A32,"MMM"),"-",MID(Q32,3,2)) -> Jan-24 | X32: =IFERROR(IF(D32="Sell",(H32-P32),-(H32+P32)),0) -> 8734.15 | Y32: =IF(X32>0,X32,"") -> 8734.15 | Z32: =IF(X32<0,X32,"")
A33: 45308 | B33: OPT-CNXBAN-17-Jan-2024-46700-C-E-I | C33: NSE | D33: Sell | E33: 900 | F33: 0 | G33: 16.15 | H33: 14535 | I33: #202401173700021119 | J33: 8.95 | K33: 7.34 | L33: 0 | M33: 0.01 | N33: 1200 | O33: 217.32 | P33: 1433.62 | Q33: =YEAR(A33) -> 2024 | R33: =MONTH(A33) -> 1 | S33: =IF(R33<4,Q33-1,Q33) -> 2023 | T33: =IF(R33<4,R33+9,R33-3) -> 10 | U33: =IF(LEN(T33)=1,_xlfn.CONCAT(0,T33),T33) -> 10 | V33: =_xlfn.CONCAT(S33,U33) -> 202310 | W33: =_xlfn.CONCAT(TEXT(A33,"MMM"),"-",MID(Q33,3,2)) -> Jan-24 | X33: =IFERROR(IF(D33="Sell",(H33-P33),-(H33+P33)),0) -> 13101.38 | Y33: =IF(X33>0,X33,"") -> 13101.38 | Z33: =IF(X33<0,X33,"")
A34: 45308 | B34: OPT-CNXBAN-17-Jan-2024-46700-C-E-I | C34: NSE | D34: Buy | E34: 300 | F34: 0 | G34: 31.75 | H34: 9525 | I34: #202401173700018837 | J34: 0 | K34: 4.8 | L34: 0 | M34: 0 | N34: 400 | O34: 72.86 | P34: 477.66 | Q34: =YEAR(A34) -> 2024 | R34: =MONTH(A34) -> 1 | S34: =IF(R34<4,Q34-1,Q34) -> 2023 | T34: =IF(R34<4,R34+9,R34-3) -> 10 | U34: =IF(LEN(T34)=1,_xlfn.CONCAT(0,T34),T34) -> 10 | V34: =_xlfn.CONCAT(S34,U34) -> 202310 | W34: =_xlfn.CONCAT(TEXT(A34,"MMM"),"-",MID(Q34,3,2)) -> Jan-24 | X34: =IFERROR(IF(D34="Sell",(H34-P34),-(H34+P34)),0) -> -10002.66 | Y34: =IF(X34>0,X34,"") | Z34: =IF(X34<0,X34,"") -> -10002.66
A35: 45308 | B35: OPT-CNXBAN-17-Jan-2024-46700-C-E-I | C35: NSE | D35: Buy | E35: 300 | F35: 0 | G35: 40.25 | H35: 12075 | I35: #202401173700017802 | J35: 0 | K35: 6.08 | L35: 0 | M35: 0 | N35: 400 | O35: 73.1 | P35: 479.18 | Q35: =YEAR(A35) -> 2024 | R35: =MONTH(A35) -> 1 | S35: =IF(R35<4,Q35-1,Q35) -> 2023 | T35: =IF(R35<4,R35+9,R35-3) -> 10 | U35: =IF(LEN(T35)=1,_xlfn.CONCAT(0,T35),T35) -> 10 | V35: =_xlfn.CONCAT(S35,U35) -> 202310 | W35: =_xlfn.CONCAT(TEXT(A35,"MMM"),"-",MID(Q35,3,2)) -> Jan-24 | X35: =IFERROR(IF(D35="Sell",(H35-P35),-(H35+P35)),0) -> -12554.18 | Y35: =IF(X35>0,X35,"") | Z35: =IF(X35<0,X35,"") -> -12554.18
A36: 45308 | B36: OPT-CNXBAN-17-Jan-2024-46700-C-E-I | C36: NSE | D36: Buy | E36: 300 | F36: 0 | G36: 49.15 | H36: 14745 | I36: #202401173700016080 | J36: 0 | K36: 7.45 | L36: 2 | M36: 0.01 | N36: 400 | O36: 73.34 | P36: 482.8 | Q36: =YEAR(A36) -> 2024 | R36: =MONTH(A36) -> 1 | S36: =IF(R36<4,Q36-1,Q36) -> 2023 | T36: =IF(R36<4,R36+9,R36-3) -> 10 | U36: =IF(LEN(T36)=1,_xlfn.CONCAT(0,T36),T36) -> 10 | V36: =_xlfn.CONCAT(S36,U36) -> 202310 | W36: =_xlfn.CONCAT(TEXT(A36,"MMM"),"-",MID(Q36,3,2)) -> Jan-24 | X36: =IFERROR(IF(D36="Sell",(H36-P36),-(H36+P36)),0) -> -15227.8 | Y36: =IF(X36>0,X36,"") | Z36: =IF(X36<0,X36,"") -> -15227.8
A37: 45308 | B37: OPT-CNXBAN-17-Jan-2024-46700-C-E-I | C37: NSE | D37: Buy | E37: 150 | F37: 0 | G37: 43.45 | H37: 6517.5 | I37: #202401173700015246 | J37: 0 | K37: 3.29 | L37: 0 | M37: 0.01 | N37: 200 | O37: 36.6 | P37: 239.9 | Q37: =YEAR(A37) -> 2024 | R37: =MONTH(A37) -> 1 | S37: =IF(R37<4,Q37-1,Q37) -> 2023 | T37: =IF(R37<4,R37+9,R37-3) -> 10 | U37: =IF(LEN(T37)=1,_xlfn.CONCAT(0,T37),T37) -> 10 | V37: =_xlfn.CONCAT(S37,U37) -> 202310 | W37: =_xlfn.CONCAT(TEXT(A37,"MMM"),"-",MID(Q37,3,2)) -> Jan-24 | X37: =IFERROR(IF(D37="Sell",(H37-P37),-(H37+P37)),0) -> -6757.4 | Y37: =IF(X37>0,X37,"") | Z37: =IF(X37<0,X37,"") -> -6757.4
A38: 45308 | B38: OPT-CNXBAN-17-Jan-2024-46700-C-E-I | C38: NSE | D38: Buy | E38: 150 | F38: 0 | G38: 52.55 | H38: 7882.5 | I38: #202401173700014614 | J38: 0 | K38: 3.98 | L38: 0 | M38: 0.01 | N38: 200 | O38: 36.72 | P38: 240.71 | Q38: =YEAR(A38) -> 2024 | R38: =MONTH(A38) -> 1 | S38: =IF(R38<4,Q38-1,Q38) -> 2023 | T38: =IF(R38<4,R38+9,R38-3) -> 10 | U38: =IF(LEN(T38)=1,_xlfn.CONCAT(0,T38),T38) -> 10 | V38: =_xlfn.CONCAT(S38,U38) -> 202310 | W38: =_xlfn.CONCAT(TEXT(A38,"MMM"),"-",MID(Q38,3,2)) -> Jan-24 | X38: =IFERROR(IF(D38="Sell",(H38-P38),-(H38+P38)),0) -> -8123.21 | Y38: =IF(X38>0,X38,"") | Z38: =IF(X38<0,X38,"") -> -8123.21
A39: 45308 | B39: OPT-CNXBAN-17-Jan-2024-46700-C-E-I | C39: NSE | D39: Buy | E39: 150 | F39: 0 | G39: 54 | H39: 8100 | I39: #202401173700013513 | J39: 0 | K39: 4.09 | L39: 0 | M39: 0.01 | N39: 200 | O39: 36.74 | P39: 240.84 | Q39: =YEAR(A39) -> 2024 | R39: =MONTH(A39) -> 1 | S39: =IF(R39<4,Q39-1,Q39) -> 2023 | T39: =IF(R39<4,R39+9,R39-3) -> 10 | U39: =IF(LEN(T39)=1,_xlfn.CONCAT(0,T39),T39) -> 10 | V39: =_xlfn.CONCAT(S39,U39) -> 202310 | W39: =_xlfn.CONCAT(TEXT(A39,"MMM"),"-",MID(Q39,3,2)) -> Jan-24 | X39: =IFERROR(IF(D39="Sell",(H39-P39),-(H39+P39)),0) -> -8340.84 | Y39: =IF(X39>0,X39,"") | Z39: =IF(X39<0,X39,"") -> -8340.84
A40: 45308 | B40: OPT-CNXBAN-17-Jan-2024-46700-C-E-I | C40: NSE | D40: Buy | E40: 90 | F40: 0 | G40: 74 | H40: 6660 | I40: #202401173700012803 | J40: 0 | K40: 3.36 | L40: 0 | M40: 0.01 | N40: 120 | O40: 22.2 | P40: 145.57 | Q40: =YEAR(A40) -> 2024 | R40: =MONTH(A40) -> 1 | S40: =IF(R40<4,Q40-1,Q40) -> 2023 | T40: =IF(R40<4,R40+9,R40-3) -> 10 | U40: =IF(LEN(T40)=1,_xlfn.CONCAT(0,T40),T40) -> 10 | V40: =_xlfn.CONCAT(S40,U40) -> 202310 | W40: =_xlfn.CONCAT(TEXT(A40,"MMM"),"-",MID(Q40,3,2)) -> Jan-24 | X40: =IFERROR(IF(D40="Sell",(H40-P40),-(H40+P40)),0) -> -6805.57 | Y40: =IF(X40>0,X40,"") | Z40: =IF(X40<0,X40,"") -> -6805.57
A41: 45308 | B41: OPT-CNXBAN-17-Jan-2024-46700-C-E-I | C41: NSE | D41: Buy | E41: 15 | F41: 0 | G41: 77.75 | H41: 1166.25 | I41: #202401173700012740 | J41: 0 | K41: 0.59 | L41: 0 | M41: 0 | N41: 20 | O41: 3.7 | P41: 24.29 | Q41: =YEAR(A41) -> 2024 | R41: =MONTH(A41) -> 1 | S41: =IF(R41<4,Q41-1,Q41) -> 2023 | T41: =IF(R41<4,R41+9,R41-3) -> 10 | U41: =IF(LEN(T41)=1,_xlfn.CONCAT(0,T41),T41) -> 10 | V41: =_xlfn.CONCAT(S41,U41) -> 202310 | W41: =_xlfn.CONCAT(TEXT(A41,"MMM"),"-",MID(Q41,3,2)) -> Jan-24 | X41: =IFERROR(IF(D41="Sell",(H41-P41),-(H41+P41)),0) -> -1190.54 | Y41: =IF(X41>0,X41,"") | Z41: =IF(X41<0,X41,"") -> -1190.54
... A1406: 46076 | B1406: OPT-NIFTY-24-Feb-2026-25350-P-E-I | C1406: NSE | D1406: Sell | E1406: 650 | F1406: 0 | G1406: 22 | H1406: 14300 | I1406: #202602232700001112 | J1406: 14.59 | K1406: 5.08 | L1406: 0 | M1406: 0.01 | N1406: 290 | O1406: 53.12 | P1406: 362.8 | Q1406: =YEAR(A1406) -> 2026 | R1406: =MONTH(A1406) -> 2 | S1406: =IF(R1406<4,Q1406-1,Q1406) -> 2025 | T1406: =IF(R1406<4,R1406+9,R1406-3) -> 11 | U1406: =IF(LEN(T1406)=1,_xlfn.CONCAT(0,T1406),T1406) -> 11 | V1406: =_xlfn.CONCAT(S1406,U1406) -> 202511 | W1406: =_xlfn.CONCAT(TEXT(A1406,"MMM"),"-",MID(Q1406,3,2)) -> Feb-26 | X1406: =IFERROR(IF(D1406="Sell",(H1406-P1406),-(H1406+P1406)),0) -> 13937.2 | Y1406: =IF(X1406>0,X1406,"") -> 13937.2 | Z1406: =IF(X1406<0,X1406,"")

Sheet Interest
C1: 1 | D1: =0.06*C1 -> 0.06 | E1: =D1/365 -> 0.00016438356 | H1: =SUM(G:G) -> -87414.251 | I1: =H1+E2 -> -1067714.4 | J1: =H1/I1 -> 0.081870444
E2: -980300.13
A3: Years (Trade Date) | B3: Quarters (Trade Date) | C3: Months (Trade Date) | D3: Trade Date | E3: Sum of Amount
A4: <09-01-2024 | B4: <09-01-2024 | C4: <09-01-2024 | D4: (blank)
A5: 2024 | B5: Qtr1 | C5: Jan | D5: 45300 | E5: 12696.87 | F5: =TODAY()-D5 -> 777 | G5: =F5*E5*$E$1 -> 1621.7208
A6: 2024 | B6: Qtr1 | C6: Jan | D6: 45301 | E6: -33965.82 | F6: =TODAY()-D6 -> 776 | G6: =F6*E6*$E$1 -> -4332.7358
A7: 2024 | B7: Qtr1 | C7: Jan | D7: 45302 | E7: 1115.49 | F7: =TODAY()-D7 -> 775 | G7: =F7*E7*$E$1 -> 142.11037
A8: 2024 | B8: Qtr1 | C8: Jan | D8: 45308 | E8: -50948.41 | F8: =TODAY()-D8 -> 769 | G8: =F8*E8*$E$1 -> -6440.4374
A9: 2024 | B9: Qtr1 | C9: Jan | D9: 45309 | E9: 2963.25 | F9: =TODAY()-D9 -> 768 | G9: =F9*E9*$E$1 -> 374.10016
A10: 2024 | B10: Qtr1 | C10: Jan | D10: 45310 | E10: 3294.23 | F10: =TODAY()-D10 -> 767 | G10: =F10*E10*$E$1 -> 415.34374
A11: 2024 | B11: Qtr1 | C11: Jan | D11: 45314 | E11: -6890.41 | F11: =TODAY()-D11 -> 763 | G11: =F11*E11*$E$1 -> -864.22731
A12: 2024 | B12: Qtr1 | C12: Jan | D12: 45315 | E12: 5510.53 | F12: =TODAY()-D12 -> 762 | G12: =F12*E12*$E$1 -> 690.2505
A13: 2024 | B13: Qtr1 | C13: Jan | D13: 45316 | E13: -1637.43 | F13: =TODAY()-D13 -> 761 | G13: =F13*E13*$E$1 -> -204.83576
A14: 2024 | B14: Qtr1 | C14: Jan | D14: 45320 | E14: -1240.35 | F14: =TODAY()-D14 -> 757 | G14: =F14*E14*$E$1 -> -154.34712
A15: 2024 | B15: Qtr1 | C15: Jan | D15: 45321 | E15: -2308.31 | F15: =TODAY()-D15 -> 756 | G15: =F15*E15*$E$1 -> -286.86285
A16: 2024 | B16: Qtr1 | C16: Jan | D16: 45322 | E16: 49106.92 | F16: =TODAY()-D16 -> 755 | G16: =F16*E16*$E$1 -> 6094.6397
... A234: 2026 | B234: Qtr1 | C234: Feb | D234: 46076 | E234: 27968.99 | F234: =TODAY()-D234 -> 1 | G234: =F234*E234*$E$1 -> 4.5976422
A235: Grand Total | E235: -980300.13

Sheet Pivot
A3: Sum of Amount | C3: Action
A4: FinPeriod | B4: MonthName | C4: Buy | D4: Sell | E4: Grand Total | H4: FinPeriod | I4: MonthName | J4: Sum of Amount
A5: 202310 | B5: Jan-24 | C5: -324983.46 | D5: 302680.02 | E5: -22303.44 | H5: 202310 | I5: Jan-24 | J5: -22303.44
A6: 202311 | B6: Feb-24 | C6: -1036200.6 | D6: 800886.88 | E6: -235313.76 | H6: 202311 | I6: Feb-24 | J6: -235313.76
A7: 202312 | B7: Mar-24 | C7: -1259756.9 | D7: 1160105.2 | E7: -99651.71 | H7: 202312 | I7: Mar-24 | J7: -99651.71
A8: 202401 | B8: Apr-24 | C8: -451775.19 | D8: 451274.97 | E8: -500.22 | H8: 202401 | I8: Apr-24 | J8: -500.22
A9: 202402 | B9: May-24 | C9: -334783.49 | D9: 268321.19 | E9: -66462.3 | H9: 202402 | I9: May-24 | J9: -66462.3
A10: 202403 | B10: Jun-24 | C10: -180755.39 | D10: 163476.4 | E10: -17278.99 | H10: 202403 | I10: Jun-24 | J10: -17278.99
A11: 202404 | B11: Jul-24 | C11: -442984.76 | D11: 401049.44 | E11: -41935.32 | H11: 202404 | I11: Jul-24 | J11: -41935.32
A12: 202405 | B12: Aug-24 | C12: -78718.23 | D12: 42678.15 | E12: -36040.08 | H12: 202405 | I12: Aug-24 | J12: -36040.08
A13: 202406 | B13: Sep-24 | C13: -60074.16 | D13: 24702.29 | E13: -35371.87 | H13: 202406 | I13: Sep-24 | J13: -35371.87
A14: 202407 | B14: Oct-24 | C14: -50008.65 | D14: 13433.92 | E14: -36574.73 | H14: 202407 | I14: Oct-24 | J14: -36574.73
A15: 202408 | B15: Nov-24 | C15: -96498.76 | D15: 36606.09 | E15: -59892.67 | H15: 202408 | I15: Nov-24 | J15: -59892.67
A16: 202409 | B16: Dec-24 | C16: -1137513.8 | D16: 1021640.7 | E16: -115873.07 | H16: 202409 | I16: Dec-24 | J16: -115873.07
... A29: 202511 | B29: Feb-26 | C29: -588485.74 | D29: 581196.28 | E29: -7289.46 | H29: 202511 | I29: Feb-26 | J29: -7289.46
A30: Grand Total | C30: -9783100.1 | D30: 8802800 | E30: -980300.13 | H30: Grand Total | J30: -980300.13

Sheet ICICI
A1: Slno | B1: Date | C1: Lot | D1: Amnt | E1: Rule | F1: Candle | G1: RSI | H1: P SAR | I1: Remarks | L1: Total | M1: =SUM(D:D) -> -2625 | P1: Qty | Q1: Price | R1: Value
A2: 1 | B2: 45644 | C2: 3 | D2: 4620 | E2: Follwed | F2: First Green above MA | G2: >50 | H2: Below Candle | P2: 700 | Q2: 14.25 | R2: =P2*Q2 -> 9975
A3: 2 | B3: 45645 | C3: 3 | D3: 3570 | E3: Follwed | F3: First Green above MA | G3: >50 | H3: Below Candle | P3: 1400 | Q3: 14.7 | R3: =P3*Q3 -> 20580 | T3: =16.25-14.55 -> 1.7 | U3: =2100*T3 -> 3570
A4: 3 | B4: 45649 | C4: 5 | D4: -10815 | E4: Not Follwed | F4: 16th Red above MA | G4: <50 | H4: Above Candle | I4: Blind Thought of Trend Reversal | P4: =SUM(P2:P3) -> 2100 | Q4: =R4/P4 -> 14.55 | R4: =SUM(R2:R3) -> 30555
A5: 4
A6: 5
A7: 6
A8: 7
A9: 8
A10: 9
A11: 10
A12: 11
A13: 12
A14: 13
A15: 14
A16: 15
... A1001: 1000

Sheet Others
A1: Slno | B1: Scrip | C1: Date | D1: Lot | E1: Amnt | F1: Remarks | I1: Total | J1: =SUM(E:E) -> 3330
A2: 1 | B2: LTIM | C2: 45645 | D2: 4 | E2: 3330 | F2: Rule Follwed, Good
A3: 2
A4: 3
A5: 4
A6: 5
A7: 6
A8: 7
A9: 8
A10: 9
A11: 10
A12: 11
A13: 12
A14: 13
... A1001: 1000

Sheet OI Trend
A1: 24900 | B1: call OI | C1: Put OI | D1: Diff | E1: Go with | G1: =A1+50 -> 24950 | H1: call OI | I1: Put OI | J1: Diff | K1: Go with | M1: =G1+50 -> 25000 | N1: call OI | O1: Put OI | P1: Diff | Q1: Go with | S1: Outcome
A2: 9.2 | B2: 50 | C2: 86 | D2: =C2-B2 -> 36 | E2: =IF(D2>=15,"Strong Call",IF(D2>5,"Call",IF(D2>=-5,"Wait",IF(D2>=-15,"Put","Strong Put")))) -> Strong Call | G2: 9.2 | H2: 32 | I2: 66 | J2: =I2-H2 -> 34 | K2: =IF(J2>=15,"Strong Call",IF(J2>5,"Call",IF(J2>=-5,"Wait",IF(J2>=-15,"Put","Strong Put")))) -> Strong Call | M2: 9.2 | N2: 107 | O2: 109 | P2: =O2-N2 -> 2 | Q2: =IF(P2>=15,"Strong Call",IF(P2>5,"Call",IF(P2>=-5,"Wait",IF(P2>=-15,"Put","Strong Put")))) -> Wait | R2: =E2&K2&Q2 -> Strong CallStrong CallWait | S2: =VLOOKUP(R2,Strategy!A:E,5,0) -> Strong Call
A3: 9.3 | B3: 44 | C3: 96 | D3: =C3-B3 -> 52 | E3: =IF(D3>=15,"Strong Call",IF(D3>5,"Call",IF(D3>=-5,"Wait",IF(D3>=-15,"Put","Strong Put")))) -> Strong Call | G3: 9.3 | H3: 26 | I3: 78 | J3: =I3-H3 -> 52 | K3: =IF(J3>=15,"Strong Call",IF(J3>5,"Call",IF(J3>=-5,"Wait",IF(J3>=-15,"Put","Strong Put")))) -> Strong Call | M3: 9.3 | N3: 103 | O3: 136 | P3: =O3-N3 -> 33 | Q3: =IF(P3>=15,"Strong Call",IF(P3>5,"Call",IF(P3>=-5,"Wait",IF(P3>=-15,"Put","Strong Put")))) -> Strong Call | R3: =E3&K3&Q3 -> Strong CallStrong CallStrong Call | S3: =VLOOKUP(R3,Strategy!A:E,5,0) -> Strong Call
A4: 9.45 | B4: 39 | C4: 69 | D4: =C4-B4 -> 30 | E4: =IF(D4>=15,"Strong Call",IF(D4>5,"Call",IF(D4>=-5,"Wait",IF(D4>=-15,"Put","Strong Put")))) -> Strong Call | G4: 9.45 | H4: 25 | I4: 84 | J4: =I4-H4 -> 59 | K4: =IF(J4>=15,"Strong Call",IF(J4>5,"Call",IF(J4>=-5,"Wait",IF(J4>=-15,"Put","Strong Put")))) -> Strong Call | M4: 9.45 | N4: 107 | O4: 166 | P4: =O4-N4 -> 59 | Q4: =IF(P4>=15,"Strong Call",IF(P4>5,"Call",IF(P4>=-5,"Wait",IF(P4>=-15,"Put","Strong Put")))) -> Strong Call | R4: =E4&K4&Q4 -> Strong CallStrong CallStrong Call | S4: =VLOOKUP(R4,Strategy!A:E,5,0) -> Strong Call | T4: Continous Strong Put/Call implies Rangebound Trade
A5: 9.55 | B5: 38 | C5: 107 | D5: =C5-B5 -> 69 | E5: =IF(D5>=15,"Strong Call",IF(D5>5,"Call",IF(D5>=-5,"Wait",IF(D5>=-15,"Put","Strong Put")))) -> Strong Call | G5: 9.55 | H5: 23 | I5: 83 | J5: =I5-H5 -> 60 | K5: =IF(J5>=15,"Strong Call",IF(J5>5,"Call",IF(J5>=-5,"Wait",IF(J5>=-15,"Put","Strong Put")))) -> Strong Call | M5: 9.55 | N5: 110 | O5: 173 | P5: =O5-N5 -> 63 | Q5: =IF(P5>=15,"Strong Call",IF(P5>5,"Call",IF(P5>=-5,"Wait",IF(P5>=-15,"Put","Strong Put")))) -> Strong Call | R5: =E5&K5&Q5 -> Strong CallStrong CallStrong Call | S5: =VLOOKUP(R5,Strategy!A:E,5,0) -> Strong Call
A6: 10.05 | B6: 40 | C6: 109 | D6: =C6-B6 -> 69 | E6: =IF(D6>=15,"Strong Call",IF(D6>5,"Call",IF(D6>=-5,"Wait",IF(D6>=-15,"Put","Strong Put")))) -> Strong Call | G6: 10.05 | H6: 26 | I6: 86 | J6: =I6-H6 -> 60 | K6: =IF(J6>=15,"Strong Call",IF(J6>5,"Call",IF(J6>=-5,"Wait",IF(J6>=-15,"Put","Strong Put")))) -> Strong Call | M6: 10.05 | N6: 124 | O6: 177 | P6: =O6-N6 -> 53 | Q6: =IF(P6>=15,"Strong Call",IF(P6>5,"Call",IF(P6>=-5,"Wait",IF(P6>=-15,"Put","Strong Put")))) -> Strong Call | R6: =E6&K6&Q6 -> Strong CallStrong CallStrong Call | S6: =VLOOKUP(R6,Strategy!A:E,5,0) -> Strong Call
A7: 10.25 | D7: =C7-B7 -> 0 | E7: =IF(D7>=15,"Strong Call",IF(D7>5,"Call",IF(D7>=-5,"Wait",IF(D7>=-15,"Put","Strong Put")))) -> Wait | G7: 10.25 | J7: =I7-H7 -> 0 | K7: =IF(J7>=15,"Strong Call",IF(J7>5,"Call",IF(J7>=-5,"Wait",IF(J7>=-15,"Put","Strong Put")))) -> Wait | M7: 10.25 | P7: =O7-N7 -> 0 | Q7: =IF(P7>=15,"Strong Call",IF(P7>5,"Call",IF(P7>=-5,"Wait",IF(P7>=-15,"Put","Strong Put")))) -> Wait | R7: =E7&K7&Q7 -> WaitWaitWait | S7: =VLOOKUP(R7,Strategy!A:E,5,0) -> Rangebound
A8: 10.4 | D8: =C8-B8 -> 0 | E8: =IF(D8>=15,"Strong Call",IF(D8>5,"Call",IF(D8>=-5,"Wait",IF(D8>=-15,"Put","Strong Put")))) -> Wait | G8: 10.4 | J8: =I8-H8 -> 0 | K8: =IF(J8>=15,"Strong Call",IF(J8>5,"Call",IF(J8>=-5,"Wait",IF(J8>=-15,"Put","Strong Put")))) -> Wait | M8: 10.4 | P8: =O8-N8 -> 0 | Q8: =IF(P8>=15,"Strong Call",IF(P8>5,"Call",IF(P8>=-5,"Wait",IF(P8>=-15,"Put","Strong Put")))) -> Wait | R8: =E8&K8&Q8 -> WaitWaitWait | S8: =VLOOKUP(R8,Strategy!A:E,5,0) -> Rangebound
A9: 10.55 | D9: =C9-B9 -> 0 | E9: =IF(D9>=15,"Strong Call",IF(D9>5,"Call",IF(D9>=-5,"Wait",IF(D9>=-15,"Put","Strong Put")))) -> Wait | G9: 10.55 | J9: =I9-H9 -> 0 | K9: =IF(J9>=15,"Strong Call",IF(J9>5,"Call",IF(J9>=-5,"Wait",IF(J9>=-15,"Put","Strong Put")))) -> Wait | M9: 10.55 | P9: =O9-N9 -> 0 | Q9: =IF(P9>=15,"Strong Call",IF(P9>5,"Call",IF(P9>=-5,"Wait",IF(P9>=-15,"Put","Strong Put")))) -> Wait | R9: =E9&K9&Q9 -> WaitWaitWait | S9: =VLOOKUP(R9,Strategy!A:E,5,0) -> Rangebound
A10: 11.05 | D10: =C10-B10 -> 0 | E10: =IF(D10>=15,"Strong Call",IF(D10>5,"Call",IF(D10>=-5,"Wait",IF(D10>=-15,"Put","Strong Put")))) -> Wait | G10: 11.05 | J10: =I10-H10 -> 0 | K10: =IF(J10>=15,"Strong Call",IF(J10>5,"Call",IF(J10>=-5,"Wait",IF(J10>=-15,"Put","Strong Put")))) -> Wait | M10: 11.05 | P10: =O10-N10 -> 0 | Q10: =IF(P10>=15,"Strong Call",IF(P10>5,"Call",IF(P10>=-5,"Wait",IF(P10>=-15,"Put","Strong Put")))) -> Wait | R10: =E10&K10&Q10 -> WaitWaitWait | S10: =VLOOKUP(R10,Strategy!A:E,5,0) -> Rangebound
A11: 11.25 | D11: =C11-B11 -> 0 | E11: =IF(D11>=15,"Strong Call",IF(D11>5,"Call",IF(D11>=-5,"Wait",IF(D11>=-15,"Put","Strong Put")))) -> Wait | G11: 11.25 | J11: =I11-H11 -> 0 | K11: =IF(J11>=15,"Strong Call",IF(J11>5,"Call",IF(J11>=-5,"Wait",IF(J11>=-15,"Put","Strong Put")))) -> Wait | M11: 11.25 | P11: =O11-N11 -> 0 | Q11: =IF(P11>=15,"Strong Call",IF(P11>5,"Call",IF(P11>=-5,"Wait",IF(P11>=-15,"Put","Strong Put")))) -> Wait | R11: =E11&K11&Q11 -> WaitWaitWait | S11: =VLOOKUP(R11,Strategy!A:E,5,0) -> Rangebound
A12: 11.35 | D12: =C12-B12 -> 0 | E12: =IF(D12>=15,"Strong Call",IF(D12>5,"Call",IF(D12>=-5,"Wait",IF(D12>=-15,"Put","Strong Put")))) -> Wait | G12: 11.35 | J12: =I12-H12 -> 0 | K12: =IF(J12>=15,"Strong Call",IF(J12>5,"Call",IF(J12>=-5,"Wait",IF(J12>=-15,"Put","Strong Put")))) -> Wait | M12: 11.35 | P12: =O12-N12 -> 0 | Q12: =IF(P12>=15,"Strong Call",IF(P12>5,"Call",IF(P12>=-5,"Wait",IF(P12>=-15,"Put","Strong Put")))) -> Wait | R12: =E12&K12&Q12 -> WaitWaitWait | S12: =VLOOKUP(R12,Strategy!A:E,5,0) -> Rangebound
A13: 12.25 | D13: =C13-B13 -> 0 | E13: =IF(D13>=15,"Strong Call",IF(D13>5,"Call",IF(D13>=-5,"Wait",IF(D13>=-15,"Put","Strong Put")))) -> Wait | G13: 12.25 | J13: =I13-H13 -> 0 | K13: =IF(J13>=15,"Strong Call",IF(J13>5,"Call",IF(J13>=-5,"Wait",IF(J13>=-15,"Put","Strong Put")))) -> Wait | M13: 12.25 | P13: =O13-N13 -> 0 | Q13: =IF(P13>=15,"Strong Call",IF(P13>5,"Call",IF(P13>=-5,"Wait",IF(P13>=-15,"Put","Strong Put")))) -> Wait | R13: =E13&K13&Q13 -> WaitWaitWait | S13: =VLOOKUP(R13,Strategy!A:E,5,0) -> Rangebound
A14: 1.25 | D14: =C14-B14 -> 0 | E14: =IF(D14>=15,"Strong Call",IF(D14>5,"Call",IF(D14>=-5,"Wait",IF(D14>=-15,"Put","Strong Put")))) -> Wait | G14: 1.25 | J14: =I14-H14 -> 0 | K14: =IF(J14>=15,"Strong Call",IF(J14>5,"Call",IF(J14>=-5,"Wait",IF(J14>=-15,"Put","Strong Put")))) -> Wait | M14: 1.25 | P14: =O14-N14 -> 0 | Q14: =IF(P14>=15,"Strong Call",IF(P14>5,"Call",IF(P14>=-5,"Wait",IF(P14>=-15,"Put","Strong Put")))) -> Wait | R14: =E14&K14&Q14 -> WaitWaitWait | S14: =VLOOKUP(R14,Strategy!A:E,5,0) -> Rangebound
A15: 2.15 | D15: =C15-B15 -> 0 | E15: =IF(D15>=15,"Strong Call",IF(D15>5,"Call",IF(D15>=-5,"Wait",IF(D15>=-15,"Put","Strong Put")))) -> Wait | G15: 2.15 | J15: =I15-H15 -> 0 | K15: =IF(J15>=15,"Strong Call",IF(J15>5,"Call",IF(J15>=-5,"Wait",IF(J15>=-15,"Put","Strong Put")))) -> Wait | M15: 2.15 | P15: =O15-N15 -> 0 | Q15: =IF(P15>=15,"Strong Call",IF(P15>5,"Call",IF(P15>=-5,"Wait",IF(P15>=-15,"Put","Strong Put")))) -> Wait | R15: =E15&K15&Q15 -> WaitWaitWait | S15: =VLOOKUP(R15,Strategy!A:E,5,0) -> Rangebound

Sheet PV Analysis
A1: 5200 | I1: 5400 | Q1: Qty | R1: Price | S1: Buy Value | T1: Current | U1: P/L
A2: Call | E2: Put | I2: Call | M2: Put | Q2: 100 | R2: 9 | S2: =100*R2 -> 900 | T2: 7.9
A3: Time | B3: OI | C3: Price | D3: Remarks | E3: Time | F3: OI | G3: Price | H3: Remarks | I3: Time | J3: OI | K3: Price | L3: Remarks | M3: Time | N3: OI | O3: Price | P3: Remarks | Q3: 50 | R3: 7 | S3: =100*R3 -> 700
A4: 5 | B4: 4691 | C4: 105 | E4: 5 | F4: 11265 | G4: 9 | I4: 5 | J4: 13512 | K4: 6.7 | M4: 5 | N4: 6629 | O4: 104 | S4: =100*R4 -> 0
A5: 5.15 | B5: 4598 | C5: 106 | D5: =IF(ISBLANK(B5),"",IF(AND(B5>B4,C5>C4),"Long Buildup",IF(AND(B5>B4,C5<C4),"Short Buildup",IF(AND(B5<B4,C5>C4),"Short Covering",IF(AND(B5<B4,C5<C4),"Long Unwinding"))))) -> Short Covering | E5: 5.15 | F5: 11228 | G5: 8.7 | H5: =IF(ISBLANK(F5),"",IF(AND(F5>F4,G5>G4),"Long Buildup",IF(AND(F5>F4,G5<G4),"Short Buildup",IF(AND(F5<F4,G5>G4),"Short Covering",IF(AND(F5<F4,G5<G4),"Long Unwinding"))))) -> Long Unwinding | I5: 5.15 | J5: 13531 | K5: 6.4 | L5: =IF(ISBLANK(J5),"",IF(AND(J5>J4,K5>K4),"Long Buildup",IF(AND(J5>J4,K5<K4),"Short Buildup",IF(AND(J5<J4,K5>K4),"Short Covering",IF(AND(J5<J4,K5<K4),"Long Unwinding"))))) -> Short Buildup | M5: 5.15 | N5: 6559 | O5: 107 | P5: =IF(ISBLANK(N5),"",IF(AND(N5>N4,O5>O4),"Long Buildup",IF(AND(N5>N4,O5<O4),"Short Buildup",IF(AND(N5<N4,O5>O4),"Short Covering",IF(AND(N5<N4,O5<O4),"Long Unwinding"))))) -> Short Covering | S5: =100*R5 -> 0
A6: 5.3 | B6: 4599 | C6: 112 | D6: =IF(ISBLANK(B6),"",IF(AND(B6>B5,C6>C5),"Long Buildup",IF(AND(B6>B5,C6<C5),"Short Buildup",IF(AND(B6<B5,C6>C5),"Short Covering",IF(AND(B6<B5,C6<C5),"Long Unwinding"))))) -> Long Buildup | E6: 5.3 | F6: 11300 | G6: 7.9 | H6: =IF(ISBLANK(F6),"",IF(AND(F6>F5,G6>G5),"Long Buildup",IF(AND(F6>F5,G6<G5),"Short Buildup",IF(AND(F6<F5,G6>G5),"Short Covering",IF(AND(F6<F5,G6<G5),"Long Unwinding"))))) -> Short Buildup | I6: 5.3 | J6: 13791 | K6: 6 | L6: =IF(ISBLANK(J6),"",IF(AND(J6>J5,K6>K5),"Long Buildup",IF(AND(J6>J5,K6<K5),"Short Buildup",IF(AND(J6<J5,K6>K5),"Short Covering",IF(AND(J6<J5,K6<K5),"Long Unwinding"))))) -> Short Buildup | M6: 5.3 | N6: 6554 | O6: 108 | P6: =IF(ISBLANK(N6),"",IF(AND(N6>N5,O6>O5),"Long Buildup",IF(AND(N6>N5,O6<O5),"Short Buildup",IF(AND(N6<N5,O6>O5),"Short Covering",IF(AND(N6<N5,O6<O5),"Long Unwinding"))))) -> Short Covering | Q6: =SUM(Q2:Q5) -> 150 | R6: =S6/Q6 -> 10.666667 | S6: =SUM(S2:S5) -> 1600
A7: 5.45 | B7: 4678 | C7: 106 | D7: =IF(ISBLANK(B7),"",IF(AND(B7>B6,C7>C6),"Long Buildup",IF(AND(B7>B6,C7<C6),"Short Buildup",IF(AND(B7<B6,C7>C6),"Short Covering",IF(AND(B7<B6,C7<C6),"Long Unwinding"))))) -> Short Buildup | E7: 5.45 | F7: 11282 | G7: 8.7 | H7: =IF(ISBLANK(F7),"",IF(AND(F7>F6,G7>G6),"Long Buildup",IF(AND(F7>F6,G7<G6),"Short Buildup",IF(AND(F7<F6,G7>G6),"Short Covering",IF(AND(F7<F6,G7<G6),"Long Unwinding"))))) -> Short Covering | I7: 5.45 | J7: 13802 | K7: 5.9 | L7: =IF(ISBLANK(J7),"",IF(AND(J7>J6,K7>K6),"Long Buildup",IF(AND(J7>J6,K7<K6),"Short Buildup",IF(AND(J7<J6,K7>K6),"Short Covering",IF(AND(J7<J6,K7<K6),"Long Unwinding"))))) -> Short Buildup | M7: 5.45 | N7: 6659 | O7: 105 | P7: =IF(ISBLANK(N7),"",IF(AND(N7>N6,O7>O6),"Long Buildup",IF(AND(N7>N6,O7<O6),"Short Buildup",IF(AND(N7<N6,O7>O6),"Short Covering",IF(AND(N7<N6,O7<O6),"Long Unwinding"))))) -> Short Buildup
A8: 6 | D8: =IF(ISBLANK(B8),"",IF(AND(B8>B7,C8>C7),"Long Buildup",IF(AND(B8>B7,C8<C7),"Short Buildup",IF(AND(B8<B7,C8>C7),"Short Covering",IF(AND(B8<B7,C8<C7),"Long Unwinding"))))) | E8: 6 | H8: =IF(ISBLANK(F8),"",IF(AND(F8>F7,G8>G7),"Long Buildup",IF(AND(F8>F7,G8<G7),"Short Buildup",IF(AND(F8<F7,G8>G7),"Short Covering",IF(AND(F8<F7,G8<G7),"Long Unwinding"))))) | I8: 6 | L8: =IF(ISBLANK(J8),"",IF(AND(J8>J7,K8>K7),"Long Buildup",IF(AND(J8>J7,K8<K7),"Short Buildup",IF(AND(J8<J7,K8>K7),"Short Covering",IF(AND(J8<J7,K8<K7),"Long Unwinding"))))) | M8: 6 | P8: =IF(ISBLANK(N8),"",IF(AND(N8>N7,O8>O7),"Long Buildup",IF(AND(N8>N7,O8<O7),"Short Buildup",IF(AND(N8<N7,O8>O7),"Short Covering",IF(AND(N8<N7,O8<O7),"Long Unwinding")))))
A9: 6.15 | D9: =IF(ISBLANK(B9),"",IF(AND(B9>B8,C9>C8),"Long Buildup",IF(AND(B9>B8,C9<C8),"Short Buildup",IF(AND(B9<B8,C9>C8),"Short Covering",IF(AND(B9<B8,C9<C8),"Long Unwinding"))))) | E9: 6.15 | H9: =IF(ISBLANK(F9),"",IF(AND(F9>F8,G9>G8),"Long Buildup",IF(AND(F9>F8,G9<G8),"Short Buildup",IF(AND(F9<F8,G9>G8),"Short Covering",IF(AND(F9<F8,G9<G8),"Long Unwinding"))))) | I9: 6.15 | L9: =IF(ISBLANK(J9),"",IF(AND(J9>J8,K9>K8),"Long Buildup",IF(AND(J9>J8,K9<K8),"Short Buildup",IF(AND(J9<J8,K9>K8),"Short Covering",IF(AND(J9<J8,K9<K8),"Long Unwinding"))))) | M9: 6.15 | P9: =IF(ISBLANK(N9),"",IF(AND(N9>N8,O9>O8),"Long Buildup",IF(AND(N9>N8,O9<O8),"Short Buildup",IF(AND(N9<N8,O9>O8),"Short Covering",IF(AND(N9<N8,O9<O8),"Long Unwinding")))))
A10: 6.3 | D10: =IF(ISBLANK(B10),"",IF(AND(B10>B9,C10>C9),"Long Buildup",IF(AND(B10>B9,C10<C9),"Short Buildup",IF(AND(B10<B9,C10>C9),"Short Covering",IF(AND(B10<B9,C10<C9),"Long Unwinding"))))) | E10: 6.3 | H10: =IF(ISBLANK(F10),"",IF(AND(F10>F9,G10>G9),"Long Buildup",IF(AND(F10>F9,G10<G9),"Short Buildup",IF(AND(F10<F9,G10>G9),"Short Covering",IF(AND(F10<F9,G10<G9),"Long Unwinding"))))) | I10: 6.3 | L10: =IF(ISBLANK(J10),"",IF(AND(J10>J9,K10>K9),"Long Buildup",IF(AND(J10>J9,K10<K9),"Short Buildup",IF(AND(J10<J9,K10>K9),"Short Covering",IF(AND(J10<J9,K10<K9),"Long Unwinding"))))) | M10: 6.3 | P10: =IF(ISBLANK(N10),"",IF(AND(N10>N9,O10>O9),"Long Buildup",IF(AND(N10>N9,O10<O9),"Short Buildup",IF(AND(N10<N9,O10>O9),"Short Covering",IF(AND(N10<N9,O10<O9),"Long Unwinding")))))
D11: =IF(ISBLANK(B11),"",IF(AND(B11>B10,C11>C10),"Long Buildup",IF(AND(B11>B10,C11<C10),"Short Buildup",IF(AND(B11<B10,C11>C10),"Short Covering",IF(AND(B11<B10,C11<C10),"Long Unwinding"))))) | H11: =IF(ISBLANK(F11),"",IF(AND(F11>F10,G11>G10),"Long Buildup",IF(AND(F11>F10,G11<G10),"Short Buildup",IF(AND(F11<F10,G11>G10),"Short Covering",IF(AND(F11<F10,G11<G10),"Long Unwinding"))))) | L11: =IF(ISBLANK(J11),"",IF(AND(J11>J10,K11>K10),"Long Buildup",IF(AND(J11>J10,K11<K10),"Short Buildup",IF(AND(J11<J10,K11>K10),"Short Covering",IF(AND(J11<J10,K11<K10),"Long Unwinding"))))) | P11: =IF(ISBLANK(N11),"",IF(AND(N11>N10,O11>O10),"Long Buildup",IF(AND(N11>N10,O11<O10),"Short Buildup",IF(AND(N11<N10,O11>O10),"Short Covering",IF(AND(N11<N10,O11<O10),"Long Unwinding")))))
D12: =IF(ISBLANK(B12),"",IF(AND(B12>B11,C12>C11),"Long Buildup",IF(AND(B12>B11,C12<C11),"Short Buildup",IF(AND(B12<B11,C12>C11),"Short Covering",IF(AND(B12<B11,C12<C11),"Long Unwinding"))))) | H12: =IF(ISBLANK(F12),"",IF(AND(F12>F11,G12>G11),"Long Buildup",IF(AND(F12>F11,G12<G11),"Short Buildup",IF(AND(F12<F11,G12>G11),"Short Covering",IF(AND(F12<F11,G12<G11),"Long Unwinding"))))) | L12: =IF(ISBLANK(J12),"",IF(AND(J12>J11,K12>K11),"Long Buildup",IF(AND(J12>J11,K12<K11),"Short Buildup",IF(AND(J12<J11,K12>K11),"Short Covering",IF(AND(J12<J11,K12<K11),"Long Unwinding"))))) | P12: =IF(ISBLANK(N12),"",IF(AND(N12>N11,O12>O11),"Long Buildup",IF(AND(N12>N11,O12<O11),"Short Buildup",IF(AND(N12<N11,O12>O11),"Short Covering",IF(AND(N12<N11,O12<O11),"Long Unwinding")))))
D13: =IF(ISBLANK(B13),"",IF(AND(B13>B12,C13>C12),"Long Buildup",IF(AND(B13>B12,C13<C12),"Short Buildup",IF(AND(B13<B12,C13>C12),"Short Covering",IF(AND(B13<B12,C13<C12),"Long Unwinding"))))) | H13: =IF(ISBLANK(F13),"",IF(AND(F13>F12,G13>G12),"Long Buildup",IF(AND(F13>F12,G13<G12),"Short Buildup",IF(AND(F13<F12,G13>G12),"Short Covering",IF(AND(F13<F12,G13<G12),"Long Unwinding"))))) | L13: =IF(ISBLANK(J13),"",IF(AND(J13>J12,K13>K12),"Long Buildup",IF(AND(J13>J12,K13<K12),"Short Buildup",IF(AND(J13<J12,K13>K12),"Short Covering",IF(AND(J13<J12,K13<K12),"Long Unwinding"))))) | P13: =IF(ISBLANK(N13),"",IF(AND(N13>N12,O13>O12),"Long Buildup",IF(AND(N13>N12,O13<O12),"Short Buildup",IF(AND(N13<N12,O13>O12),"Short Covering",IF(AND(N13<N12,O13<O12),"Long Unwinding")))))
D14: =IF(ISBLANK(B14),"",IF(AND(B14>B13,C14>C13),"Long Buildup",IF(AND(B14>B13,C14<C13),"Short Buildup",IF(AND(B14<B13,C14>C13),"Short Covering",IF(AND(B14<B13,C14<C13),"Long Unwinding"))))) | H14: =IF(ISBLANK(F14),"",IF(AND(F14>F13,G14>G13),"Long Buildup",IF(AND(F14>F13,G14<G13),"Short Buildup",IF(AND(F14<F13,G14>G13),"Short Covering",IF(AND(F14<F13,G14<G13),"Long Unwinding"))))) | L14: =IF(ISBLANK(J14),"",IF(AND(J14>J13,K14>K13),"Long Buildup",IF(AND(J14>J13,K14<K13),"Short Buildup",IF(AND(J14<J13,K14>K13),"Short Covering",IF(AND(J14<J13,K14<K13),"Long Unwinding"))))) | P14: =IF(ISBLANK(N14),"",IF(AND(N14>N13,O14>O13),"Long Buildup",IF(AND(N14>N13,O14<O13),"Short Buildup",IF(AND(N14<N13,O14>O13),"Short Covering",IF(AND(N14<N13,O14<O13),"Long Unwinding")))))
D15: =IF(ISBLANK(B15),"",IF(AND(B15>B14,C15>C14),"Long Buildup",IF(AND(B15>B14,C15<C14),"Short Buildup",IF(AND(B15<B14,C15>C14),"Short Covering",IF(AND(B15<B14,C15<C14),"Long Unwinding"))))) | H15: =IF(ISBLANK(F15),"",IF(AND(F15>F14,G15>G14),"Long Buildup",IF(AND(F15>F14,G15<G14),"Short Buildup",IF(AND(F15<F14,G15>G14),"Short Covering",IF(AND(F15<F14,G15<G14),"Long Unwinding"))))) | L15: =IF(ISBLANK(J15),"",IF(AND(J15>J14,K15>K14),"Long Buildup",IF(AND(J15>J14,K15<K14),"Short Buildup",IF(AND(J15<J14,K15>K14),"Short Covering",IF(AND(J15<J14,K15<K14),"Long Unwinding"))))) | P15: =IF(ISBLANK(N15),"",IF(AND(N15>N14,O15>O14),"Long Buildup",IF(AND(N15>N14,O15<O14),"Short Buildup",IF(AND(N15<N14,O15>O14),"Short Covering",IF(AND(N15<N14,O15<O14),"Long Unwinding")))))
D16: =IF(ISBLANK(B16),"",IF(AND(B16>B15,C16>C15),"Long Buildup",IF(AND(B16>B15,C16<C15),"Short Buildup",IF(AND(B16<B15,C16>C15),"Short Covering",IF(AND(B16<B15,C16<C15),"Long Unwinding"))))) | H16: =IF(ISBLANK(F16),"",IF(AND(F16>F15,G16>G15),"Long Buildup",IF(AND(F16>F15,G16<G15),"Short Buildup",IF(AND(F16<F15,G16>G15),"Short Covering",IF(AND(F16<F15,G16<G15),"Long Unwinding"))))) | L16: =IF(ISBLANK(J16),"",IF(AND(J16>J15,K16>K15),"Long Buildup",IF(AND(J16>J15,K16<K15),"Short Buildup",IF(AND(J16<J15,K16>K15),"Short Covering",IF(AND(J16<J15,K16<K15),"Long Unwinding"))))) | P16: =IF(ISBLANK(N16),"",IF(AND(N16>N15,O16>O15),"Long Buildup",IF(AND(N16>N15,O16<O15),"Short Buildup",IF(AND(N16<N15,O16>O15),"Short Covering",IF(AND(N16<N15,O16<O15),"Long Unwinding")))))
D17: =IF(ISBLANK(B17),"",IF(AND(B17>B16,C17>C16),"Long Buildup",IF(AND(B17>B16,C17<C16),"Short Buildup",IF(AND(B17<B16,C17>C16),"Short Covering",IF(AND(B17<B16,C17<C16),"Long Unwinding"))))) | H17: =IF(ISBLANK(F17),"",IF(AND(F17>F16,G17>G16),"Long Buildup",IF(AND(F17>F16,G17<G16),"Short Buildup",IF(AND(F17<F16,G17>G16),"Short Covering",IF(AND(F17<F16,G17<G16),"Long Unwinding"))))) | L17: =IF(ISBLANK(J17),"",IF(AND(J17>J16,K17>K16),"Long Buildup",IF(AND(J17>J16,K17<K16),"Short Buildup",IF(AND(J17<J16,K17>K16),"Short Covering",IF(AND(J17<J16,K17<K16),"Long Unwinding"))))) | P17: =IF(ISBLANK(N17),"",IF(AND(N17>N16,O17>O16),"Long Buildup",IF(AND(N17>N16,O17<O16),"Short Buildup",IF(AND(N17<N16,O17>O16),"Short Covering",IF(AND(N17<N16,O17<O16),"Long Unwinding")))))
D18: =IF(ISBLANK(B18),"",IF(AND(B18>B17,C18>C17),"Long Buildup",IF(AND(B18>B17,C18<C17),"Short Buildup",IF(AND(B18<B17,C18>C17),"Short Covering",IF(AND(B18<B17,C18<C17),"Long Unwinding"))))) | H18: =IF(ISBLANK(F18),"",IF(AND(F18>F17,G18>G17),"Long Buildup",IF(AND(F18>F17,G18<G17),"Short Buildup",IF(AND(F18<F17,G18>G17),"Short Covering",IF(AND(F18<F17,G18<G17),"Long Unwinding"))))) | L18: =IF(ISBLANK(J18),"",IF(AND(J18>J17,K18>K17),"Long Buildup",IF(AND(J18>J17,K18<K17),"Short Buildup",IF(AND(J18<J17,K18>K17),"Short Covering",IF(AND(J18<J17,K18<K17),"Long Unwinding"))))) | P18: =IF(ISBLANK(N18),"",IF(AND(N18>N17,O18>O17),"Long Buildup",IF(AND(N18>N17,O18<O17),"Short Buildup",IF(AND(N18<N17,O18>O17),"Short Covering",IF(AND(N18<N17,O18<O17),"Long Unwinding")))))
D19: =IF(ISBLANK(B19),"",IF(AND(B19>B18,C19>C18),"Long Buildup",IF(AND(B19>B18,C19<C18),"Short Buildup",IF(AND(B19<B18,C19>C18),"Short Covering",IF(AND(B19<B18,C19<C18),"Long Unwinding"))))) | H19: =IF(ISBLANK(F19),"",IF(AND(F19>F18,G19>G18),"Long Buildup",IF(AND(F19>F18,G19<G18),"Short Buildup",IF(AND(F19<F18,G19>G18),"Short Covering",IF(AND(F19<F18,G19<G18),"Long Unwinding"))))) | L19: =IF(ISBLANK(J19),"",IF(AND(J19>J18,K19>K18),"Long Buildup",IF(AND(J19>J18,K19<K18),"Short Buildup",IF(AND(J19<J18,K19>K18),"Short Covering",IF(AND(J19<J18,K19<K18),"Long Unwinding"))))) | P19: =IF(ISBLANK(N19),"",IF(AND(N19>N18,O19>O18),"Long Buildup",IF(AND(N19>N18,O19<O18),"Short Buildup",IF(AND(N19<N18,O19>O18),"Short Covering",IF(AND(N19<N18,O19<O18),"Long Unwinding")))))
D20: =IF(ISBLANK(B20),"",IF(AND(B20>B19,C20>C19),"Long Buildup",IF(AND(B20>B19,C20<C19),"Short Buildup",IF(AND(B20<B19,C20>C19),"Short Covering",IF(AND(B20<B19,C20<C19),"Long Unwinding"))))) | H20: =IF(ISBLANK(F20),"",IF(AND(F20>F19,G20>G19),"Long Buildup",IF(AND(F20>F19,G20<G19),"Short Buildup",IF(AND(F20<F19,G20>G19),"Short Covering",IF(AND(F20<F19,G20<G19),"Long Unwinding"))))) | L20: =IF(ISBLANK(J20),"",IF(AND(J20>J19,K20>K19),"Long Buildup",IF(AND(J20>J19,K20<K19),"Short Buildup",IF(AND(J20<J19,K20>K19),"Short Covering",IF(AND(J20<J19,K20<K19),"Long Unwinding"))))) | P20: =IF(ISBLANK(N20),"",IF(AND(N20>N19,O20>O19),"Long Buildup",IF(AND(N20>N19,O20<O19),"Short Buildup",IF(AND(N20<N19,O20>O19),"Short Covering",IF(AND(N20<N19,O20<O19),"Long Unwinding")))))

Sheet Strategy
A1: ColA | B1: low | C1: middle | D1: high | E1: Strategy | H1: Methods To Recover Loss | K1: Amnt Total | L1: 24000
A2: =B2&C2&D2 -> CallCallCall | B2: Call | C2: Call | D2: Call | E2: Strong Call | H2: Stop Loss Followed | K2: In Hand | L2: 5000
A3: =B3&C3&D3 -> CallCallWait | B3: Call | C3: Call | D3: Wait | E3: Turning to Call | H3: Later Trading | K3: Avl for Trade | L3: =L1-L2 -> 19000
A4: =B4&C4&D4 -> CallCallPut | B4: Call | C4: Call | D4: Put | E4: Wait | H4: Opposite Trading | K4: Trade Amnt 1 | L4: =205*75 -> 15375 | M4: =(L4/L3) -> 0.80921053 | N4: Bal | O4: =L3-L4 -> 3625
A5: =B5&C5&D5 -> CallCallStrong Call | B5: Call | C5: Call | D5: Strong Call | E5: Strong Call | K5: Trade Amnt 2
A6: =B6&C6&D6 -> CallCallStrong Put | B6: Call | C6: Call | D6: Strong Put | E6: waiting for call breakout | K6: Trade Amnt 3
A7: =B7&C7&D7 -> CallWaitCall | B7: Call | C7: Wait | D7: Call | E7: Call
A8: =B8&C8&D8 -> CallWaitWait | B8: Call | C8: Wait | D8: Wait | E8: Rangebound
A9: =B9&C9&D9 -> CallWaitPut | B9: Call | C9: Wait | D9: Put | E9: Rangebound
A10: =B10&C10&D10 -> CallWaitStrong Put | B10: Call | C10: Wait | D10: Strong Put | E10: Wait | M10: =K10*L10 -> 0
A11: =B11&C11&D11 -> CallWaitStrong Call | B11: Call | C11: Wait | D11: Strong Call | E11: Call | M11: =K11*L11 -> 0
A12: =B12&C12&D12 -> CallPutCall | B12: Call | C12: Put | D12: Call | E12: Rangebound | M12: =K12*L12 -> 0
A13: =B13&C13&D13 -> CallPutWait | B13: Call | C13: Put | D13: Wait | E13: Rangebound | M13: =K13*L13 -> 0
A14: =B14&C14&D14 -> CallPutPut | B14: Call | C14: Put | D14: Put | E14: Turning to Put | M14: =K14*L14 -> 0
A15: =B15&C15&D15 -> CallPutStrong Put | B15: Call | C15: Put | D15: Strong Put | E15: Strong Put | M15: =K15*L15 -> 0
A16: =B16&C16&D16 -> CallPutStrong Call | B16: Call | C16: Put | D16: Strong Call | E16: Call | K16: =SUM(K10:K15) -> 0 | L16: =M16/K16 -> #DIV/0! | M16: =SUM(M10:M15) -> 0
A17: =B17&C17&D17 -> CallStrong CallCall | B17: Call | C17: Strong Call | D17: Call | E17: Strong Call
A18: =B18&C18&D18 -> CallStrong CallWait | B18: Call | C18: Strong Call | D18: Wait | E18: Call
A19: =B19&C19&D19 -> CallStrong CallPut | B19: Call | C19: Strong Call | D19: Put | E19: Call
A20: =B20&C20&D20 -> CallStrong CallStrong Call | B20: Call | C20: Strong Call | D20: Strong Call | E20: Strong Call
A21: =B21&C21&D21 -> CallStrong CallStrong Put | B21: Call | C21: Strong Call | D21: Strong Put | E21: Breakout to Happen
A22: =B22&C22&D22 -> CallStrong PutCall | B22: Call | C22: Strong Put | D22: Call | E22: NA
A23: =B23&C23&D23 -> CallStrong PutWait | B23: Call | C23: Strong Put | D23: Wait | E23: NA
A24: =B24&C24&D24 -> CallStrong PutPut | B24: Call | C24: Strong Put | D24: Put | E24: NA
A25: =B25&C25&D25 -> CallStrong PutStrong Call | B25: Call | C25: Strong Put | D25: Strong Call | E25: Breakout to Happen
A26: =B26&C26&D26 -> CallStrong PutStrong Put | B26: Call | C26: Strong Put | D26: Strong Put | E26: Strong Put
A27: =B27&C27&D27 -> WaitCallCall | B27: Wait | C27: Call | D27: Call | E27: Turning to Call
A28: =B28&C28&D28 -> WaitCallWait | B28: Wait | C28: Call | D28: Wait | E28: Wait
... A104: =B104&C104&D104 -> Strong PutCallPut | B104: Strong Put | C104: Call | D104: Put | E104: NA
A105: =B105&C105&D105
A106: =B106&C106&D106 -> Strong PutCallStrong Put | B106: Strong Put | C106: Call | D106: Strong Put | E106: Strong Put
A107: =B107&C107&D107 -> Strong PutWaitCall | B107: Strong Put | C107: Wait | D107: Call | E107: NA
A108: =B108&C108&D108 -> Strong PutWaitWait | B108: Strong Put | C108: Wait | D108: Wait | E108: NA
A109: =B109&C109&D109 -> Strong PutWaitPut | B109: Strong Put | C109: Wait | D109: Put | E109: Put
A110: =B110&C110&D110
A111: =B111&C111&D111 -> Strong PutWaitStrong Put | B111: Strong Put | C111: Wait | D111: Strong Put | E111: Strong Put
A112: =B112&C112&D112 -> Strong PutPutCall | B112: Strong Put | C112: Put | D112: Call | E112: Strong Put
A113: =B113&C113&D113 -> Strong PutPutWait | B113: Strong Put | C113: Put | D113: Wait | E113: Strong Put
A114: =B114&C114&D114 -> Strong PutPutPut | B114: Strong Put | C114: Put | D114: Put | E114: Strong Put
A115: =B115&C115&D115
...
