Workbook

Sheet Sheet1
A1: ColB | B1: DPST | C1: DpstName | D1: Item | E1: Item_desc | F1: ProductGroups | G1: New PG | H1: NewProductGrp
A2: =B2&D2 -> 90041120326630 | B2: 90041 | C2: AED - SPARES | D2: 120326630 | E2: LOCK ASSY RIGHT | F2: SPARES / ACCESSORIES | H2: =IF(LEN(G2)<2,F2,G2) -> SPARES / ACCESSORIES | I2: ="update ats_prd_master_new set ProductGroups= "&"'"&H2&"'"&"where ProductGroups="&"'"&F2&"'"&" and DPST= "&"'"&B2&"'"&"and item= "&"'"&D2&"'" -> update ats_prd_master_new set ProductGroups= 'SPARES / ACCESSORIES'where ProductGroups='SPARES / ACCESSORIES' and DPST= '90041'and item= '120326630'
A3: =B3&D3 -> 90041120353370 | B3: 90041 | C3: AED - SPARES | D3: 120353370 | E3: COVER;TOP;MOTOR | F3: SPARES / ACCESSORIES | H3: =IF(LEN(G3)<2,F3,G3) -> SPARES / ACCESSORIES | I3: ="update ats_prd_master_new set ProductGroups= "&"'"&H3&"'"&"where ProductGroups="&"'"&F3&"'"&" and DPST= "&"'"&B3&"'"&"and item= "&"'"&D3&"'" -> update ats_prd_master_new set ProductGroups= 'SPARES / ACCESSORIES'where ProductGroups='SPARES / ACCESSORIES' and DPST= '90041'and item= '120353370'
A4: =B4&D4 -> 90041120355460 | B4: 90041 | C4: AED - SPARES | D4: 120355460 | E4: TOP PLATE ASSY FOLL POWDER COA | F4: SPARES / ACCESSORIES | H4: =IF(LEN(G4)<2,F4,G4) -> SPARES / ACCESSORIES | I4: ="update ats_prd_master_new set ProductGroups= "&"'"&H4&"'"&"where ProductGroups="&"'"&F4&"'"&" and DPST= "&"'"&B4&"'"&"and item= "&"'"&D4&"'" -> update ats_prd_master_new set ProductGroups= 'SPARES / ACCESSORIES'where ProductGroups='SPARES / ACCESSORIES' and DPST= '90041'and item= '120355460'
A5: =B5&D5 -> 900411203SA1000NU | B5: 90041 | C5: AED - SPARES | D5: 1203SA1000NU | E5: PIN SA1000-WSC | F5: SPARES / ACCESSORIES | H5: =IF(LEN(G5)<2,F5,G5) -> SPARES / ACCESSORIES | I5: ="update ats_prd_master_new set ProductGroups= "&"'"&H5&"'"&"where ProductGroups="&"'"&F5&"'"&" and DPST= "&"'"&B5&"'"&"and item= "&"'"&D5&"'" -> update ats_prd_master_new set ProductGroups= 'SPARES / ACCESSORIES'where ProductGroups='SPARES / ACCESSORIES' and DPST= '90041'and item= '1203SA1000NU'
A6: =B6&D6 -> 90041120418960 | B6: 90041 | C6: AED - SPARES | D6: 120418960 | E6: HOSE ASSY (3 MTRS) | F6: SPARES / ACCESSORIES | H6: =IF(LEN(G6)<2,F6,G6) -> SPARES / ACCESSORIES | I6: ="update ats_prd_master_new set ProductGroups= "&"'"&H6&"'"&"where ProductGroups="&"'"&F6&"'"&" and DPST= "&"'"&B6&"'"&"and item= "&"'"&D6&"'" -> update ats_prd_master_new set ProductGroups= 'SPARES / ACCESSORIES'where ProductGroups='SPARES / ACCESSORIES' and DPST= '90041'and item= '120418960'
A7: =B7&D7 -> 90041120430551 | B7: 90041 | C7: AED - SPARES | D7: 120430551 | E7: UNION TEE DIA6MM | F7: SPARES / ACCESSORIES | H7: =IF(LEN(G7)<2,F7,G7) -> SPARES / ACCESSORIES | I7: ="update ats_prd_master_new set ProductGroups= "&"'"&H7&"'"&"where ProductGroups="&"'"&F7&"'"&" and DPST= "&"'"&B7&"'"&"and item= "&"'"&D7&"'" -> update ats_prd_master_new set ProductGroups= 'SPARES / ACCESSORIES'where ProductGroups='SPARES / ACCESSORIES' and DPST= '90041'and item= '120430551'
A8: =B8&D8 -> 90041120430552 | B8: 90041 | C8: AED - SPARES | D8: 120430552 | E8: MALE CONNECTOR DIA6X5MM | F8: SPARES / ACCESSORIES | H8: =IF(LEN(G8)<2,F8,G8) -> SPARES / ACCESSORIES | I8: ="update ats_prd_master_new set ProductGroups= "&"'"&H8&"'"&"where ProductGroups="&"'"&F8&"'"&" and DPST= "&"'"&B8&"'"&"and item= "&"'"&D8&"'" -> update ats_prd_master_new set ProductGroups= 'SPARES / ACCESSORIES'where ProductGroups='SPARES / ACCESSORIES' and DPST= '90041'and item= '120430552'
A9: =B9&D9 -> 90041120452510 | B9: 90041 | C9: AED - SPARES | D9: 120452510 | E9: COVER HOLDER; PIN - 3TON | F9: SPARES / ACCESSORIES | H9: =IF(LEN(G9)<2,F9,G9) -> SPARES / ACCESSORIES | I9: ="update ats_prd_master_new set ProductGroups= "&"'"&H9&"'"&"where ProductGroups="&"'"&F9&"'"&" and DPST= "&"'"&B9&"'"&"and item= "&"'"&D9&"'" -> update ats_prd_master_new set ProductGroups= 'SPARES / ACCESSORIES'where ProductGroups='SPARES / ACCESSORIES' and DPST= '90041'and item= '120452510'
A10: =B10&D10 -> 90041120453550 | B10: 90041 | C10: AED - SPARES | D10: 120453550 | E10: PULLEY MOTOR M/C SAL | F10: SPARES / ACCESSORIES | H10: =IF(LEN(G10)<2,F10,G10) -> SPARES / ACCESSORIES | I10: ="update ats_prd_master_new set ProductGroups= "&"'"&H10&"'"&"where ProductGroups="&"'"&F10&"'"&" and DPST= "&"'"&B10&"'"&"and item= "&"'"&D10&"'" -> update ats_prd_master_new set ProductGroups= 'SPARES / ACCESSORIES'where ProductGroups='SPARES / ACCESSORIES' and DPST= '90041'and item= '120453550'
A11: =B11&D11 -> 90041120454600 | B11: 90041 | C11: AED - SPARES | D11: 120454600 | E11: STUD ASSY,ARM - SAL HYN | F11: SPARES / ACCESSORIES | H11: =IF(LEN(G11)<2,F11,G11) -> SPARES / ACCESSORIES | I11: ="update ats_prd_master_new set ProductGroups= "&"'"&H11&"'"&"where ProductGroups="&"'"&F11&"'"&" and DPST= "&"'"&B11&"'"&"and item= "&"'"&D11&"'" -> update ats_prd_master_new set ProductGroups= 'SPARES / ACCESSORIES'where ProductGroups='SPARES / ACCESSORIES' and DPST= '90041'and item= '120454600'
A12: =B12&D12 -> 90041120463570 | B12: 90041 | C12: AED - SPARES | D12: 120463570 | E12: PIN (CYLINDER BOTTOM) | F12: SPARES / ACCESSORIES | H12: =IF(LEN(G12)<2,F12,G12) -> SPARES / ACCESSORIES | I12: ="update ats_prd_master_new set ProductGroups= "&"'"&H12&"'"&"where ProductGroups="&"'"&F12&"'"&" and DPST= "&"'"&B12&"'"&"and item= "&"'"&D12&"'" -> update ats_prd_master_new set ProductGroups= 'SPARES / ACCESSORIES'where ProductGroups='SPARES / ACCESSORIES' and DPST= '90041'and item= '120463570'
A13: =B13&D13 -> 90041120463850 | B13: 90041 | C13: AED - SPARES | D13: 120463850 | E13: BREATHER | F13: SPARES / ACCESSORIES | H13: =IF(LEN(G13)<2,F13,G13) -> SPARES / ACCESSORIES | I13: ="update ats_prd_master_new set ProductGroups= "&"'"&H13&"'"&"where ProductGroups="&"'"&F13&"'"&" and DPST= "&"'"&B13&"'"&"and item= "&"'"&D13&"'" -> update ats_prd_master_new set ProductGroups= 'SPARES / ACCESSORIES'where ProductGroups='SPARES / ACCESSORIES' and DPST= '90041'and item= '120463850'
... A23: =B23&D23 -> 90029SCIN0005 | B23: 90029 | C23: Rocd-service revenue | D23: SCIN0005 | E23: AMC CHARGES | F23: SERVICE BILLING | H23: =IF(LEN(G23)<2,F23,G23) -> SERVICE BILLING | I23: ="update ats_prd_master_new set ProductGroups= "&"'"&H23&"'"&"where ProductGroups="&"'"&F23&"'"&" and DPST= "&"'"&B23&"'"&"and item= "&"'"&D23&"'" -> update ats_prd_master_new set ProductGroups= 'SERVICE BILLING'where ProductGroups='SERVICE BILLING' and DPST= '90029'and item= 'SCIN0005'
A24: =B24&D24 -> 90029SCIN0006 | B24: 90029 | C24: Rocd-service revenue | D24: SCIN0006 | F24: SERVICE BILLING | H24: =IF(LEN(G24)<2,F24,G24) -> SERVICE BILLING | I24: ="update ats_prd_master_new set ProductGroups= "&"'"&H24&"'"&"where ProductGroups="&"'"&F24&"'"&" and DPST= "&"'"&B24&"'"&"and item= "&"'"&D24&"'" -> update ats_prd_master_new set ProductGroups= 'SERVICE BILLING'where ProductGroups='SERVICE BILLING' and DPST= '90029'and item= 'SCIN0006'
A25: =B25&D25 -> 90029SCIN0007 | B25: 90029 | C25: Rocd-service revenue | D25: SCIN0007 | F25: SERVICE BILLING | H25: =IF(LEN(G25)<2,F25,G25) -> SERVICE BILLING | I25: ="update ats_prd_master_new set ProductGroups= "&"'"&H25&"'"&"where ProductGroups="&"'"&F25&"'"&" and DPST= "&"'"&B25&"'"&"and item= "&"'"&D25&"'" -> update ats_prd_master_new set ProductGroups= 'SERVICE BILLING'where ProductGroups='SERVICE BILLING' and DPST= '90029'and item= 'SCIN0007'
A26: =B26&D26 -> 90029SCIN0008 | B26: 90029 | C26: Rocd-service revenue | D26: SCIN0008 | F26: SERVICE BILLING | H26: =IF(LEN(G26)<2,F26,G26) -> SERVICE BILLING | I26: ="update ats_prd_master_new set ProductGroups= "&"'"&H26&"'"&"where ProductGroups="&"'"&F26&"'"&" and DPST= "&"'"&B26&"'"&"and item= "&"'"&D26&"'" -> update ats_prd_master_new set ProductGroups= 'SERVICE BILLING'where ProductGroups='SERVICE BILLING' and DPST= '90029'and item= 'SCIN0008'
A27: =B27&D27 -> 90029SCIN0009 | B27: 90029 | C27: Rocd-service revenue | D27: SCIN0009 | F27: SERVICE BILLING | H27: =IF(LEN(G27)<2,F27,G27) -> SERVICE BILLING | I27: ="update ats_prd_master_new set ProductGroups= "&"'"&H27&"'"&"where ProductGroups="&"'"&F27&"'"&" and DPST= "&"'"&B27&"'"&"and item= "&"'"&D27&"'" -> update ats_prd_master_new set ProductGroups= 'SERVICE BILLING'where ProductGroups='SERVICE BILLING' and DPST= '90029'and item= 'SCIN0009'
A28: =B28&D28 -> 90040008400130 | B28: 90040 | C28: AED - MANUFACTURED UNITS | D28: 008400130 | E28: ON DELAY TIMER | F28: SPARES / ACCESSORIES | H28: =IF(LEN(G28)<2,F28,G28) -> SPARES / ACCESSORIES | I28: ="update ats_prd_master_new set ProductGroups= "&"'"&H28&"'"&"where ProductGroups="&"'"&F28&"'"&" and DPST= "&"'"&B28&"'"&"and item= "&"'"&D28&"'" -> update ats_prd_master_new set ProductGroups= 'SPARES / ACCESSORIES'where ProductGroups='SPARES / ACCESSORIES' and DPST= '90040'and item= '008400130'
A29: =B29&D29 -> 90040008937011 | B29: 90040 | C29: AED - MANUFACTURED UNITS | D29: 008937011 | E29: TRANSFORMER 50VA 415V-0-24V. | F29: SPARES / ACCESSORIES | H29: =IF(LEN(G29)<2,F29,G29) -> SPARES / ACCESSORIES | I29: ="update ats_prd_master_new set ProductGroups= "&"'"&H29&"'"&"where ProductGroups="&"'"&F29&"'"&" and DPST= "&"'"&B29&"'"&"and item= "&"'"&D29&"'" -> update ats_prd_master_new set ProductGroups= 'SPARES / ACCESSORIES'where ProductGroups='SPARES / ACCESSORIES' and DPST= '90040'and item= '008937011'
A30: =B30&D30 -> 90040080302630 | B30: 90040 | C30: AED - MANUFACTURED UNITS | D30: 080302630 | E30: CUSHION CHAIR | F30: MOBILE SERVICE UNITS | H30: =IF(LEN(G30)<2,F30,G30) -> MOBILE SERVICE UNITS | I30: ="update ats_prd_master_new set ProductGroups= "&"'"&H30&"'"&"where ProductGroups="&"'"&F30&"'"&" and DPST= "&"'"&B30&"'"&"and item= "&"'"&D30&"'" -> update ats_prd_master_new set ProductGroups= 'MOBILE SERVICE UNITS'where ProductGroups='MOBILE SERVICE UNITS' and DPST= '90040'and item= '080302630'
A31: =B31&D31 -> 90040080302730 | B31: 90040 | C31: AED - MANUFACTURED UNITS | D31: 080302730 | E31: AIR TANK ASSY | F31: MOBILE SERVICE UNITS | H31: =IF(LEN(G31)<2,F31,G31) -> MOBILE SERVICE UNITS | I31: ="update ats_prd_master_new set ProductGroups= "&"'"&H31&"'"&"where ProductGroups="&"'"&F31&"'"&" and DPST= "&"'"&B31&"'"&"and item= "&"'"&D31&"'" -> update ats_prd_master_new set ProductGroups= 'MOBILE SERVICE UNITS'where ProductGroups='MOBILE SERVICE UNITS' and DPST= '90040'and item= '080302730'
A32: =B32&D32 -> 90041130315300 | B32: 90041 | C32: AED - SPARES | D32: 130315300 | E32: COVER ASSY GREASE DRUM | F32: SPARES / ACCESSORIES | H32: =IF(LEN(G32)<2,F32,G32) -> SPARES / ACCESSORIES | I32: ="update ats_prd_master_new set ProductGroups= "&"'"&H32&"'"&"where ProductGroups="&"'"&F32&"'"&" and DPST= "&"'"&B32&"'"&"and item= "&"'"&D32&"'" -> update ats_prd_master_new set ProductGroups= 'SPARES / ACCESSORIES'where ProductGroups='SPARES / ACCESSORIES' and DPST= '90041'and item= '130315300'
A33: =B33&D33 -> 90041130416931 | B33: 90041 | C33: AED - SPARES | D33: 130416931 | E33: DRUM ASSY GREASE | F33: SPARES / ACCESSORIES | H33: =IF(LEN(G33)<2,F33,G33) -> SPARES / ACCESSORIES | I33: ="update ats_prd_master_new set ProductGroups= "&"'"&H33&"'"&"where ProductGroups="&"'"&F33&"'"&" and DPST= "&"'"&B33&"'"&"and item= "&"'"&D33&"'" -> update ats_prd_master_new set ProductGroups= 'SPARES / ACCESSORIES'where ProductGroups='SPARES / ACCESSORIES' and DPST= '90041'and item= '130416931'
A34: =B34&D34 -> 90040080302750 | B34: 90040 | C34: AED - MANUFACTURED UNITS | D34: 080302750 | E34: COMPRESSOR ASSY | F34: MMS | H34: =IF(LEN(G34)<2,F34,G34) -> MMS | I34: ="update ats_prd_master_new set ProductGroups= "&"'"&H34&"'"&"where ProductGroups="&"'"&F34&"'"&" and DPST= "&"'"&B34&"'"&"and item= "&"'"&D34&"'" -> update ats_prd_master_new set ProductGroups= 'MMS'where ProductGroups='MMS' and DPST= '90040'and item= '080302750'
A35: =B35&D35 -> 90041130453220 | B35: 90041 | C35: AED - SPARES | D35: 130453220 | E35: ADAPTER BUNG M/C | F35: SPARES / ACCESSORIES | H35: =IF(LEN(G35)<2,F35,G35) -> SPARES / ACCESSORIES | I35: ="update ats_prd_master_new set ProductGroups= "&"'"&H35&"'"&"where ProductGroups="&"'"&F35&"'"&" and DPST= "&"'"&B35&"'"&"and item= "&"'"&D35&"'" -> update ats_prd_master_new set ProductGroups= 'SPARES / ACCESSORIES'where ProductGroups='SPARES / ACCESSORIES' and DPST= '90041'and item= '130453220'
A36: =B36&D36 -> 90041130493020 | B36: 90041 | C36: AED - SPARES | D36: 130493020 | E36: PUMP WITH GUN ASSY-5 KG | F36: SPARES / ACCESSORIES | H36: =IF(LEN(G36)<2,F36,G36) -> SPARES / ACCESSORIES | I36: ="update ats_prd_master_new set ProductGroups= "&"'"&H36&"'"&"where ProductGroups="&"'"&F36&"'"&" and DPST= "&"'"&B36&"'"&"and item= "&"'"&D36&"'" -> update ats_prd_master_new set ProductGroups= 'SPARES / ACCESSORIES'where ProductGroups='SPARES / ACCESSORIES' and DPST= '90041'and item= '130493020'
A37: =B37&D37 -> 90040080302820 | B37: 90040 | C37: AED - MANUFACTURED UNITS | D37: 080302820 | E37: WATER TANK ASSY | F37: MMS | H37: =IF(LEN(G37)<2,F37,G37) -> MMS | I37: ="update ats_prd_master_new set ProductGroups= "&"'"&H37&"'"&"where ProductGroups="&"'"&F37&"'"&" and DPST= "&"'"&B37&"'"&"and item= "&"'"&D37&"'" -> update ats_prd_master_new set ProductGroups= 'MMS'where ProductGroups='MMS' and DPST= '90040'and item= '080302820'
A38: =B38&D38 -> 900411332HC0801PI | B38: 90041 | C38: AED - SPARES | D38: 1332HC0801PI | E38: WIND NOZZLE | F38: SPARES / ACCESSORIES | H38: =IF(LEN(G38)<2,F38,G38) -> SPARES / ACCESSORIES | I38: ="update ats_prd_master_new set ProductGroups= "&"'"&H38&"'"&"where ProductGroups="&"'"&F38&"'"&" and DPST= "&"'"&B38&"'"&"and item= "&"'"&D38&"'" -> update ats_prd_master_new set ProductGroups= 'SPARES / ACCESSORIES'where ProductGroups='SPARES / ACCESSORIES' and DPST= '90041'and item= '1332HC0801PI'
A39: =B39&D39 -> 900411332HC0803PI | B39: 90041 | C39: AED - SPARES | D39: 1332HC0803PI | E39: MINI BALL VALVE | F39: SPARES / ACCESSORIES | H39: =IF(LEN(G39)<2,F39,G39) -> SPARES / ACCESSORIES | I39: ="update ats_prd_master_new set ProductGroups= "&"'"&H39&"'"&"where ProductGroups="&"'"&F39&"'"&" and DPST= "&"'"&B39&"'"&"and item= "&"'"&D39&"'" -> update ats_prd_master_new set ProductGroups= 'SPARES / ACCESSORIES'where ProductGroups='SPARES / ACCESSORIES' and DPST= '90041'and item= '1332HC0803PI'
... A55: =B55&D55 -> 900401199PP002 | B55: 90040 | C55: AED - MANUFACTURED UNITS | D55: 1199PP002 | E55: CARWASHER 3HP MODELP36/30 | F55: WASHING EQUIPMENTS | H55: =IF(LEN(G55)<2,F55,G55) -> WASHING EQUIPMENTS | I55: ="update ats_prd_master_new set ProductGroups= "&"'"&H55&"'"&"where ProductGroups="&"'"&F55&"'"&" and DPST= "&"'"&B55&"'"&"and item= "&"'"&D55&"'" -> update ats_prd_master_new set ProductGroups= 'WASHING EQUIPMENTS'where ProductGroups='WASHING EQUIPMENTS' and DPST= '90040'and item= '1199PP002'
A56: =B56&D56 -> 900401199QR001 | B56: 90040 | C56: AED - MANUFACTURED UNITS | D56: 1199QR001 | E56: CAR MAT WASHER | F56: Mate Washer | G56: WASHING EQUIPMENTS | H56: =IF(LEN(G56)<2,F56,G56) -> WASHING EQUIPMENTS | I56: ="update ats_prd_master_new set ProductGroups= "&"'"&H56&"'"&"where ProductGroups="&"'"&F56&"'"&" and DPST= "&"'"&B56&"'"&"and item= "&"'"&D56&"'" -> update ats_prd_master_new set ProductGroups= 'WASHING EQUIPMENTS'where ProductGroups='Mate Washer' and DPST= '90040'and item= '1199QR001'
A57: =B57&D57 -> 90040120360320 | B57: 90040 | C57: AED - MANUFACTURED UNITS | D57: 120360320 | E57: WIRE ROPE ASSEMBLY | F57: LIFTING EQUIPMENTS | G57: LIFTING EQUIPMENTS - 2PL | H57: =IF(LEN(G57)<2,F57,G57) -> LIFTING EQUIPMENTS - 2PL | I57: ="update ats_prd_master_new set ProductGroups= "&"'"&H57&"'"&"where ProductGroups="&"'"&F57&"'"&" and DPST= "&"'"&B57&"'"&"and item= "&"'"&D57&"'" -> update ats_prd_master_new set ProductGroups= 'LIFTING EQUIPMENTS - 2PL'where ProductGroups='LIFTING EQUIPMENTS' and DPST= '90040'and item= '120360320'
A58: =B58&D58 -> 90040120367160 | B58: 90040 | C58: AED - MANUFACTURED UNITS | D58: 120367160 | E58: EP - POWER PACK ASSEMBLY | F58: WHEEL SERVICE EQUIPMENTS | H58: =IF(LEN(G58)<2,F58,G58) -> WHEEL SERVICE EQUIPMENTS | I58: ="update ats_prd_master_new set ProductGroups= "&"'"&H58&"'"&"where ProductGroups="&"'"&F58&"'"&" and DPST= "&"'"&B58&"'"&"and item= "&"'"&D58&"'" -> update ats_prd_master_new set ProductGroups= 'WHEEL SERVICE EQUIPMENTS'where ProductGroups='WHEEL SERVICE EQUIPMENTS' and DPST= '90040'and item= '120367160'
A59: =B59&D59 -> 90040120466030 | B59: 90040 | C59: AED - MANUFACTURED UNITS | D59: 120466030 | E59: KIT WHEELS FREE LIFT - S12105 | F59: LIFTING EQUIPMENTS | G59: LIFTING EQUIPMENTS - OTHERS | H59: =IF(LEN(G59)<2,F59,G59) -> LIFTING EQUIPMENTS - OTHERS | I59: ="update ats_prd_master_new set ProductGroups= "&"'"&H59&"'"&"where ProductGroups="&"'"&F59&"'"&" and DPST= "&"'"&B59&"'"&"and item= "&"'"&D59&"'" -> update ats_prd_master_new set ProductGroups= 'LIFTING EQUIPMENTS - OTHERS'where ProductGroups='LIFTING EQUIPMENTS' and DPST= '90040'and item= '120466030'
A60: =B60&D60 -> 9004012DTPP605DL | B60: 90040 | C60: AED - MANUFACTURED UNITS | D60: 12DTPP605DL | E60: PARKING LIFT SINGLE TYPE LIFT( | F60: LIFTING EQUIPMENTS | G60: LIFTING EQUIPMENTS - OTHERS | H60: =IF(LEN(G60)<2,F60,G60) -> LIFTING EQUIPMENTS - OTHERS | I60: ="update ats_prd_master_new set ProductGroups= "&"'"&H60&"'"&"where ProductGroups="&"'"&F60&"'"&" and DPST= "&"'"&B60&"'"&"and item= "&"'"&D60&"'" -> update ats_prd_master_new set ProductGroups= 'LIFTING EQUIPMENTS - OTHERS'where ProductGroups='LIFTING EQUIPMENTS' and DPST= '90040'and item= '12DTPP605DL'
A61: =B61&D61 -> 9004012DTPP606DL | B61: 90040 | C61: AED - MANUFACTURED UNITS | D61: 12DTPP606DL | E61: PARKING LIFT COMBINED TYPE LIF | F61: LIFTING EQUIPMENTS | G61: LIFTING EQUIPMENTS - OTHERS | H61: =IF(LEN(G61)<2,F61,G61) -> LIFTING EQUIPMENTS - OTHERS | I61: ="update ats_prd_master_new set ProductGroups= "&"'"&H61&"'"&"where ProductGroups="&"'"&F61&"'"&" and DPST= "&"'"&B61&"'"&"and item= "&"'"&D61&"'" -> update ats_prd_master_new set ProductGroups= 'LIFTING EQUIPMENTS - OTHERS'where ProductGroups='LIFTING EQUIPMENTS' and DPST= '90040'and item= '12DTPP606DL'
A62: =B62&D62 -> 9004013032834A | B62: 90040 | C62: AED - MANUFACTURED UNITS | D62: 13032834A | E62: HOSE ASSY OIL 1.1MT | F62: LUBE EQUIPMENTS | H62: =IF(LEN(G62)<2,F62,G62) -> LUBE EQUIPMENTS | I62: ="update ats_prd_master_new set ProductGroups= "&"'"&H62&"'"&"where ProductGroups="&"'"&F62&"'"&" and DPST= "&"'"&B62&"'"&"and item= "&"'"&D62&"'" -> update ats_prd_master_new set ProductGroups= 'LUBE EQUIPMENTS'where ProductGroups='LUBE EQUIPMENTS' and DPST= '90040'and item= '13032834A'
A63: =B63&D63 -> 90040130450190 | B63: 90040 | C63: AED - MANUFACTURED UNITS | D63: 130450190 | E63: PIPE ASSY; RISER | F63: SPARES / ACCESSORIES | H63: =IF(LEN(G63)<2,F63,G63) -> SPARES / ACCESSORIES | I63: ="update ats_prd_master_new set ProductGroups= "&"'"&H63&"'"&"where ProductGroups="&"'"&F63&"'"&" and DPST= "&"'"&B63&"'"&"and item= "&"'"&D63&"'" -> update ats_prd_master_new set ProductGroups= 'SPARES / ACCESSORIES'where ProductGroups='SPARES / ACCESSORIES' and DPST= '90040'and item= '130450190'
A64: =B64&D64 -> 90040150482210 | B64: 90040 | C64: AED - MANUFACTURED UNITS | D64: 150482210 | E64: FILTERS AND REGULATOR ASSY | F64: TYRE INFLATORS | H64: =IF(LEN(G64)<2,F64,G64) -> TYRE INFLATORS | I64: ="update ats_prd_master_new set ProductGroups= "&"'"&H64&"'"&"where ProductGroups="&"'"&F64&"'"&" and DPST= "&"'"&B64&"'"&"and item= "&"'"&D64&"'" -> update ats_prd_master_new set ProductGroups= 'TYRE INFLATORS'where ProductGroups='TYRE INFLATORS' and DPST= '90040'and item= '150482210'
...

Sheet Sheet2
A1: ColA | B1: DPST | C1: DpstName | D1: Item | E1: Item_desc | F1: ProductGroups | G1: UpdatedDate | H1: Rnk
A2: =B2&D2 -> 900423818010200003YS | B2: 90042 | C2: AED - TRADED UNITS | D2: 3818010200003YS | E2: CENTRAL PROCESSING UNIT FOR 3A | F2: NULL | G2: 43503.191 | H2: 1 | I2: =VLOOKUP(A2,Sheet1!A:G,1,0) -> 900423818010200003YS | J2: =VLOOKUP(A2,Sheet1!A:G,6,0) -> SPARES / ACCESSORIES | K2: ="update ATS_Prd_Master_New set ProductGroups= "&"'"&J2&"'"&"where dpst= "&B2&"and item= "&"'"&D2&"'"&"and ProductGroups is null" -> update ATS_Prd_Master_New set ProductGroups= 'SPARES / ACCESSORIES'where dpst= 90042and item= '3818010200003YS'and ProductGroups is null
A3: =B3&D3 -> 900421199KT002 | B3: 90042 | C3: AED - TRADED UNITS | D3: 1199KT002 | E3: WRP 1250 LITRES/HR | F3: NULL | G3: 43547.191 | H3: 1 | I3: =VLOOKUP(A3,Sheet1!A:G,1,0) -> 900421199KT002 | J3: =VLOOKUP(A3,Sheet1!A:G,6,0) -> ETP/RO/WRP | K3: ="update ATS_Prd_Master_New set ProductGroups= "&"'"&J3&"'"&"where dpst= "&B3&"and item= "&"'"&D3&"'"&"and ProductGroups is null" -> update ATS_Prd_Master_New set ProductGroups= 'ETP/RO/WRP'where dpst= 90042and item= '1199KT002'and ProductGroups is null
A4: =B4&D4 -> 90042S25007 | B4: 90042 | C4: AED - TRADED UNITS | D4: S25007 | E4: ACRU - FA - WITHOUT PRINTER | F4: NULL | G4: 43547.191 | H4: 1 | I4: =VLOOKUP(A4,Sheet1!A:G,1,0) -> 90042S25007 | J4: =VLOOKUP(A4,Sheet1!A:G,6,0) -> AC CHARGING MACHINE | K4: ="update ATS_Prd_Master_New set ProductGroups= "&"'"&J4&"'"&"where dpst= "&B4&"and item= "&"'"&D4&"'"&"and ProductGroups is null" -> update ATS_Prd_Master_New set ProductGroups= 'AC CHARGING MACHINE'where dpst= 90042and item= 'S25007'and ProductGroups is null
A5: =B5&D5 -> 900401699EL007 | B5: 90040 | C5: AED - MANUFACTURED UNITS | D5: 1699EL007 | E5: DOUBLE MOTOR INDUSTRIAL W&D VR | F5: NULL | G5: 43545.192 | H5: 1 | I5: =VLOOKUP(A5,Sheet1!A:G,1,0) -> 900401699EL007 | J5: =VLOOKUP(A5,Sheet1!A:G,6,0) -> WASHING EQUIPMENTS | K5: ="update ATS_Prd_Master_New set ProductGroups= "&"'"&J5&"'"&"where dpst= "&B5&"and item= "&"'"&D5&"'"&"and ProductGroups is null" -> update ATS_Prd_Master_New set ProductGroups= 'WASHING EQUIPMENTS'where dpst= 90040and item= '1699EL007'and ProductGroups is null
A6: =B6&D6 -> 900404899SZ059 | B6: 90040 | C6: AED - MANUFACTURED UNITS | D6: 4899SZ059 | E6: Pull Strap Kit | F6: NULL | G6: 43545.192 | H6: 1 | I6: =VLOOKUP(A6,Sheet1!A:G,1,0) -> 900404899SZ059 | J6: =VLOOKUP(A6,Sheet1!A:G,6,0) -> BODY SHOP & PAINT EQUIPMENTS | K6: ="update ATS_Prd_Master_New set ProductGroups= "&"'"&J6&"'"&"where dpst= "&B6&"and item= "&"'"&D6&"'"&"and ProductGroups is null" -> update ATS_Prd_Master_New set ProductGroups= 'BODY SHOP & PAINT EQUIPMENTS'where dpst= 90040and item= '4899SZ059'and ProductGroups is null
A7: =B7&D7 -> 900404899SZ061 | B7: 90040 | C7: AED - MANUFACTURED UNITS | D7: 4899SZ061 | E7: Pull plier | F7: NULL | G7: 43545.192 | H7: 1 | I7: =VLOOKUP(A7,Sheet1!A:G,1,0) -> 900404899SZ061 | J7: =VLOOKUP(A7,Sheet1!A:G,6,0) -> BODY SHOP & PAINT EQUIPMENTS | K7: ="update ATS_Prd_Master_New set ProductGroups= "&"'"&J7&"'"&"where dpst= "&B7&"and item= "&"'"&D7&"'"&"and ProductGroups is null" -> update ATS_Prd_Master_New set ProductGroups= 'BODY SHOP & PAINT EQUIPMENTS'where dpst= 90040and item= '4899SZ061'and ProductGroups is null
A8: =B8&D8 -> 900404899SZ062 | B8: 90040 | C8: AED - MANUFACTURED UNITS | D8: 4899SZ062 | E8: Chain Shorten 2 Hooks | F8: NULL | G8: 43545.192 | H8: 1 | I8: =VLOOKUP(A8,Sheet1!A:G,1,0) -> 900404899SZ062 | J8: =VLOOKUP(A8,Sheet1!A:G,6,0) -> BODY SHOP & PAINT EQUIPMENTS | K8: ="update ATS_Prd_Master_New set ProductGroups= "&"'"&J8&"'"&"where dpst= "&B8&"and item= "&"'"&D8&"'"&"and ProductGroups is null" -> update ATS_Prd_Master_New set ProductGroups= 'BODY SHOP & PAINT EQUIPMENTS'where dpst= 90040and item= '4899SZ062'and ProductGroups is null
A9: =B9&D9 -> 900404899SZ063 | B9: 90040 | C9: AED - MANUFACTURED UNITS | D9: 4899SZ063 | E9: 1.5 M Chain 10 T with 1 hook | F9: NULL | G9: 43545.192 | H9: 1 | I9: =VLOOKUP(A9,Sheet1!A:G,1,0) -> 900404899SZ063 | J9: =VLOOKUP(A9,Sheet1!A:G,6,0) -> BODY SHOP & PAINT EQUIPMENTS | K9: ="update ATS_Prd_Master_New set ProductGroups= "&"'"&J9&"'"&"where dpst= "&B9&"and item= "&"'"&D9&"'"&"and ProductGroups is null" -> update ATS_Prd_Master_New set ProductGroups= 'BODY SHOP & PAINT EQUIPMENTS'where dpst= 90040and item= '4899SZ063'and ProductGroups is null
A10: =B10&D10 -> 900404899SZ064 | B10: 90040 | C10: AED - MANUFACTURED UNITS | D10: 4899SZ064 | E10: 3 M Chain 10 T with 1 hook | F10: NULL | G10: 43545.192 | H10: 1 | I10: =VLOOKUP(A10,Sheet1!A:G,1,0) -> 900404899SZ064 | J10: =VLOOKUP(A10,Sheet1!A:G,6,0) -> BODY SHOP & PAINT EQUIPMENTS | K10: ="update ATS_Prd_Master_New set ProductGroups= "&"'"&J10&"'"&"where dpst= "&B10&"and item= "&"'"&D10&"'"&"and ProductGroups is null" -> update ATS_Prd_Master_New set ProductGroups= 'BODY SHOP & PAINT EQUIPMENTS'where dpst= 90040and item= '4899SZ064'and ProductGroups is null
A11: =B11&D11 -> 900409099YA001 | B11: 90040 | C11: AED - MANUFACTURED UNITS | D11: 9099YA001 | E11: Collision Repair System 300 | F11: NULL | G11: 43545.192 | H11: 1 | I11: =VLOOKUP(A11,Sheet1!A:G,1,0) -> 900409099YA001 | J11: =VLOOKUP(A11,Sheet1!A:G,6,0) -> BODY SHOP & PAINT EQUIPMENTS | K11: ="update ATS_Prd_Master_New set ProductGroups= "&"'"&J11&"'"&"where dpst= "&B11&"and item= "&"'"&D11&"'"&"and ProductGroups is null" -> update ATS_Prd_Master_New set ProductGroups= 'BODY SHOP & PAINT EQUIPMENTS'where dpst= 90040and item= '9099YA001'and ProductGroups is null
A12: =B12&D12 -> 900409099YA004 | B12: 90040 | C12: AED - MANUFACTURED UNITS | D12: 9099YA004 | E12: Air jack | F12: NULL | G12: 43545.192 | H12: 1 | I12: =VLOOKUP(A12,Sheet1!A:G,1,0) -> 900409099YA004 | J12: =VLOOKUP(A12,Sheet1!A:G,6,0) -> BODY SHOP & PAINT EQUIPMENTS | K12: ="update ATS_Prd_Master_New set ProductGroups= "&"'"&J12&"'"&"where dpst= "&B12&"and item= "&"'"&D12&"'"&"and ProductGroups is null" -> update ATS_Prd_Master_New set ProductGroups= 'BODY SHOP & PAINT EQUIPMENTS'where dpst= 90040and item= '9099YA004'and ProductGroups is null
A13: =B13&D13 -> 900409099YA006 | B13: 90040 | C13: AED - MANUFACTURED UNITS | D13: 9099YA006 | E13: Accessories Kit | F13: NULL | G13: 43545.192 | H13: 1 | I13: =VLOOKUP(A13,Sheet1!A:G,1,0) -> 900409099YA006 | J13: =VLOOKUP(A13,Sheet1!A:G,6,0) -> SPARES / ACCESSORIES | K13: ="update ATS_Prd_Master_New set ProductGroups= "&"'"&J13&"'"&"where dpst= "&B13&"and item= "&"'"&D13&"'"&"and ProductGroups is null" -> update ATS_Prd_Master_New set ProductGroups= 'SPARES / ACCESSORIES'where dpst= 90040and item= '9099YA006'and ProductGroups is null
... A53: =B53&D53 -> 900423999WR027 | B53: 90042 | C53: AED - TRADED UNITS | D53: 3999WR027 | E53: Exhaust Extraction System | F53: NULL | G53: 43540.191 | H53: 1 | I53: =VLOOKUP(A53,Sheet1!A:G,1,0) -> 900423999WR027 | J53: =VLOOKUP(A53,Sheet1!A:G,6,0) -> BODY SHOP & PAINT EQUIPMENTS | K53: ="update ATS_Prd_Master_New set ProductGroups= "&"'"&J53&"'"&"where dpst= "&B53&"and item= "&"'"&D53&"'"&"and ProductGroups is null" -> update ATS_Prd_Master_New set ProductGroups= 'BODY SHOP & PAINT EQUIPMENTS'where dpst= 90042and item= '3999WR027'and ProductGroups is null

Sheet Sheet3
B1: DPST | C1: DpstName | D1: Item | E1: Item_desc | F1: ProductGroups | G1: Lookup
A2: =B2&D2 -> 90041120326630 | B2: 90041 | C2: AED - SPARES | D2: 120326630 | E2: LOCK ASSY RIGHT | F2: SPARES / ACCESSORIES | G2: =VLOOKUP(A2,Sheet2!A:J,1,0) -> #N/A | H2: =VLOOKUP(A2,Sheet2!A:J,6,0) -> #N/A
A3: =B3&D3 -> 90041120353370 | B3: 90041 | C3: AED - SPARES | D3: 120353370 | E3: COVER;TOP;MOTOR | F3: SPARES / ACCESSORIES | G3: =VLOOKUP(A3,Sheet2!A:J,1,0) -> #N/A | H3: =VLOOKUP(A3,Sheet2!A:J,6,0) -> #N/A
A4: =B4&D4 -> 90041120355460 | B4: 90041 | C4: AED - SPARES | D4: 120355460 | E4: TOP PLATE ASSY FOLL POWDER COA | F4: SPARES / ACCESSORIES | G4: =VLOOKUP(A4,Sheet2!A:J,1,0) -> #N/A | H4: =VLOOKUP(A4,Sheet2!A:J,6,0) -> #N/A
A5: =B5&D5 -> 900411203SA1000NU | B5: 90041 | C5: AED - SPARES | D5: 1203SA1000NU | E5: PIN SA1000-WSC | F5: SPARES / ACCESSORIES | G5: =VLOOKUP(A5,Sheet2!A:J,1,0) -> #N/A | H5: =VLOOKUP(A5,Sheet2!A:J,6,0) -> #N/A
A6: =B6&D6 -> 90041120418960 | B6: 90041 | C6: AED - SPARES | D6: 120418960 | E6: HOSE ASSY (3 MTRS) | F6: SPARES / ACCESSORIES | G6: =VLOOKUP(A6,Sheet2!A:J,1,0) -> #N/A | H6: =VLOOKUP(A6,Sheet2!A:J,6,0) -> #N/A
A7: =B7&D7 -> 90041120430551 | B7: 90041 | C7: AED - SPARES | D7: 120430551 | E7: UNION TEE DIA6MM | F7: SPARES / ACCESSORIES | G7: =VLOOKUP(A7,Sheet2!A:J,1,0) -> #N/A | H7: =VLOOKUP(A7,Sheet2!A:J,6,0) -> #N/A
A8: =B8&D8 -> 90041120430552 | B8: 90041 | C8: AED - SPARES | D8: 120430552 | E8: MALE CONNECTOR DIA6X5MM | F8: SPARES / ACCESSORIES | G8: =VLOOKUP(A8,Sheet2!A:J,1,0) -> #N/A | H8: =VLOOKUP(A8,Sheet2!A:J,6,0) -> #N/A
A9: =B9&D9 -> 90041120452510 | B9: 90041 | C9: AED - SPARES | D9: 120452510 | E9: COVER HOLDER; PIN - 3TON | F9: SPARES / ACCESSORIES | G9: =VLOOKUP(A9,Sheet2!A:J,1,0) -> #N/A | H9: =VLOOKUP(A9,Sheet2!A:J,6,0) -> #N/A
A10: =B10&D10 -> 90041120453550 | B10: 90041 | C10: AED - SPARES | D10: 120453550 | E10: PULLEY MOTOR M/C SAL | F10: SPARES / ACCESSORIES | G10: =VLOOKUP(A10,Sheet2!A:J,1,0) -> #N/A | H10: =VLOOKUP(A10,Sheet2!A:J,6,0) -> #N/A
A11: =B11&D11 -> 90041120454600 | B11: 90041 | C11: AED - SPARES | D11: 120454600 | E11: STUD ASSY,ARM - SAL HYN | F11: SPARES / ACCESSORIES | G11: =VLOOKUP(A11,Sheet2!A:J,1,0) -> #N/A | H11: =VLOOKUP(A11,Sheet2!A:J,6,0) -> #N/A
A12: =B12&D12 -> 90041120463570 | B12: 90041 | C12: AED - SPARES | D12: 120463570 | E12: PIN (CYLINDER BOTTOM) | F12: SPARES / ACCESSORIES | G12: =VLOOKUP(A12,Sheet2!A:J,1,0) -> #N/A | H12: =VLOOKUP(A12,Sheet2!A:J,6,0) -> #N/A
A13: =B13&D13 -> 90041120463850 | B13: 90041 | C13: AED - SPARES | D13: 120463850 | E13: BREATHER | F13: SPARES / ACCESSORIES | G13: =VLOOKUP(A13,Sheet2!A:J,1,0) -> #N/A | H13: =VLOOKUP(A13,Sheet2!A:J,6,0) -> #N/A
... A23: =B23&D23 -> 90029SCIN0005 | B23: 90029 | C23: Rocd-service revenue | D23: SCIN0005 | E23: AMC CHARGES | F23: SERVICE BILLING | G23: =VLOOKUP(A23,Sheet2!A:J,1,0) -> #N/A | H23: =VLOOKUP(A23,Sheet2!A:J,6,0) -> #N/A
A24: =B24&D24 -> 90029SCIN0006 | B24: 90029 | C24: Rocd-service revenue | D24: SCIN0006 | F24: SERVICE BILLING | G24: =VLOOKUP(A24,Sheet2!A:J,1,0) -> #N/A | H24: =VLOOKUP(A24,Sheet2!A:J,6,0) -> #N/A
A25: =B25&D25 -> 90029SCIN0007 | B25: 90029 | C25: Rocd-service revenue | D25: SCIN0007 | F25: SERVICE BILLING | G25: =VLOOKUP(A25,Sheet2!A:J,1,0) -> #N/A | H25: =VLOOKUP(A25,Sheet2!A:J,6,0) -> #N/A
A26: =B26&D26 -> 90029SCIN0008 | B26: 90029 | C26: Rocd-service revenue | D26: SCIN0008 | F26: SERVICE BILLING | G26: =VLOOKUP(A26,Sheet2!A:J,1,0) -> #N/A | H26: =VLOOKUP(A26,Sheet2!A:J,6,0) -> #N/A
A27: =B27&D27 -> 90029SCIN0009 | B27: 90029 | C27: Rocd-service revenue | D27: SCIN0009 | F27: SERVICE BILLING | G27: =VLOOKUP(A27,Sheet2!A:J,1,0) -> #N/A | H27: =VLOOKUP(A27,Sheet2!A:J,6,0) -> #N/A
A28: =B28&D28 -> 90040008400130 | B28: 90040 | C28: AED - MANUFACTURED UNITS | D28: 008400130 | E28: ON DELAY TIMER | F28: SPARES / ACCESSORIES | G28: =VLOOKUP(A28,Sheet2!A:J,1,0) -> #N/A | H28: =VLOOKUP(A28,Sheet2!A:J,6,0) -> #N/A
A29: =B29&D29 -> 90040008937011 | B29: 90040 | C29: AED - MANUFACTURED UNITS | D29: 008937011 | E29: TRANSFORMER 50VA 415V-0-24V. | F29: SPARES / ACCESSORIES | G29: =VLOOKUP(A29,Sheet2!A:J,1,0) -> #N/A | H29: =VLOOKUP(A29,Sheet2!A:J,6,0) -> #N/A
A30: =B30&D30 -> 90040080302630 | B30: 90040 | C30: AED - MANUFACTURED UNITS | D30: 080302630 | E30: CUSHION CHAIR | F30: MOBILE SERVICE UNITS | G30: =VLOOKUP(A30,Sheet2!A:J,1,0) -> #N/A | H30: =VLOOKUP(A30,Sheet2!A:J,6,0) -> #N/A
A31: =B31&D31 -> 90040080302730 | B31: 90040 | C31: AED - MANUFACTURED UNITS | D31: 080302730 | E31: AIR TANK ASSY | F31: MOBILE SERVICE UNITS | G31: =VLOOKUP(A31,Sheet2!A:J,1,0) -> #N/A | H31: =VLOOKUP(A31,Sheet2!A:J,6,0) -> #N/A
A32: =B32&D32 -> 90041130315300 | B32: 90041 | C32: AED - SPARES | D32: 130315300 | E32: COVER ASSY GREASE DRUM | F32: SPARES / ACCESSORIES | G32: =VLOOKUP(A32,Sheet2!A:J,1,0) -> #N/A | H32: =VLOOKUP(A32,Sheet2!A:J,6,0) -> #N/A
A33: =B33&D33 -> 90041130416931 | B33: 90041 | C33: AED - SPARES | D33: 130416931 | E33: DRUM ASSY GREASE | F33: SPARES / ACCESSORIES | G33: =VLOOKUP(A33,Sheet2!A:J,1,0) -> #N/A | H33: =VLOOKUP(A33,Sheet2!A:J,6,0) -> #N/A
A34: =B34&D34 -> 90040080302750 | B34: 90040 | C34: AED - MANUFACTURED UNITS | D34: 080302750 | E34: COMPRESSOR ASSY | F34: MMS | G34: =VLOOKUP(A34,Sheet2!A:J,1,0) -> #N/A | H34: =VLOOKUP(A34,Sheet2!A:J,6,0) -> #N/A
A35: =B35&D35 -> 90041130453220 | B35: 90041 | C35: AED - SPARES | D35: 130453220 | E35: ADAPTER BUNG M/C | F35: SPARES / ACCESSORIES | G35: =VLOOKUP(A35,Sheet2!A:J,1,0) -> #N/A | H35: =VLOOKUP(A35,Sheet2!A:J,6,0) -> #N/A
A36: =B36&D36 -> 90041130493020 | B36: 90041 | C36: AED - SPARES | D36: 130493020 | E36: PUMP WITH GUN ASSY-5 KG | F36: SPARES / ACCESSORIES | G36: =VLOOKUP(A36,Sheet2!A:J,1,0) -> #N/A | H36: =VLOOKUP(A36,Sheet2!A:J,6,0) -> #N/A
A37: =B37&D37 -> 90040080302820 | B37: 90040 | C37: AED - MANUFACTURED UNITS | D37: 080302820 | E37: WATER TANK ASSY | F37: MMS | G37: =VLOOKUP(A37,Sheet2!A:J,1,0) -> #N/A | H37: =VLOOKUP(A37,Sheet2!A:J,6,0) -> #N/A
A38: =B38&D38 -> 900411332HC0801PI | B38: 90041 | C38: AED - SPARES | D38: 1332HC0801PI | E38: WIND NOZZLE | F38: SPARES / ACCESSORIES | G38: =VLOOKUP(A38,Sheet2!A:J,1,0) -> #N/A | H38: =VLOOKUP(A38,Sheet2!A:J,6,0) -> #N/A
A39: =B39&D39 -> 900411332HC0803PI | B39: 90041 | C39: AED - SPARES | D39: 1332HC0803PI | E39: MINI BALL VALVE | F39: SPARES / ACCESSORIES | G39: =VLOOKUP(A39,Sheet2!A:J,1,0) -> #N/A | H39: =VLOOKUP(A39,Sheet2!A:J,6,0) -> #N/A
... A202: =B202&D202 -> 9004150TP02007MT | B202: 90041 | C202: AED - SPARES | D202: 50TP02007MT | E202: ROLLER ASSEMBLY | F202: SPARES / ACCESSORIES | G202: =VLOOKUP(A202,Sheet2!A:J,1,0) -> #N/A | H202: =VLOOKUP(A202,Sheet2!A:J,6,0) -> #N/A
A203: =B203&D203 -> 900423818010200003YS | B203: 90042 | C203: AED - TRADED UNITS | D203: 3818010200003YS | E203: CENTRAL PROCESSING UNIT FOR 3A | F203: SPARES / ACCESSORIES | G203: =VLOOKUP(A203,Sheet2!A:J,1,0) -> 900423818010200003YS | H203: =VLOOKUP(A203,Sheet2!A:J,10,0) -> SPARES / ACCESSORIES | I203: =IF(F203=H203,TRUE,FALSE) -> TRUE
A204: =B204&D204 -> 90040S19002 | B204: 90040 | C204: AED - MANUFACTURED UNITS | D204: S19002 | E204: SPARK PLUG CLEANER UNIT | F204: TYRE INFLATORS | G204: =VLOOKUP(A204,Sheet2!A:J,1,0) -> #N/A | H204: =VLOOKUP(A204,Sheet2!A:J,6,0) -> #N/A
A205: =B205&D205 -> 90040S23004 | B205: 90040 | C205: AED - MANUFACTURED UNITS | D205: S23004 | E205: VWB ASSEMBLY | F205: WHEEL SERVICE EQUIPMENTS | G205: =VLOOKUP(A205,Sheet2!A:J,1,0) -> #N/A | H205: =VLOOKUP(A205,Sheet2!A:J,6,0) -> #N/A
A206: =B206&D206 -> 90040S25004 | B206: 90040 | C206: AED - MANUFACTURED UNITS | D206: S25004 | E206: AC RECOVERY UNIT | F206: AC CHARGING MACHINE | G206: =VLOOKUP(A206,Sheet2!A:J,1,0) -> #N/A | H206: =VLOOKUP(A206,Sheet2!A:J,6,0) -> #N/A
A207: =B207&D207 -> 90049120459360 | B207: 90049 | C207: SUPPLIER SALES | D207: 120459360 | E207: CYLINDER SEAL KIT FOR 63DIA | F207: SUPPLIER SALES | G207: =VLOOKUP(A207,Sheet2!A:J,1,0) -> #N/A | H207: =VLOOKUP(A207,Sheet2!A:J,6,0) -> #N/A
A208: =B208&D208 -> 90049123465960 | B208: 90049 | C208: SUPPLIER SALES | D208: 123465960 | E208: SEAL KIT CYLINDER DH FPL | F208: SUPPLIER SALES | G208: =VLOOKUP(A208,Sheet2!A:J,1,0) -> #N/A | H208: =VLOOKUP(A208,Sheet2!A:J,6,0) -> #N/A
A209: =B209&D209 -> 90040S25005 | B209: 90040 | C209: AED - MANUFACTURED UNITS | D209: S25005 | E209: AC RECOVERY - FULLY AUTOMATIC | F209: AC CHARGING MACHINE | G209: =VLOOKUP(A209,Sheet2!A:J,1,0) -> #N/A | H209: =VLOOKUP(A209,Sheet2!A:J,6,0) -> #N/A
A210: =B210&D210 -> 90049460349920 | B210: 90049 | C210: SUPPLIER SALES | D210: 460349920 | E210: EXTRACTOR ASSY M1-C2 | F210: SUPPLIER SALES | G210: =VLOOKUP(A210,Sheet2!A:J,1,0) -> #N/A | H210: =VLOOKUP(A210,Sheet2!A:J,6,0) -> #N/A
A211: =B211&D211 -> 90049460349940 | B211: 90049 | C211: SUPPLIER SALES | D211: 460349940 | E211: EX BLOWER BOX ASSY | F211: SUPPLIER SALES | G211: =VLOOKUP(A211,Sheet2!A:J,1,0) -> #N/A | H211: =VLOOKUP(A211,Sheet2!A:J,6,0) -> #N/A
...

Sheet Sheet4
A1: ProductGrp
A2: AC CHARGING MACHINE
A3: ACW
A4: BODY SHOP & PAINT EQUIPMENTS - CRS
A5: BODY SHOP & PAINT EQUIPMENTS - OTHERS
A6: BODY SHOP & PAINT EQUIPMENTS - PANEL REPAIR
A7: BODY SHOP & PAINT EQUIPMENTS - PB
A8: BODY SHOP & PAINT EQUIPMENTS - WELDERS
A9: Consumables
A10: ETP
A11: FRT
A12: International Sales
... A35: WHEEL SERVICE EQUIPMENTS
